Workbook

Sheet T1
A1: Px GCCK | D1: BẢNG CHẤM CÔNG THÁNG - THÁNG 1/2026 | AI1: Tổng công ca | AJ1: Tổng công TC | AK1: ∑
D2: 46023
A3: STT | B3: Họ tên | D3: 46023 | E3: 46024 | F3: =+E3+1 -> 46025 | G3: =+F3+1 -> 46026 | H3: =+G3+1 -> 46027 | I3: =+H3+1 -> 46028 | J3: =+I3+1 -> 46029 | K3: =+J3+1 -> 46030 | L3: =+K3+1 -> 46031 | M3: =+L3+1 -> 46032 | ... AH3: =+AG3+1 -> 46053
A4: 1 | B4: Nguyễn Trung Đông | C4: TC | O4: 1 | AB4: 5.25 | AI4: =0 -> 0 | AJ4: =SUM(D4:AH4)/8 -> 0.78125 | AK4: =AI4+AJ4 -> 0.78125
C5: C1 | E5: x | F5: x | H5: x | K5: x | L5: x | M5: x | N5: x | O5: x | P5: x | Q5: x | R5: x | S5: x | U5: x | V5: x | W5: x | X5: x | Y5: x | Z5: x | AA5: x | AC5: x | AD5: x | AE5: x | AG5: x | AI5: =COUNTIF(D5:AH5,"x")+COUNTIF(D5:AH5,"x-0,25")+COUNTIF(D5:AH5,"x-0,50")+COUNTIF(D5:AH5,"x-0.75")+COUNTIF(D5:AH5,"x-1")+COUNTIF(D5:AH5,"x-1,25")+COUNTIF(D5:AH5,"x-1,5")+COUNTIF(D5:AH5,"x-1,55")+COUNTIF(D5:AH5,"x-2")+COUNTIF(D5:AH5,"x/2")/2 -> 23 | AJ5: =0 -> 0 | AK5: =AI5+AJ5 -> 23
C6: C2 | AI6: =COUNTIF(D6:AH6,"x")+COUNTIF(D6:AH6,"x-0,25")+COUNTIF(D6:AH6,"x-0,50")+COUNTIF(D6:AH6,"x-0.75")+COUNTIF(D6:AH6,"x-1")+COUNTIF(D6:AH6,"x-1,25")+COUNTIF(D6:AH6,"x-1,5")+COUNTIF(D6:AH6,"x-1,55")+COUNTIF(D6:AH6,"x-2")+COUNTIF(D6:AH6,"x/2")/2 -> 0 | AJ6: =0 -> 0 | AK6: =AI6+AJ6 -> 0
C7: C3 | AI7: =COUNTIF(D7:AH7,"x")+COUNTIF(D7:AH7,"x-0,25")+COUNTIF(D7:AH7,"x-0,50")+COUNTIF(D7:AH7,"x-0.75")+COUNTIF(D7:AH7,"x-1")+COUNTIF(D7:AH7,"x-1,25")+COUNTIF(D7:AH7,"x-1,5")+COUNTIF(D7:AH7,"x-1,55")+COUNTIF(D7:AH7,"x-2")+COUNTIF(D7:AH7,"x/2")/2 -> 0 | AJ7: =0 -> 0 | AK7: =AI7+AJ7 -> 0
AI8: ="" | AJ8: ="" | AK8: =""
A9: 2 | B9: Trần Văn Dũng | C9: TC | O9: 1 | AB9: 5.25 | AI9: =0 -> 0 | AJ9: =SUM(D9:AH9)/8 -> 0.78125 | AK9: =AI9+AJ9 -> 0.78125
C10: C1 | E10: x | F10: x | H10: x | K10: x | L10: x | M10: x | N10: x | O10: x | P10: x | Q10: x | R10: x | S10: x | U10: x | V10: x | W10: x | X10: x | Y10: x | Z10: x | AA10: x | AC10: x | AD10: x | AE10: x | AG10: x | AI10: =COUNTIF(D10:AH10,"x")+COUNTIF(D10:AH10,"x-0,25")+COUNTIF(D10:AH10,"x-0,50")+COUNTIF(D10:AH10,"x-0.75")+COUNTIF(D10:AH10,"x-1")+COUNTIF(D10:AH10,"x-1,25")+COUNTIF(D10:AH10,"x-1,5")+COUNTIF(D10:AH10,"x-1,55")+COUNTIF(D10:AH10,"x-2")+COUNTIF(D10:AH10,"x/2")/2 -> 23 | AJ10: =0 -> 0 | AK10: =AI10+AJ10 -> 23
C11: C2 | AI11: =COUNTIF(D11:AH11,"x")+COUNTIF(D11:AH11,"x-0,25")+COUNTIF(D11:AH11,"x-0,50")+COUNTIF(D11:AH11,"x-0.75")+COUNTIF(D11:AH11,"x-1")+COUNTIF(D11:AH11,"x-1,25")+COUNTIF(D11:AH11,"x-1,5")+COUNTIF(D11:AH11,"x-1,55")+COUNTIF(D11:AH11,"x-2")+COUNTIF(D11:AH11,"x/2")/2 -> 0 | AJ11: =0 -> 0 | AK11: =AI11+AJ11 -> 0
C12: C3 | AI12: =COUNTIF(D12:AH12,"x")+COUNTIF(D12:AH12,"x-0,25")+COUNTIF(D12:AH12,"x-0,50")+COUNTIF(D12:AH12,"x-0.75")+COUNTIF(D12:AH12,"x-1")+COUNTIF(D12:AH12,"x-1,25")+COUNTIF(D12:AH12,"x-1,5")+COUNTIF(D12:AH12,"x-1,55")+COUNTIF(D12:AH12,"x-2")+COUNTIF(D12:AH12,"x/2")/2 -> 0 | AJ12: =0 -> 0 | AK12: =AI12+AJ12 -> 0
AI13: ="" | AJ13: ="" | AK13: =""
A14: 3 | B14: Hoàng Ngọc Hà | C14: TC | O14: 1 | AB14: 5.25 | AI14: =0 -> 0 | AJ14: =SUM(D14:AH14)/8 -> 0.78125 | AK14: =AI14+AJ14 -> 0.78125
C15: C1 | E15: x | F15: x | H15: x | K15: x | L15: x | M15: x | N15: x | O15: x | P15: x | Q15: x | R15: x | S15: x | U15: x | V15: x | W15: x | X15: x | Y15: x | Z15: x | AA15: x | AC15: x | AD15: x | AE15: x | AG15: x | AI15: =COUNTIF(D15:AH15,"x")+COUNTIF(D15:AH15,"x-0,25")+COUNTIF(D15:AH15,"x-0,50")+COUNTIF(D15:AH15,"x-0.75")+COUNTIF(D15:AH15,"x-1")+COUNTIF(D15:AH15,"x-1,25")+COUNTIF(D15:AH15,"x-1,5")+COUNTIF(D15:AH15,"x-1,55")+COUNTIF(D15:AH15,"x-2")+COUNTIF(D15:AH15,"x/2")/2 -> 23 | AJ15: =0 -> 0 | AK15: =AI15+AJ15 -> 23
C16: C2 | AI16: =COUNTIF(D16:AH16,"x")+COUNTIF(D16:AH16,"x-0,25")+COUNTIF(D16:AH16,"x-0,50")+COUNTIF(D16:AH16,"x-0.75")+COUNTIF(D16:AH16,"x-1")+COUNTIF(D16:AH16,"x-1,25")+COUNTIF(D16:AH16,"x-1,5")+COUNTIF(D16:AH16,"x-1,55")+COUNTIF(D16:AH16,"x-2")+COUNTIF(D16:AH16,"x/2")/2 -> 0 | AJ16: =0 -> 0 | AK16: =AI16+AJ16 -> 0
C17: C3 | AI17: =COUNTIF(D17:AH17,"x")+COUNTIF(D17:AH17,"x-0,25")+COUNTIF(D17:AH17,"x-0,50")+COUNTIF(D17:AH17,"x-0.75")+COUNTIF(D17:AH17,"x-1")+COUNTIF(D17:AH17,"x-1,25")+COUNTIF(D17:AH17,"x-1,5")+COUNTIF(D17:AH17,"x-1,55")+COUNTIF(D17:AH17,"x-2")+COUNTIF(D17:AH17,"x/2")/2 -> 0 | AJ17: =0 -> 0 | AK17: =AI17+AJ17 -> 0
AI18: ="" | AJ18: ="" | AK18: =AI18+AJ18 -> #VALUE!
A19: 4 | B19: Phùng Đình Hùng | C19: TC | O19: 1 | AB19: 5.25 | AI19: =0 -> 0 | AJ19: =SUM(D19:AH19)/8 -> 0.78125 | AK19: =AI19+AJ19 -> 0.78125
C20: C1 | E20: x | F20: x | H20: x | K20: x | L20: x | M20: x | N20: x | O20: x | P20: x | Q20: x | R20: x | S20: x | U20: x | V20: x | W20: x | X20: x | Y20: x | Z20: x | AA20: x | AC20: x | AD20: x | AE20: x | AG20: x | AI20: =COUNTIF(D20:AH20,"x")+COUNTIF(D20:AH20,"x-0,25")+COUNTIF(D20:AH20,"x-0,50")+COUNTIF(D20:AH20,"x-0.75")+COUNTIF(D20:AH20,"x-1")+COUNTIF(D20:AH20,"x-1,25")+COUNTIF(D20:AH20,"x-1,5")+COUNTIF(D20:AH20,"x-1,55")+COUNTIF(D20:AH20,"x-2")+COUNTIF(D20:AH20,"x/2")/2 -> 23 | AJ20: =0 -> 0 | AK20: =AI20+AJ20 -> 23
C21: C2 | AI21: =COUNTIF(D21:AH21,"x")+COUNTIF(D21:AH21,"x-0,25")+COUNTIF(D21:AH21,"x-0,50")+COUNTIF(D21:AH21,"x-0.75")+COUNTIF(D21:AH21,"x-1")+COUNTIF(D21:AH21,"x-1,25")+COUNTIF(D21:AH21,"x-1,5")+COUNTIF(D21:AH21,"x-1,55")+COUNTIF(D21:AH21,"x-2")+COUNTIF(D21:AH21,"x/2")/2 -> 0 | AJ21: =0 -> 0 | AK21: =AI21+AJ21 -> 0
C22: C3 | AI22: =COUNTIF(D22:AH22,"x")+COUNTIF(D22:AH22,"x-0,25")+COUNTIF(D22:AH22,"x-0,50")+COUNTIF(D22:AH22,"x-0.75")+COUNTIF(D22:AH22,"x-1")+COUNTIF(D22:AH22,"x-1,25")+COUNTIF(D22:AH22,"x-1,5")+COUNTIF(D22:AH22,"x-1,55")+COUNTIF(D22:AH22,"x-2")+COUNTIF(D22:AH22,"x/2")/2 -> 0 | AJ22: =0 -> 0 | AK22: =AI22+AJ22 -> 0
AI23: ="" | AJ23: ="" | AK23: =""
A24: 5 | B24: Đặng Ngọc Long | C24: TC | O24: 1 | AB24: 5.25 | AI24: =0 -> 0 | AJ24: =SUM(D24:AH24)/8 -> 0.78125 | AK24: =AI24+AJ24 -> 0.78125
C25: C1 | E25: x | F25: x | H25: x | K25: x | L25: x | M25: x | N25: x | O25: x | P25: x | Q25: x | R25: x | S25: x | U25: x | V25: x | W25: x | X25: x | Y25: x | Z25: x | AA25: x | AC25: x | AD25: x | AE25: x | AG25: x | AI25: =COUNTIF(D25:AH25,"x")+COUNTIF(D25:AH25,"x-0,25")+COUNTIF(D25:AH25,"x-0,50")+COUNTIF(D25:AH25,"x-0.75")+COUNTIF(D25:AH25,"x-1")+COUNTIF(D25:AH25,"x-1,25")+COUNTIF(D25:AH25,"x-1,5")+COUNTIF(D25:AH25,"x-1,55")+COUNTIF(D25:AH25,"x-2")+COUNTIF(D25:AH25,"x/2")/2 -> 23 | AJ25: =0 -> 0 | AK25: =AI25+AJ25 -> 23
C26: C2 | AI26: =COUNTIF(D26:AH26,"x")+COUNTIF(D26:AH26,"x-0,25")+COUNTIF(D26:AH26,"x-0,50")+COUNTIF(D26:AH26,"x-0.75")+COUNTIF(D26:AH26,"x-1")+COUNTIF(D26:AH26,"x-1,25")+COUNTIF(D26:AH26,"x-1,5")+COUNTIF(D26:AH26,"x-1,55")+COUNTIF(D26:AH26,"x-2")+COUNTIF(D26:AH26,"x/2")/2 -> 0 | AJ26: =0 -> 0 | AK26: =AI26+AJ26 -> 0
C27: C3 | AI27: =COUNTIF(D27:AH27,"x")+COUNTIF(D27:AH27,"x-0,25")+COUNTIF(D27:AH27,"x-0,50")+COUNTIF(D27:AH27,"x-0.75")+COUNTIF(D27:AH27,"x-1")+COUNTIF(D27:AH27,"x-1,25")+COUNTIF(D27:AH27,"x-1,5")+COUNTIF(D27:AH27,"x-1,55")+COUNTIF(D27:AH27,"x-2")+COUNTIF(D27:AH27,"x/2")/2 -> 0 | AJ27: =0 -> 0 | AK27: =AI27+AJ27 -> 0
AI28: ="" | AJ28: ="" | AK28: =""
A29: 6 | B29: Trần Văn Nhận | C29: TC | O29: 1 | AB29: 5.25 | AI29: =0 -> 0 | AJ29: =SUM(D29:AH29)/8 -> 0.78125 | AK29: =AI29+AJ29 -> 0.78125
C30: C1 | E30: x | F30: x | H30: x | K30: x | L30: x | M30: x | N30: x | O30: x | P30: x | Q30: x | R30: x | S30: x | U30: x | V30: x | W30: x | X30: x | Y30: x | Z30: x | AA30: x | AC30: x | AD30: x | AE30: x | AG30: x | AI30: =COUNTIF(D30:AH30,"x")+COUNTIF(D30:AH30,"x-0,25")+COUNTIF(D30:AH30,"x-0,50")+COUNTIF(D30:AH30,"x-0.75")+COUNTIF(D30:AH30,"x-1")+COUNTIF(D30:AH30,"x-1,25")+COUNTIF(D30:AH30,"x-1,5")+COUNTIF(D30:AH30,"x-1,55")+COUNTIF(D30:AH30,"x-2")+COUNTIF(D30:AH30,"x/2")/2 -> 23 | AJ30: =0 -> 0 | AK30: =AI30+AJ30 -> 23
C31: C2 | AI31: =COUNTIF(D31:AH31,"x")+COUNTIF(D31:AH31,"x-0,25")+COUNTIF(D31:AH31,"x-0,50")+COUNTIF(D31:AH31,"x-0.75")+COUNTIF(D31:AH31,"x-1")+COUNTIF(D31:AH31,"x-1,25")+COUNTIF(D31:AH31,"x-1,5")+COUNTIF(D31:AH31,"x-1,55")+COUNTIF(D31:AH31,"x-2")+COUNTIF(D31:AH31,"x/2")/2 -> 0 | AJ31: =0 -> 0 | AK31: =AI31+AJ31 -> 0
C32: C3 | AI32: =COUNTIF(D32:AH32,"x")+COUNTIF(D32:AH32,"x-0,25")+COUNTIF(D32:AH32,"x-0,50")+COUNTIF(D32:AH32,"x-0.75")+COUNTIF(D32:AH32,"x-1")+COUNTIF(D32:AH32,"x-1,25")+COUNTIF(D32:AH32,"x-1,5")+COUNTIF(D32:AH32,"x-1,55")+COUNTIF(D32:AH32,"x-2")+COUNTIF(D32:AH32,"x/2")/2 -> 0 | AJ32: =0 -> 0 | AK32: =0 -> 0
AI33: ="" | AJ33: ="" | AK33: =""
A34: 7 | B34: Phùng Gia Phúc | C34: TC | O34: 1 | AB34: 5.25 | AI34: =0 -> 0 | AJ34: =SUM(D34:AH34)/8 -> 0.78125 | AK34: =AI34+AJ34 -> 0.78125
C35: C1 | E35: x | F35: x | H35: x | K35: x | L35: x | M35: x | N35: x | O35: x | P35: x | Q35: x | R35: x | S35: x | U35: x | V35: x | W35: x | X35: x | Y35: x | Z35: x | AA35: x | AC35: x | AD35: x | AE35: x | AG35: x | AI35: =COUNTIF(D35:AH35,"x")+COUNTIF(D35:AH35,"x-0,25")+COUNTIF(D35:AH35,"x-0,50")+COUNTIF(D35:AH35,"x-0.75")+COUNTIF(D35:AH35,"x-1")+COUNTIF(D35:AH35,"x-1,25")+COUNTIF(D35:AH35,"x-1,5")+COUNTIF(D35:AH35,"x-1,55")+COUNTIF(D35:AH35,"x-2")+COUNTIF(D35:AH35,"x/2")/2 -> 23 | AJ35: =0 -> 0 | AK35: =AI35+AJ35 -> 23
C36: C2 | AI36: =COUNTIF(D36:AH36,"x")+COUNTIF(D36:AH36,"x-0,25")+COUNTIF(D36:AH36,"x-0,50")+COUNTIF(D36:AH36,"x-0.75")+COUNTIF(D36:AH36,"x-1")+COUNTIF(D36:AH36,"x-1,25")+COUNTIF(D36:AH36,"x-1,5")+COUNTIF(D36:AH36,"x-1,55")+COUNTIF(D36:AH36,"x-2")+COUNTIF(D36:AH36,"x/2")/2 -> 0 | AJ36: =0 -> 0 | AK36: =AI36+AJ36 -> 0
C37: C3 | AI37: =COUNTIF(D37:AH37,"x")+COUNTIF(D37:AH37,"x-0,25")+COUNTIF(D37:AH37,"x-0,50")+COUNTIF(D37:AH37,"x-0.75")+COUNTIF(D37:AH37,"x-1")+COUNTIF(D37:AH37,"x-1,25")+COUNTIF(D37:AH37,"x-1,5")+COUNTIF(D37:AH37,"x-1,55")+COUNTIF(D37:AH37,"x-2")+COUNTIF(D37:AH37,"x/2")/2 -> 0 | AJ37: =0 -> 0 | AK37: =AI37+AJ37 -> 0
AI38: ="" | AJ38: ="" | AK38: =""
A39: 8 | B39: Trần Văn Quỳnh | C39: TC | O39: 1 | AB39: 5.25 | AI39: =0 -> 0 | AJ39: =SUM(D39:AH39)/8 -> 0.78125 | AK39: =AI39+AJ39 -> 0.78125
C40: C1 | E40: x | F40: x | H40: x | K40: x | L40: x | M40: x | N40: x | O40: x | P40: x | Q40: x | R40: x | S40: x | U40: x | V40: x | W40: x | X40: x | Y40: x | Z40: x | AA40: x | AC40: x | AD40: x | AE40: x | AG40: x | AI40: =COUNTIF(D40:AH40,"x")+COUNTIF(D40:AH40,"x-0,25")+COUNTIF(D40:AH40,"x-0,50")+COUNTIF(D40:AH40,"x-0.75")+COUNTIF(D40:AH40,"x-1")+COUNTIF(D40:AH40,"x-1,25")+COUNTIF(D40:AH40,"x-1,5")+COUNTIF(D40:AH40,"x-1,55")+COUNTIF(D40:AH40,"x-2")+COUNTIF(D40:AH40,"x/2")/2 -> 23 | AJ40: =0 -> 0 | AK40: =AI40+AJ40 -> 23
...

Sheet T2
A1: Px GCCK | D1: BẢNG CHẤM CÔNG THÁNG - THÁNG 2/2026 | AI1: Tổng công ca | AJ1: Tổng công TC | AK1: ∑
D2: 46054
A3: STT | B3: Họ tên | D3: 46054 | E3: 46055 | F3: =+E3+1 -> 46056 | G3: =+F3+1 -> 46057 | H3: =+G3+1 -> 46058 | I3: =+H3+1 -> 46059 | J3: =+I3+1 -> 46060 | K3: =+J3+1 -> 46061 | L3: =+K3+1 -> 46062 | M3: =+L3+1 -> 46063 | ... AH3: =+AG3+1 -> 46084
A4: 1 | B4: Nguyễn Trung Đông | C4: TC | AI4: =0 -> 0 | AJ4: =SUM(D4:AH4)/8 -> 0 | AK4: =AI4+AJ4 -> 0
C5: C1 | E5: x | F5: x | G5: x | H5: 0 | I5: x | J5: x | L5: x | M5: x | N5: x | O5: x | P5: x/2 | X5: x | Y5: x | Z5: x | AA5: x | AB5: x | AC5: x | AD5: x | AE5: x | AI5: =COUNTIF(D5:AH5,"x")+COUNTIF(D5:AH5,"x-0,25")+COUNTIF(D5:AH5,"x-0,50")+COUNTIF(D5:AH5,"x-0.75")+COUNTIF(D5:AH5,"x-1")+COUNTIF(D5:AH5,"x-1,25")+COUNTIF(D5:AH5,"x-1,5")+COUNTIF(D5:AH5,"x-1,55")+COUNTIF(D5:AH5,"x-2")+COUNTIF(D5:AH5,"x/2")/2 -> 17.5 | AJ5: =0 -> 0 | AK5: =AI5+AJ5 -> 17.5
C6: C2 | AI6: =COUNTIF(D6:AH6,"x")+COUNTIF(D6:AH6,"x-0,25")+COUNTIF(D6:AH6,"x-0,50")+COUNTIF(D6:AH6,"x-0.75")+COUNTIF(D6:AH6,"x-1")+COUNTIF(D6:AH6,"x-1,25")+COUNTIF(D6:AH6,"x-1,5")+COUNTIF(D6:AH6,"x-1,55")+COUNTIF(D6:AH6,"x-2")+COUNTIF(D6:AH6,"x/2")/2 -> 0 | AJ6: =0 -> 0 | AK6: =AI6+AJ6 -> 0
C7: C3 | AI7: =COUNTIF(D7:AH7,"x")+COUNTIF(D7:AH7,"x-0,25")+COUNTIF(D7:AH7,"x-0,50")+COUNTIF(D7:AH7,"x-0.75")+COUNTIF(D7:AH7,"x-1")+COUNTIF(D7:AH7,"x-1,25")+COUNTIF(D7:AH7,"x-1,5")+COUNTIF(D7:AH7,"x-1,55")+COUNTIF(D7:AH7,"x-2")+COUNTIF(D7:AH7,"x/2")/2 -> 0 | AJ7: =0 -> 0 | AK7: =AI7+AJ7 -> 0
AI8: ="" | AJ8: ="" | AK8: =""
A9: 2 | B9: Trần Văn Dũng | C9: TC | AI9: =0 -> 0 | AJ9: =SUM(D9:AH9)/8 -> 0 | AK9: =AI9+AJ9 -> 0
C10: C1 | E10: x | F10: x | G10: x | H10: x | I10: x | J10: x | L10: x | M10: x | N10: x | O10: x | P10: x | Y10: x | Z10: x | AA10: x | AB10: x | AC10: x | AD10: x | AE10: x | AI10: =COUNTIF(D10:AH10,"x")+COUNTIF(D10:AH10,"x-0,25")+COUNTIF(D10:AH10,"x-0,50")+COUNTIF(D10:AH10,"x-0.75")+COUNTIF(D10:AH10,"x-1")+COUNTIF(D10:AH10,"x-1,25")+COUNTIF(D10:AH10,"x-1,5")+COUNTIF(D10:AH10,"x-1,55")+COUNTIF(D10:AH10,"x-2")+COUNTIF(D10:AH10,"x/2")/2 -> 18 | AJ10: =0 -> 0 | AK10: =AI10+AJ10 -> 18
C11: C2 | AI11: =COUNTIF(D11:AH11,"x")+COUNTIF(D11:AH11,"x-0,25")+COUNTIF(D11:AH11,"x-0,50")+COUNTIF(D11:AH11,"x-0.75")+COUNTIF(D11:AH11,"x-1")+COUNTIF(D11:AH11,"x-1,25")+COUNTIF(D11:AH11,"x-1,5")+COUNTIF(D11:AH11,"x-1,55")+COUNTIF(D11:AH11,"x-2")+COUNTIF(D11:AH11,"x/2")/2 -> 0 | AJ11: =0 -> 0 | AK11: =AI11+AJ11 -> 0
C12: C3 | AI12: =COUNTIF(D12:AH12,"x")+COUNTIF(D12:AH12,"x-0,25")+COUNTIF(D12:AH12,"x-0,50")+COUNTIF(D12:AH12,"x-0.75")+COUNTIF(D12:AH12,"x-1")+COUNTIF(D12:AH12,"x-1,25")+COUNTIF(D12:AH12,"x-1,5")+COUNTIF(D12:AH12,"x-1,55")+COUNTIF(D12:AH12,"x-2")+COUNTIF(D12:AH12,"x/2")/2 -> 0 | AJ12: =0 -> 0 | AK12: =AI12+AJ12 -> 0
AI13: ="" | AJ13: ="" | AK13: =""
A14: 3 | B14: Hoàng Ngọc Hà | C14: TC | K14: 0.75 | AI14: =0 -> 0 | AJ14: =SUM(D14:AH14)/8 -> 0.09375 | AK14: =AI14+AJ14 -> 0.09375
C15: C1 | E15: x | F15: x | G15: x | H15: x | I15: x | J15: x | K15: x | L15: x | M15: x | N15: x | O15: x | P15: x | X15: x | Y15: x | Z15: x | AA15: x | AB15: x | AC15: x | AD15: x | AE15: x | AI15: =COUNTIF(D15:AH15,"x")+COUNTIF(D15:AH15,"x-0,25")+COUNTIF(D15:AH15,"x-0,50")+COUNTIF(D15:AH15,"x-0.75")+COUNTIF(D15:AH15,"x-1")+COUNTIF(D15:AH15,"x-1,25")+COUNTIF(D15:AH15,"x-1,5")+COUNTIF(D15:AH15,"x-1,55")+COUNTIF(D15:AH15,"x-2")+COUNTIF(D15:AH15,"x/2")/2 -> 20 | AJ15: =0 -> 0 | AK15: =AI15+AJ15 -> 20
C16: C2 | AI16: =COUNTIF(D16:AH16,"x")+COUNTIF(D16:AH16,"x-0,25")+COUNTIF(D16:AH16,"x-0,50")+COUNTIF(D16:AH16,"x-0.75")+COUNTIF(D16:AH16,"x-1")+COUNTIF(D16:AH16,"x-1,25")+COUNTIF(D16:AH16,"x-1,5")+COUNTIF(D16:AH16,"x-1,55")+COUNTIF(D16:AH16,"x-2")+COUNTIF(D16:AH16,"x/2")/2 -> 0 | AJ16: =0 -> 0 | AK16: =AI16+AJ16 -> 0
C17: C3 | AI17: =COUNTIF(D17:AH17,"x")+COUNTIF(D17:AH17,"x-0,25")+COUNTIF(D17:AH17,"x-0,50")+COUNTIF(D17:AH17,"x-0.75")+COUNTIF(D17:AH17,"x-1")+COUNTIF(D17:AH17,"x-1,25")+COUNTIF(D17:AH17,"x-1,5")+COUNTIF(D17:AH17,"x-1,55")+COUNTIF(D17:AH17,"x-2")+COUNTIF(D17:AH17,"x/2")/2 -> 0 | AJ17: =0 -> 0 | AK17: =AI17+AJ17 -> 0
AI18: ="" | AJ18: ="" | AK18: =AI18+AJ18 -> #VALUE!
A19: 4 | B19: Phùng Đình Hùng | C19: TC | AI19: =0 -> 0 | AJ19: =SUM(D19:AH19)/8 -> 0 | AK19: =AI19+AJ19 -> 0
C20: C1 | E20: x | F20: x | G20: x | H20: x | I20: x | J20: 0 | K20: x | L20: x | M20: x | N20: x | O20: x | P20: x | Y20: x | Z20: x | AA20: x | AB20: x | AC20: x | AD20: x | AE20: x | AI20: =COUNTIF(D20:AH20,"x")+COUNTIF(D20:AH20,"x-0,25")+COUNTIF(D20:AH20,"x-0,50")+COUNTIF(D20:AH20,"x-0.75")+COUNTIF(D20:AH20,"x-1")+COUNTIF(D20:AH20,"x-1,25")+COUNTIF(D20:AH20,"x-1,5")+COUNTIF(D20:AH20,"x-1,55")+COUNTIF(D20:AH20,"x-2")+COUNTIF(D20:AH20,"x/2")/2 -> 18 | AJ20: =0 -> 0 | AK20: =AI20+AJ20 -> 18
C21: C2 | AI21: =COUNTIF(D21:AH21,"x")+COUNTIF(D21:AH21,"x-0,25")+COUNTIF(D21:AH21,"x-0,50")+COUNTIF(D21:AH21,"x-0.75")+COUNTIF(D21:AH21,"x-1")+COUNTIF(D21:AH21,"x-1,25")+COUNTIF(D21:AH21,"x-1,5")+COUNTIF(D21:AH21,"x-1,55")+COUNTIF(D21:AH21,"x-2")+COUNTIF(D21:AH21,"x/2")/2 -> 0 | AJ21: =0 -> 0 | AK21: =AI21+AJ21 -> 0
C22: C3 | AI22: =COUNTIF(D22:AH22,"x")+COUNTIF(D22:AH22,"x-0,25")+COUNTIF(D22:AH22,"x-0,50")+COUNTIF(D22:AH22,"x-0.75")+COUNTIF(D22:AH22,"x-1")+COUNTIF(D22:AH22,"x-1,25")+COUNTIF(D22:AH22,"x-1,5")+COUNTIF(D22:AH22,"x-1,55")+COUNTIF(D22:AH22,"x-2")+COUNTIF(D22:AH22,"x/2")/2 -> 0 | AJ22: =0 -> 0 | AK22: =AI22+AJ22 -> 0
AI23: ="" | AJ23: ="" | AK23: =""
A24: 5 | B24: Đặng Ngọc Long | C24: TC | AI24: =0 -> 0 | AJ24: =SUM(D24:AH24)/8 -> 0 | AK24: =AI24+AJ24 -> 0
C25: C1 | E25: x | F25: x | G25: x | H25: x | I25: x | J25: x | K25: x | L25: x | M25: x | N25: x | O25: x | P25: x | X25: x/2 | Y25: x | Z25: x | AA25: x | AB25: x | AC25: x | AD25: x | AE25: x | AI25: =COUNTIF(D25:AH25,"x")+COUNTIF(D25:AH25,"x-0,25")+COUNTIF(D25:AH25,"x-0,50")+COUNTIF(D25:AH25,"x-0.75")+COUNTIF(D25:AH25,"x-1")+COUNTIF(D25:AH25,"x-1,25")+COUNTIF(D25:AH25,"x-1,5")+COUNTIF(D25:AH25,"x-1,55")+COUNTIF(D25:AH25,"x-2")+COUNTIF(D25:AH25,"x/2")/2 -> 19.5 | AJ25: =0 -> 0 | AK25: =AI25+AJ25 -> 19.5
C26: C2 | AI26: =COUNTIF(D26:AH26,"x")+COUNTIF(D26:AH26,"x-0,25")+COUNTIF(D26:AH26,"x-0,50")+COUNTIF(D26:AH26,"x-0.75")+COUNTIF(D26:AH26,"x-1")+COUNTIF(D26:AH26,"x-1,25")+COUNTIF(D26:AH26,"x-1,5")+COUNTIF(D26:AH26,"x-1,55")+COUNTIF(D26:AH26,"x-2")+COUNTIF(D26:AH26,"x/2")/2 -> 0 | AJ26: =0 -> 0 | AK26: =AI26+AJ26 -> 0
C27: C3 | AI27: =COUNTIF(D27:AH27,"x")+COUNTIF(D27:AH27,"x-0,25")+COUNTIF(D27:AH27,"x-0,50")+COUNTIF(D27:AH27,"x-0.75")+COUNTIF(D27:AH27,"x-1")+COUNTIF(D27:AH27,"x-1,25")+COUNTIF(D27:AH27,"x-1,5")+COUNTIF(D27:AH27,"x-1,55")+COUNTIF(D27:AH27,"x-2")+COUNTIF(D27:AH27,"x/2")/2 -> 0 | AJ27: =0 -> 0 | AK27: =AI27+AJ27 -> 0
AI28: ="" | AJ28: ="" | AK28: =""
A29: 6 | B29: Trần Văn Nhận | C29: TC | AI29: =0 -> 0 | AJ29: =SUM(D29:AH29)/8 -> 0 | AK29: =AI29+AJ29 -> 0
C30: C1 | E30: x | F30: x | G30: x | H30: x | I30: x | J30: x | L30: x | M30: x | N30: x | O30: x | P30: x | X30: x | Y30: x | Z30: x | AA30: x | AB30: x | AC30: x | AD30: x | AE30: x | AI30: =COUNTIF(D30:AH30,"x")+COUNTIF(D30:AH30,"x-0,25")+COUNTIF(D30:AH30,"x-0,50")+COUNTIF(D30:AH30,"x-0.75")+COUNTIF(D30:AH30,"x-1")+COUNTIF(D30:AH30,"x-1,25")+COUNTIF(D30:AH30,"x-1,5")+COUNTIF(D30:AH30,"x-1,55")+COUNTIF(D30:AH30,"x-2")+COUNTIF(D30:AH30,"x/2")/2 -> 19 | AJ30: =0 -> 0 | AK30: =AI30+AJ30 -> 19
C31: C2 | AI31: =COUNTIF(D31:AH31,"x")+COUNTIF(D31:AH31,"x-0,25")+COUNTIF(D31:AH31,"x-0,50")+COUNTIF(D31:AH31,"x-0.75")+COUNTIF(D31:AH31,"x-1")+COUNTIF(D31:AH31,"x-1,25")+COUNTIF(D31:AH31,"x-1,5")+COUNTIF(D31:AH31,"x-1,55")+COUNTIF(D31:AH31,"x-2")+COUNTIF(D31:AH31,"x/2")/2 -> 0 | AJ31: =0 -> 0 | AK31: =AI31+AJ31 -> 0
C32: C3 | AI32: =COUNTIF(D32:AH32,"x")+COUNTIF(D32:AH32,"x-0,25")+COUNTIF(D32:AH32,"x-0,50")+COUNTIF(D32:AH32,"x-0.75")+COUNTIF(D32:AH32,"x-1")+COUNTIF(D32:AH32,"x-1,25")+COUNTIF(D32:AH32,"x-1,5")+COUNTIF(D32:AH32,"x-1,55")+COUNTIF(D32:AH32,"x-2")+COUNTIF(D32:AH32,"x/2")/2 -> 0 | AJ32: =0 -> 0 | AK32: =0 -> 0
AI33: ="" | AJ33: ="" | AK33: =""
A34: 7 | B34: Phùng Gia Phúc | C34: TC | AI34: =0 -> 0 | AJ34: =SUM(D34:AH34)/8 -> 0 | AK34: =AI34+AJ34 -> 0
C35: C1 | E35: x | F35: x | G35: x | H35: x | I35: x | J35: x | L35: x | M35: x | N35: x | O35: x | P35: x | Z35: x | AA35: x | AB35: x | AC35: 0 | AD35: 0 | AE35: 0 | AI35: =COUNTIF(D35:AH35,"x")+COUNTIF(D35:AH35,"x-0,25")+COUNTIF(D35:AH35,"x-0,50")+COUNTIF(D35:AH35,"x-0.75")+COUNTIF(D35:AH35,"x-1")+COUNTIF(D35:AH35,"x-1,25")+COUNTIF(D35:AH35,"x-1,5")+COUNTIF(D35:AH35,"x-1,55")+COUNTIF(D35:AH35,"x-2")+COUNTIF(D35:AH35,"x/2")/2 -> 14 | AJ35: =0 -> 0 | AK35: =AI35+AJ35 -> 14
C36: C2 | AI36: =COUNTIF(D36:AH36,"x")+COUNTIF(D36:AH36,"x-0,25")+COUNTIF(D36:AH36,"x-0,50")+COUNTIF(D36:AH36,"x-0.75")+COUNTIF(D36:AH36,"x-1")+COUNTIF(D36:AH36,"x-1,25")+COUNTIF(D36:AH36,"x-1,5")+COUNTIF(D36:AH36,"x-1,55")+COUNTIF(D36:AH36,"x-2")+COUNTIF(D36:AH36,"x/2")/2 -> 0 | AJ36: =0 -> 0 | AK36: =AI36+AJ36 -> 0
C37: C3 | F37: =+E37+1 -> 1 | G37: =+F37+1 -> 2 | H37: =+G37+1 -> 3 | I37: =+H37+1 -> 4 | J37: =+I37+1 -> 5 | K37: =+J37+1 -> 6 | L37: =+K37+1 -> 7 | M37: =+L37+1 -> 8 | ... AH37: =+AG37+1 -> 29 | AI37: =COUNTIF(D37:AH37,"x")+COUNTIF(D37:AH37,"x-0,25")+COUNTIF(D37:AH37,"x-0,50")+COUNTIF(D37:AH37,"x-0.75")+COUNTIF(D37:AH37,"x-1")+COUNTIF(D37:AH37,"x-1,25")+COUNTIF(D37:AH37,"x-1,5")+COUNTIF(D37:AH37,"x-1,55")+COUNTIF(D37:AH37,"x-2")+COUNTIF(D37:AH37,"x/2")/2 -> 0 | AJ37: =0 -> 0 | AK37: =AI37+AJ37 -> 0
AI38: ="" | AJ38: ="" | AK38: =""
A39: 8 | B39: Trần Văn Quỳnh | C39: TC | AI39: =0 -> 0 | AJ39: =SUM(D39:AH39)/8 -> 0 | AK39: =AI39+AJ39 -> 0
C40: C1 | E40: x | F40: x | G40: x | H40: x | I40: x | J40: 0 | K40: x | L40: x | M40: x | N40: x | O40: x | P40: x | X40: x | Y40: x | Z40: x | AA40: x | AB40: x | AC40: x | AD40: x | AE40: x | AI40: =COUNTIF(D40:AH40,"x")+COUNTIF(D40:AH40,"x-0,25")+COUNTIF(D40:AH40,"x-0,50")+COUNTIF(D40:AH40,"x-0.75")+COUNTIF(D40:AH40,"x-1")+COUNTIF(D40:AH40,"x-1,25")+COUNTIF(D40:AH40,"x-1,5")+COUNTIF(D40:AH40,"x-1,55")+COUNTIF(D40:AH40,"x-2")+COUNTIF(D40:AH40,"x/2")/2 -> 19 | AJ40: =0 -> 0 | AK40: =AI40+AJ40 -> 19
...

Sheet T3
A1: Px GCCK | D1: BẢNG CHẤM CÔNG THÁNG - THÁNG 3/2026 | AI1: Tổng công ca | AJ1: Tổng công TC | AK1: ∑
D2: 46082
A3: STT | B3: Họ tên | D3: 46082 | E3: 46083 | F3: =+E3+1 -> 46084 | G3: =+F3+1 -> 46085 | H3: =+G3+1 -> 46086 | I3: =+H3+1 -> 46087 | J3: =+I3+1 -> 46088 | K3: =+J3+1 -> 46089 | L3: =+K3+1 -> 46090 | M3: =+L3+1 -> 46091 | ... AE3: =+AD3+1 -> 46109 | AF3: 46110 | AG3: =+AF3+1 -> 46111 | AH3: =+AG3+1 -> 46112
A4: 1 | B4: Nguyễn Trung Đông | C4: TC | AH4: 7.5 | AI4: =0 -> 0 | AJ4: =SUM(D4:AH4)/8 -> 0.9375 | AK4: =AI4+AJ4 -> 0.9375
C5: C1 | D5: x | E5: x | G5: x | H5: x | I5: x | J5: x | K5: x | L5: x | M5: x | N5: x | O5: x | P5: x | Q5: x | R5: X | S5: x | T5: x | U5: x | V5: x/2 | W5: x | X5: x | Y5: x | Z5: x | AB5: x | AC5: x | AD5: x | AE5: x | AF5: x | AG5: x | AI5: =COUNTIF(D5:AH5,"x")+COUNTIF(D5:AH5,"x-0,25")+COUNTIF(D5:AH5,"x-0,50")+COUNTIF(D5:AH5,"x-0.75")+COUNTIF(D5:AH5,"x-1")+COUNTIF(D5:AH5,"x-1,25")+COUNTIF(D5:AH5,"x-1,5")+COUNTIF(D5:AH5,"x-1,55")+COUNTIF(D5:AH5,"x-2")+COUNTIF(D5:AH5,"x/2")/2 -> 27.5 | AJ5: =0 -> 0 | AK5: =AI5+AJ5 -> 27.5
C6: C2 | AI6: =COUNTIF(D6:AH6,"x")+COUNTIF(D6:AH6,"x-0,25")+COUNTIF(D6:AH6,"x-0,50")+COUNTIF(D6:AH6,"x-0.75")+COUNTIF(D6:AH6,"x-1")+COUNTIF(D6:AH6,"x-1,25")+COUNTIF(D6:AH6,"x-1,5")+COUNTIF(D6:AH6,"x-1,55")+COUNTIF(D6:AH6,"x-2")+COUNTIF(D6:AH6,"x/2")/2 -> 0 | AJ6: =0 -> 0 | AK6: =AI6+AJ6 -> 0
C7: C3 | AI7: =COUNTIF(D7:AH7,"x")+COUNTIF(D7:AH7,"x-0,25")+COUNTIF(D7:AH7,"x-0,50")+COUNTIF(D7:AH7,"x-0.75")+COUNTIF(D7:AH7,"x-1")+COUNTIF(D7:AH7,"x-1,25")+COUNTIF(D7:AH7,"x-1,5")+COUNTIF(D7:AH7,"x-1,55")+COUNTIF(D7:AH7,"x-2")+COUNTIF(D7:AH7,"x/2")/2 -> 0 | AJ7: =0 -> 0 | AK7: =AI7+AJ7 -> 0
AI8: ="" | AJ8: ="" | AK8: =""
A9: 2 | B9: Trần Văn Dũng | C9: TC | AH9: 8.5 | AI9: =0 -> 0 | AJ9: =SUM(D9:AH9)/8 -> 1.0625 | AK9: =AI9+AJ9 -> 1.0625
C10: C1 | D10: x | E10: x | G10: x | H10: x | I10: x | J10: x | K10: x | L10: x | M10: x | N10: x | O10: x | P10: x | Q10: x | R10: X | S10: x | T10: x | U10: x | V10: x/3 | W10: x | X10: x | Y10: x | Z10: x | AB10: x | AC10: x | AD10: x | AE10: x | AF10: x | AG10: x | AI10: =COUNTIF(D10:AH10,"x")+COUNTIF(D10:AH10,"x-0,25")+COUNTIF(D10:AH10,"x-0,50")+COUNTIF(D10:AH10,"x-0.75")+COUNTIF(D10:AH10,"x-1")+COUNTIF(D10:AH10,"x-1,25")+COUNTIF(D10:AH10,"x-1,5")+COUNTIF(D10:AH10,"x-1,55")+COUNTIF(D10:AH10,"x-2")+COUNTIF(D10:AH10,"x/2")/2 -> 27 | AJ10: =0 -> 0 | AK10: =AI10+AJ10 -> 27
C11: C2 | AI11: =COUNTIF(D11:AH11,"x")+COUNTIF(D11:AH11,"x-0,25")+COUNTIF(D11:AH11,"x-0,50")+COUNTIF(D11:AH11,"x-0.75")+COUNTIF(D11:AH11,"x-1")+COUNTIF(D11:AH11,"x-1,25")+COUNTIF(D11:AH11,"x-1,5")+COUNTIF(D11:AH11,"x-1,55")+COUNTIF(D11:AH11,"x-2")+COUNTIF(D11:AH11,"x/2")/2 -> 0 | AJ11: =0 -> 0 | AK11: =AI11+AJ11 -> 0
C12: C3 | AI12: =COUNTIF(D12:AH12,"x")+COUNTIF(D12:AH12,"x-0,25")+COUNTIF(D12:AH12,"x-0,50")+COUNTIF(D12:AH12,"x-0.75")+COUNTIF(D12:AH12,"x-1")+COUNTIF(D12:AH12,"x-1,25")+COUNTIF(D12:AH12,"x-1,5")+COUNTIF(D12:AH12,"x-1,55")+COUNTIF(D12:AH12,"x-2")+COUNTIF(D12:AH12,"x/2")/2 -> 0 | AJ12: =0 -> 0 | AK12: =AI12+AJ12 -> 0
AI13: ="" | AJ13: ="" | AK13: =""
A14: 3 | B14: Hoàng Ngọc Hà | C14: TC | AH14: 9.5 | AI14: =0 -> 0 | AJ14: =SUM(D14:AH14)/8 -> 1.1875 | AK14: =AI14+AJ14 -> 1.1875
C15: C1 | D15: x | E15: x | G15: x | H15: x | I15: x | J15: x | K15: x | L15: x | M15: x | N15: x | O15: x | P15: x | Q15: x | R15: X | S15: x | T15: x | U15: x | V15: x/4 | W15: x | X15: x | Y15: x | Z15: x | AB15: x | AC15: x | AD15: x | AE15: x | AF15: x | AG15: x | AI15: =COUNTIF(D15:AH15,"x")+COUNTIF(D15:AH15,"x-0,25")+COUNTIF(D15:AH15,"x-0,50")+COUNTIF(D15:AH15,"x-0.75")+COUNTIF(D15:AH15,"x-1")+COUNTIF(D15:AH15,"x-1,25")+COUNTIF(D15:AH15,"x-1,5")+COUNTIF(D15:AH15,"x-1,55")+COUNTIF(D15:AH15,"x-2")+COUNTIF(D15:AH15,"x/2")/2 -> 27 | AJ15: =0 -> 0 | AK15: =AI15+AJ15 -> 27
C16: C2 | AI16: =COUNTIF(D16:AH16,"x")+COUNTIF(D16:AH16,"x-0,25")+COUNTIF(D16:AH16,"x-0,50")+COUNTIF(D16:AH16,"x-0.75")+COUNTIF(D16:AH16,"x-1")+COUNTIF(D16:AH16,"x-1,25")+COUNTIF(D16:AH16,"x-1,5")+COUNTIF(D16:AH16,"x-1,55")+COUNTIF(D16:AH16,"x-2")+COUNTIF(D16:AH16,"x/2")/2 -> 0 | AJ16: =0 -> 0 | AK16: =AI16+AJ16 -> 0
C17: C3 | AI17: =COUNTIF(D17:AH17,"x")+COUNTIF(D17:AH17,"x-0,25")+COUNTIF(D17:AH17,"x-0,50")+COUNTIF(D17:AH17,"x-0.75")+COUNTIF(D17:AH17,"x-1")+COUNTIF(D17:AH17,"x-1,25")+COUNTIF(D17:AH17,"x-1,5")+COUNTIF(D17:AH17,"x-1,55")+COUNTIF(D17:AH17,"x-2")+COUNTIF(D17:AH17,"x/2")/2 -> 0 | AJ17: =0 -> 0 | AK17: =AI17+AJ17 -> 0
AI18: ="" | AJ18: ="" | AK18: =AI18+AJ18 -> #VALUE!
A19: 4 | B19: Phùng Đình Hùng | C19: TC | AH19: 10.5 | AI19: =0 -> 0 | AJ19: =SUM(D19:AH19)/8 -> 1.3125 | AK19: =AI19+AJ19 -> 1.3125
C20: C1 | D20: x | E20: x | G20: x | H20: x | I20: x | J20: x | K20: x | L20: x | M20: x | N20: x | O20: x | P20: x | Q20: x | R20: X | S20: x | T20: x | U20: x | V20: x/5 | W20: x | X20: x | Y20: x | Z20: x | AB20: x | AC20: x | AD20: x | AE20: x | AF20: x | AG20: x | AI20: =COUNTIF(D20:AH20,"x")+COUNTIF(D20:AH20,"x-0,25")+COUNTIF(D20:AH20,"x-0,50")+COUNTIF(D20:AH20,"x-0.75")+COUNTIF(D20:AH20,"x-1")+COUNTIF(D20:AH20,"x-1,25")+COUNTIF(D20:AH20,"x-1,5")+COUNTIF(D20:AH20,"x-1,55")+COUNTIF(D20:AH20,"x-2")+COUNTIF(D20:AH20,"x/2")/2 -> 27 | AJ20: =0 -> 0 | AK20: =AI20+AJ20 -> 27
C21: C2 | AI21: =COUNTIF(D21:AH21,"x")+COUNTIF(D21:AH21,"x-0,25")+COUNTIF(D21:AH21,"x-0,50")+COUNTIF(D21:AH21,"x-0.75")+COUNTIF(D21:AH21,"x-1")+COUNTIF(D21:AH21,"x-1,25")+COUNTIF(D21:AH21,"x-1,5")+COUNTIF(D21:AH21,"x-1,55")+COUNTIF(D21:AH21,"x-2")+COUNTIF(D21:AH21,"x/2")/2 -> 0 | AJ21: =0 -> 0 | AK21: =AI21+AJ21 -> 0
C22: C3 | AI22: =COUNTIF(D22:AH22,"x")+COUNTIF(D22:AH22,"x-0,25")+COUNTIF(D22:AH22,"x-0,50")+COUNTIF(D22:AH22,"x-0.75")+COUNTIF(D22:AH22,"x-1")+COUNTIF(D22:AH22,"x-1,25")+COUNTIF(D22:AH22,"x-1,5")+COUNTIF(D22:AH22,"x-1,55")+COUNTIF(D22:AH22,"x-2")+COUNTIF(D22:AH22,"x/2")/2 -> 0 | AJ22: =0 -> 0 | AK22: =AI22+AJ22 -> 0
AI23: ="" | AJ23: ="" | AK23: =""
A24: 5 | B24: Đặng Ngọc Long | C24: TC | AH24: 11.5 | AI24: =0 -> 0 | AJ24: =SUM(D24:AH24)/8 -> 1.4375 | AK24: =AI24+AJ24 -> 1.4375
C25: C1 | D25: x | E25: x | G25: x | H25: x | I25: x | J25: x | K25: x | L25: x | M25: x | N25: x | O25: x | P25: x | Q25: x | R25: X | S25: x | T25: x | U25: x | V25: x/6 | W25: x | X25: x | Y25: x | Z25: x | AB25: x | AC25: x | AD25: x | AE25: x | AF25: x | AG25: x | AI25: =COUNTIF(D25:AH25,"x")+COUNTIF(D25:AH25,"x-0,25")+COUNTIF(D25:AH25,"x-0,50")+COUNTIF(D25:AH25,"x-0.75")+COUNTIF(D25:AH25,"x-1")+COUNTIF(D25:AH25,"x-1,25")+COUNTIF(D25:AH25,"x-1,5")+COUNTIF(D25:AH25,"x-1,55")+COUNTIF(D25:AH25,"x-2")+COUNTIF(D25:AH25,"x/2")/2 -> 27 | AJ25: =0 -> 0 | AK25: =AI25+AJ25 -> 27
C26: C2 | AI26: =COUNTIF(D26:AH26,"x")+COUNTIF(D26:AH26,"x-0,25")+COUNTIF(D26:AH26,"x-0,50")+COUNTIF(D26:AH26,"x-0.75")+COUNTIF(D26:AH26,"x-1")+COUNTIF(D26:AH26,"x-1,25")+COUNTIF(D26:AH26,"x-1,5")+COUNTIF(D26:AH26,"x-1,55")+COUNTIF(D26:AH26,"x-2")+COUNTIF(D26:AH26,"x/2")/2 -> 0 | AJ26: =0 -> 0 | AK26: =AI26+AJ26 -> 0
C27: C3 | AI27: =COUNTIF(D27:AH27,"x")+COUNTIF(D27:AH27,"x-0,25")+COUNTIF(D27:AH27,"x-0,50")+COUNTIF(D27:AH27,"x-0.75")+COUNTIF(D27:AH27,"x-1")+COUNTIF(D27:AH27,"x-1,25")+COUNTIF(D27:AH27,"x-1,5")+COUNTIF(D27:AH27,"x-1,55")+COUNTIF(D27:AH27,"x-2")+COUNTIF(D27:AH27,"x/2")/2 -> 0 | AJ27: =0 -> 0 | AK27: =AI27+AJ27 -> 0
AI28: ="" | AJ28: ="" | AK28: =""
A29: 6 | B29: Trần Văn Nhận | C29: TC | AH29: 12.5 | AI29: =0 -> 0 | AJ29: =SUM(D29:AH29)/8 -> 1.5625 | AK29: =AI29+AJ29 -> 1.5625
C30: C1 | D30: x | E30: x | G30: x | H30: x | I30: x | J30: x | K30: x | L30: x | M30: x | N30: x | O30: x | P30: x | Q30: x | R30: X | S30: x | T30: x | U30: x | V30: x/7 | W30: x | X30: x | Y30: x | Z30: x | AB30: x | AC30: x | AD30: x | AE30: x | AF30: x | AG30: x | AI30: =COUNTIF(D30:AH30,"x")+COUNTIF(D30:AH30,"x-0,25")+COUNTIF(D30:AH30,"x-0,50")+COUNTIF(D30:AH30,"x-0.75")+COUNTIF(D30:AH30,"x-1")+COUNTIF(D30:AH30,"x-1,25")+COUNTIF(D30:AH30,"x-1,5")+COUNTIF(D30:AH30,"x-1,55")+COUNTIF(D30:AH30,"x-2")+COUNTIF(D30:AH30,"x/2")/2 -> 27 | AJ30: =0 -> 0 | AK30: =0 -> 0
C31: C2 | AI31: =COUNTIF(D31:AH31,"x")+COUNTIF(D31:AH31,"x-0,25")+COUNTIF(D31:AH31,"x-0,50")+COUNTIF(D31:AH31,"x-0.75")+COUNTIF(D31:AH31,"x-1")+COUNTIF(D31:AH31,"x-1,25")+COUNTIF(D31:AH31,"x-1,5")+COUNTIF(D31:AH31,"x-1,55")+COUNTIF(D31:AH31,"x-2")+COUNTIF(D31:AH31,"x/2")/2 -> 0 | AJ31: =0 -> 0 | AK31: =AI31+AJ31 -> 0
C32: C3 | AI32: =COUNTIF(D32:AH32,"x")+COUNTIF(D32:AH32,"x-0,25")+COUNTIF(D32:AH32,"x-0,50")+COUNTIF(D32:AH32,"x-0.75")+COUNTIF(D32:AH32,"x-1")+COUNTIF(D32:AH32,"x-1,25")+COUNTIF(D32:AH32,"x-1,5")+COUNTIF(D32:AH32,"x-1,55")+COUNTIF(D32:AH32,"x-2")+COUNTIF(D32:AH32,"x/2")/2 -> 0 | AJ32: =0 -> 0 | AK32: =AI32+AJ32 -> 0
AI33: ="" | AJ33: ="" | AK33: =""
A34: 7 | B34: Phùng Gia Phúc | C34: TC | AH34: 13.5 | AI34: =0 -> 0 | AJ34: =SUM(D34:AH34)/8 -> 1.6875 | AK34: =AI34+AJ34 -> 1.6875
C35: C1 | D35: x | E35: x | G35: x | H35: x | I35: x | J35: x | K35: x | L35: x | M35: x | N35: x | O35: x | P35: x | Q35: x | R35: X | S35: x | T35: x | U35: x | V35: x/8 | W35: x | X35: x | Y35: x | Z35: x | AB35: x | AC35: x | AD35: x | AE35: x | AF35: x | AG35: x | AI35: =COUNTIF(D35:AH35,"x")+COUNTIF(D35:AH35,"x-0,25")+COUNTIF(D35:AH35,"x-0,50")+COUNTIF(D35:AH35,"x-0.75")+COUNTIF(D35:AH35,"x-1")+COUNTIF(D35:AH35,"x-1,25")+COUNTIF(D35:AH35,"x-1,5")+COUNTIF(D35:AH35,"x-1,55")+COUNTIF(D35:AH35,"x-2")+COUNTIF(D35:AH35,"x/2")/2 -> 27 | AJ35: =0 -> 0 | AK35: =AI35+AJ35 -> 27
C36: C2 | AI36: =COUNTIF(D36:AH36,"x")+COUNTIF(D36:AH36,"x-0,25")+COUNTIF(D36:AH36,"x-0,50")+COUNTIF(D36:AH36,"x-0.75")+COUNTIF(D36:AH36,"x-1")+COUNTIF(D36:AH36,"x-1,25")+COUNTIF(D36:AH36,"x-1,5")+COUNTIF(D36:AH36,"x-1,55")+COUNTIF(D36:AH36,"x-2")+COUNTIF(D36:AH36,"x/2")/2 -> 0 | AJ36: =0 -> 0 | AK36: =AI36+AJ36 -> 0
C37: C3 | AI37: =COUNTIF(D37:AH37,"x")+COUNTIF(D37:AH37,"x-0,25")+COUNTIF(D37:AH37,"x-0,50")+COUNTIF(D37:AH37,"x-0.75")+COUNTIF(D37:AH37,"x-1")+COUNTIF(D37:AH37,"x-1,25")+COUNTIF(D37:AH37,"x-1,5")+COUNTIF(D37:AH37,"x-1,55")+COUNTIF(D37:AH37,"x-2")+COUNTIF(D37:AH37,"x/2")/2 -> 0 | AJ37: =0 -> 0 | AK37: =AI37+AJ37 -> 0
AI38: ="" | AJ38: ="" | AK38: =""
A39: 8 | B39: Trần Văn Quỳnh | C39: TC | AH39: 14.5 | AI39: =0 -> 0 | AJ39: =SUM(D39:AH39)/8 -> 1.8125 | AK39: =AI39+AJ39 -> 1.8125
C40: C1 | D40: x | E40: x | G40: x | H40: x | I40: x | J40: x | K40: x | L40: x | M40: x | N40: x | O40: x | P40: x | Q40: x | R40: X | S40: x | T40: x | U40: x | V40: x/9 | W40: x | X40: x | Y40: x | Z40: x | AB40: x | AC40: x | AD40: x | AE40: x | AF40: x | AG40: x | AI40: =COUNTIF(D40:AH40,"x")+COUNTIF(D40:AH40,"x-0,25")+COUNTIF(D40:AH40,"x-0,50")+COUNTIF(D40:AH40,"x-0.75")+COUNTIF(D40:AH40,"x-1")+COUNTIF(D40:AH40,"x-1,25")+COUNTIF(D40:AH40,"x-1,5")+COUNTIF(D40:AH40,"x-1,55")+COUNTIF(D40:AH40,"x-2")+COUNTIF(D40:AH40,"x/2")/2 -> 27 | AJ40: =0 -> 0 | AK40: =AI40+AJ40 -> 27
...

Sheet T4
A1: Px GCCK | D1: BẢNG CHẤM CÔNG THÁNG - THÁNG 4/2026 | AI1: Tổng công ca | AJ1: Tổng công TC | AK1: ∑
D2: 46113
A3: STT | B3: Họ tên | D3: 46113 | E3: 46114 | F3: =+E3+1 -> 46115 | G3: =+F3+1 -> 46116 | H3: =+G3+1 -> 46117 | I3: =+H3+1 -> 46118 | J3: =+I3+1 -> 46119 | K3: =+J3+1 -> 46120 | L3: =+K3+1 -> 46121 | M3: =+L3+1 -> 46122 | ... AH3: =+AG3+1 -> 46143
A4: 1 | B4: Nguyễn Trung Đông | C4: TC | U4: 5.25 | Z4: 4 | AA4: 4 | AB4: 3 | AD4: 2 | AE4: 4 | AF4: 4 | AI4: =0 -> 0 | AJ4: =SUM(D4:AH4)/8 -> 3.28125 | AK4: =AI4+AJ4 -> 3.28125
C5: C1 | D5: x | E5: x | F5: x | G5: x | H5: x | I5: x | J5: x | K5: x | L5: x | M5: x | N5: 0 | O5: x | P5: x | Q5: x | R5: x | S5: x | T5: x | W5: x | X5: x | Y5: x | Z5: x | AA5: x | AB5: x | AD5: x | AE5: x | AF5: x | AI5: =COUNTIF(D5:AH5,"x")+COUNTIF(D5:AH5,"x-0,25")+COUNTIF(D5:AH5,"x-0,50")+COUNTIF(D5:AH5,"x-0.75")+COUNTIF(D5:AH5,"x-1")+COUNTIF(D5:AH5,"x-1,25")+COUNTIF(D5:AH5,"x-1,5")+COUNTIF(D5:AH5,"x-1,55")+COUNTIF(D5:AH5,"x-2")+COUNTIF(D5:AH5,"x/2")/2 -> 25 | AJ5: =0 -> 0 | AK5: =AI5+AJ5 -> 25
C6: C2 | AI6: =COUNTIF(D6:AH6,"x")+COUNTIF(D6:AH6,"x-0,25")+COUNTIF(D6:AH6,"x-0,50")+COUNTIF(D6:AH6,"x-0.75")+COUNTIF(D6:AH6,"x-1")+COUNTIF(D6:AH6,"x-1,25")+COUNTIF(D6:AH6,"x-1,5")+COUNTIF(D6:AH6,"x-1,55")+COUNTIF(D6:AH6,"x-2")+COUNTIF(D6:AH6,"x/2")/2 -> 0 | AJ6: =0 -> 0 | AK6: =AI6+AJ6 -> 0
C7: C3 | AI7: =COUNTIF(D7:AH7,"x")+COUNTIF(D7:AH7,"x-0,25")+COUNTIF(D7:AH7,"x-0,50")+COUNTIF(D7:AH7,"x-0.75")+COUNTIF(D7:AH7,"x-1")+COUNTIF(D7:AH7,"x-1,25")+COUNTIF(D7:AH7,"x-1,5")+COUNTIF(D7:AH7,"x-1,55")+COUNTIF(D7:AH7,"x-2")+COUNTIF(D7:AH7,"x/2")/2 -> 0 | AJ7: =0 -> 0 | AK7: =AI7+AJ7 -> 0
AI8: ="" | AJ8: ="" | AK8: =""
A9: 2 | B9: Trần Văn Dũng | C9: TC | Z9: 4 | AA9: 4 | AB9: 4 | AD9: 4 | AE9: 4 | AF9: 4 | AI9: =0 -> 0 | AJ9: =SUM(D9:AH9)/8 -> 3 | AK9: =AI9+AJ9 -> 3
C10: C1 | D10: x | E10: x | F10: x | G10: x | H10: x | I10: x | J10: x | K10: x | L10: x | M10: x | N10: x | O10: x | P10: x | Q10: x | R10: x | S10: x | T10: x | U10: x | V10: x | W10: x | X10: x | Y10: x | Z10: x | AA10: x | AB10: x | AD10: x | AE10: x | AF10: x | AI10: =COUNTIF(D10:AH10,"x")+COUNTIF(D10:AH10,"x-0,25")+COUNTIF(D10:AH10,"x-0,50")+COUNTIF(D10:AH10,"x-0.75")+COUNTIF(D10:AH10,"x-1")+COUNTIF(D10:AH10,"x-1,25")+COUNTIF(D10:AH10,"x-1,5")+COUNTIF(D10:AH10,"x-1,55")+COUNTIF(D10:AH10,"x-2")+COUNTIF(D10:AH10,"x/2")/2 -> 28 | AJ10: =0 -> 0 | AK10: =AI10+AJ10 -> 28
C11: C2 | AI11: =COUNTIF(D11:AH11,"x")+COUNTIF(D11:AH11,"x-0,25")+COUNTIF(D11:AH11,"x-0,50")+COUNTIF(D11:AH11,"x-0.75")+COUNTIF(D11:AH11,"x-1")+COUNTIF(D11:AH11,"x-1,25")+COUNTIF(D11:AH11,"x-1,5")+COUNTIF(D11:AH11,"x-1,55")+COUNTIF(D11:AH11,"x-2")+COUNTIF(D11:AH11,"x/2")/2 -> 0 | AJ11: =0 -> 0 | AK11: =AI11+AJ11 -> 0
C12: C3 | AI12: =COUNTIF(D12:AH12,"x")+COUNTIF(D12:AH12,"x-0,25")+COUNTIF(D12:AH12,"x-0,50")+COUNTIF(D12:AH12,"x-0.75")+COUNTIF(D12:AH12,"x-1")+COUNTIF(D12:AH12,"x-1,25")+COUNTIF(D12:AH12,"x-1,5")+COUNTIF(D12:AH12,"x-1,55")+COUNTIF(D12:AH12,"x-2")+COUNTIF(D12:AH12,"x/2")/2 -> 0 | AJ12: =0 -> 0 | AK12: =AI12+AJ12 -> 0
AI13: ="" | AJ13: ="" | AK13: =""
A14: 3 | B14: Hoàng Ngọc Hà | C14: TC | J14: -0.08 | Q14: 2 | S14: 3.7 | Z14: -0.75 | AF14: -1 | AI14: =0 -> 0 | AJ14: =SUM(D14:AH14)/8 -> 0.48375 | AK14: =AI14+AJ14 -> 0.48375
C15: C1 | D15: x | E15: x | F15: x | G15: x | I15: x | J15: x | K15: x | L15: x | M15: x | N15: x | O15: x | P15: x | Q15: x | R15: x | T15: x | U15: x | V15: x | W15: x | X15: x | Y15: x | Z15: x | AA15: x | AB15: x | AD15: x | AE15: x | AF15: x | AI15: =COUNTIF(D15:AH15,"x")+COUNTIF(D15:AH15,"x-0,25")+COUNTIF(D15:AH15,"x-0,50")+COUNTIF(D15:AH15,"x-0.75")+COUNTIF(D15:AH15,"x-1")+COUNTIF(D15:AH15,"x-1,25")+COUNTIF(D15:AH15,"x-1,5")+COUNTIF(D15:AH15,"x-1,55")+COUNTIF(D15:AH15,"x-2")+COUNTIF(D15:AH15,"x/2")/2 -> 26 | AJ15: =0 -> 0 | AK15: =AI15+AJ15 -> 26
C16: C2 | AI16: =COUNTIF(D16:AH16,"x")+COUNTIF(D16:AH16,"x-0,25")+COUNTIF(D16:AH16,"x-0,50")+COUNTIF(D16:AH16,"x-0.75")+COUNTIF(D16:AH16,"x-1")+COUNTIF(D16:AH16,"x-1,25")+COUNTIF(D16:AH16,"x-1,5")+COUNTIF(D16:AH16,"x-1,55")+COUNTIF(D16:AH16,"x-2")+COUNTIF(D16:AH16,"x/2")/2 -> 0 | AJ16: =0 -> 0 | AK16: =AI16+AJ16 -> 0
C17: C3 | AI17: =COUNTIF(D17:AH17,"x")+COUNTIF(D17:AH17,"x-0,25")+COUNTIF(D17:AH17,"x-0,50")+COUNTIF(D17:AH17,"x-0.75")+COUNTIF(D17:AH17,"x-1")+COUNTIF(D17:AH17,"x-1,25")+COUNTIF(D17:AH17,"x-1,5")+COUNTIF(D17:AH17,"x-1,55")+COUNTIF(D17:AH17,"x-2")+COUNTIF(D17:AH17,"x/2")/2 -> 0 | AJ17: =0 -> 0 | AK17: =AI17+AJ17 -> 0
AI18: ="" | AJ18: ="" | AK18: =AI18+AJ18 -> #VALUE!
A19: 4 | B19: Phùng Đình Hùng | C19: TC | AD19: 4 | AE19: 4 | AF19: 4 | AI19: =0 -> 0 | AJ19: =SUM(D19:AH19)/8 -> 1.5 | AK19: =AI19+AJ19 -> 1.5
C20: C1 | D20: x | E20: x | F20: x | G20: x | I20: x | J20: x | K20: x | L20: x | M20: x | N20: x | P20: x | Q20: x | R20: x | S20: x | T20: x | U20: x | W20: x | X20: x | Y20: x | Z20: x | AA20: x | AB20: 0 | AD20: x | AE20: x | AF20: x | AI20: =COUNTIF(D20:AH20,"x")+COUNTIF(D20:AH20,"x-0,25")+COUNTIF(D20:AH20,"x-0,50")+COUNTIF(D20:AH20,"x-0.75")+COUNTIF(D20:AH20,"x-1")+COUNTIF(D20:AH20,"x-1,25")+COUNTIF(D20:AH20,"x-1,5")+COUNTIF(D20:AH20,"x-1,55")+COUNTIF(D20:AH20,"x-2")+COUNTIF(D20:AH20,"x/2")/2 -> 24 | AJ20: =0 -> 0 | AK20: =AI20+AJ20 -> 24
C21: C2 | AI21: =COUNTIF(D21:AH21,"x")+COUNTIF(D21:AH21,"x-0,25")+COUNTIF(D21:AH21,"x-0,50")+COUNTIF(D21:AH21,"x-0.75")+COUNTIF(D21:AH21,"x-1")+COUNTIF(D21:AH21,"x-1,25")+COUNTIF(D21:AH21,"x-1,5")+COUNTIF(D21:AH21,"x-1,55")+COUNTIF(D21:AH21,"x-2")+COUNTIF(D21:AH21,"x/2")/2 -> 0 | AJ21: =0 -> 0 | AK21: =AI21+AJ21 -> 0
C22: C3 | AI22: =COUNTIF(D22:AH22,"x")+COUNTIF(D22:AH22,"x-0,25")+COUNTIF(D22:AH22,"x-0,50")+COUNTIF(D22:AH22,"x-0.75")+COUNTIF(D22:AH22,"x-1")+COUNTIF(D22:AH22,"x-1,25")+COUNTIF(D22:AH22,"x-1,5")+COUNTIF(D22:AH22,"x-1,55")+COUNTIF(D22:AH22,"x-2")+COUNTIF(D22:AH22,"x/2")/2 -> 0 | AJ22: =0 -> 0 | AK22: =AI22+AJ22 -> 0
AI23: ="" | AJ23: ="" | AK23: =""
A24: 5 | B24: Đặng Ngọc Long | C24: TC | Z24: 4 | AA24: 4 | AB24: 4 | AD24: 4 | AE24: 4 | AF24: 4 | AI24: =0 -> 0 | AJ24: =SUM(D24:AH24)/8 -> 3 | AK24: =AI24+AJ24 -> 3
C25: C1 | D25: x | E25: x | F25: x | G25: x | I25: x | J25: x | K25: x | L25: x | M25: x | N25: x | O25: x | P25: x | Q25: x | R25: x | S25: x | T25: x | U25: x | V25: x | W25: x | X25: x | Y25: 0 | Z25: x | AA25: x | AB25: x | AD25: x | AE25: x | AF25: x | AI25: =COUNTIF(D25:AH25,"x")+COUNTIF(D25:AH25,"x-0,25")+COUNTIF(D25:AH25,"x-0,50")+COUNTIF(D25:AH25,"x-0.75")+COUNTIF(D25:AH25,"x-1")+COUNTIF(D25:AH25,"x-1,25")+COUNTIF(D25:AH25,"x-1,5")+COUNTIF(D25:AH25,"x-1,55")+COUNTIF(D25:AH25,"x-2")+COUNTIF(D25:AH25,"x/2")/2 -> 26 | AJ25: =0 -> 0 | AK25: =AI25+AJ25 -> 26
C26: C2 | AI26: =COUNTIF(D26:AH26,"x")+COUNTIF(D26:AH26,"x-0,25")+COUNTIF(D26:AH26,"x-0,50")+COUNTIF(D26:AH26,"x-0.75")+COUNTIF(D26:AH26,"x-1")+COUNTIF(D26:AH26,"x-1,25")+COUNTIF(D26:AH26,"x-1,5")+COUNTIF(D26:AH26,"x-1,55")+COUNTIF(D26:AH26,"x-2")+COUNTIF(D26:AH26,"x/2")/2 -> 0 | AJ26: =0 -> 0 | AK26: =AI26+AJ26 -> 0
C27: C3 | AI27: =COUNTIF(D27:AH27,"x")+COUNTIF(D27:AH27,"x-0,25")+COUNTIF(D27:AH27,"x-0,50")+COUNTIF(D27:AH27,"x-0.75")+COUNTIF(D27:AH27,"x-1")+COUNTIF(D27:AH27,"x-1,25")+COUNTIF(D27:AH27,"x-1,5")+COUNTIF(D27:AH27,"x-1,55")+COUNTIF(D27:AH27,"x-2")+COUNTIF(D27:AH27,"x/2")/2 -> 0 | AJ27: =0 -> 0 | AK27: =AI27+AJ27 -> 0
AI28: ="" | AJ28: ="" | AK28: =""
A29: 6 | B29: Trần Văn Nhận | C29: TC | Z29: 4 | AA29: 4 | AB29: 4 | AD29: 4 | AE29: 4 | AF29: 4 | AI29: =0 -> 0 | AJ29: =SUM(D29:AH29)/8 -> 3 | AK29: =AI29+AJ29 -> 3
C30: C1 | D30: x | E30: x | F30: x | G30: x | H30: x | I30: x | J30: x | K30: x | L30: x | M30: x | N30: x | O30: x | P30: x | Q30: x | R30: x | S30: x | T30: x | U30: x | V30: x | W30: x | X30: x | Y30: x | Z30: x | AA30: x | AB30: x | AD30: x | AE30: x | AF30: x | AI30: =COUNTIF(D30:AH30,"x")+COUNTIF(D30:AH30,"x-0,25")+COUNTIF(D30:AH30,"x-0,50")+COUNTIF(D30:AH30,"x-0.75")+COUNTIF(D30:AH30,"x-1")+COUNTIF(D30:AH30,"x-1,25")+COUNTIF(D30:AH30,"x-1,5")+COUNTIF(D30:AH30,"x-1,55")+COUNTIF(D30:AH30,"x-2")+COUNTIF(D30:AH30,"x/2")/2 -> 28 | AJ30: =0 -> 0 | AK30: =0 -> 0
C31: C2 | AI31: =COUNTIF(D31:AH31,"x")+COUNTIF(D31:AH31,"x-0,25")+COUNTIF(D31:AH31,"x-0,50")+COUNTIF(D31:AH31,"x-0.75")+COUNTIF(D31:AH31,"x-1")+COUNTIF(D31:AH31,"x-1,25")+COUNTIF(D31:AH31,"x-1,5")+COUNTIF(D31:AH31,"x-1,55")+COUNTIF(D31:AH31,"x-2")+COUNTIF(D31:AH31,"x/2")/2 -> 0 | AJ31: =0 -> 0 | AK31: =AI31+AJ31 -> 0
C32: C3 | AI32: =COUNTIF(D32:AH32,"x")+COUNTIF(D32:AH32,"x-0,25")+COUNTIF(D32:AH32,"x-0,50")+COUNTIF(D32:AH32,"x-0.75")+COUNTIF(D32:AH32,"x-1")+COUNTIF(D32:AH32,"x-1,25")+COUNTIF(D32:AH32,"x-1,5")+COUNTIF(D32:AH32,"x-1,55")+COUNTIF(D32:AH32,"x-2")+COUNTIF(D32:AH32,"x/2")/2 -> 0 | AJ32: =0 -> 0 | AK32: =AI32+AJ32 -> 0
AI33: ="" | AJ33: ="" | AK33: =""
A34: 7 | B34: Phùng Gia Phúc | C34: TC | Z34: 4 | AA34: 4 | AB34: 4 | AD34: 4 | AE34: 4 | AF34: 2 | AI34: =0 -> 0 | AJ34: =SUM(D34:AH34)/8 -> 2.75 | AK34: =AI34+AJ34 -> 2.75
C35: C1 | D35: x | E35: x | F35: x | G35: x | I35: x | J35: x | K35: x | L35: x/2 | M35: x | N35: x | O35: x | P35: x | Q35: x | R35: x | S35: x | T35: x | U35: x | V35: x | W35: x | X35: x | Y35: x | Z35: x | AA35: x | AB35: x | AC35: x | AD35: x | AE35: x | AF35: x | AI35: =COUNTIF(D35:AH35,"x")+COUNTIF(D35:AH35,"x-0,25")+COUNTIF(D35:AH35,"x-0,50")+COUNTIF(D35:AH35,"x-0.75")+COUNTIF(D35:AH35,"x-1")+COUNTIF(D35:AH35,"x-1,25")+COUNTIF(D35:AH35,"x-1,5")+COUNTIF(D35:AH35,"x-1,55")+COUNTIF(D35:AH35,"x-2")+COUNTIF(D35:AH35,"x/2")/2 -> 27.5 | AJ35: =0 -> 0 | AK35: =AI35+AJ35 -> 27.5
C36: C2 | AI36: =COUNTIF(D36:AH36,"x")+COUNTIF(D36:AH36,"x-0,25")+COUNTIF(D36:AH36,"x-0,50")+COUNTIF(D36:AH36,"x-0.75")+COUNTIF(D36:AH36,"x-1")+COUNTIF(D36:AH36,"x-1,25")+COUNTIF(D36:AH36,"x-1,5")+COUNTIF(D36:AH36,"x-1,55")+COUNTIF(D36:AH36,"x-2")+COUNTIF(D36:AH36,"x/2")/2 -> 0 | AJ36: =0 -> 0 | AK36: =AI36+AJ36 -> 0
C37: C3 | AI37: =COUNTIF(D37:AH37,"x")+COUNTIF(D37:AH37,"x-0,25")+COUNTIF(D37:AH37,"x-0,50")+COUNTIF(D37:AH37,"x-0.75")+COUNTIF(D37:AH37,"x-1")+COUNTIF(D37:AH37,"x-1,25")+COUNTIF(D37:AH37,"x-1,5")+COUNTIF(D37:AH37,"x-1,55")+COUNTIF(D37:AH37,"x-2")+COUNTIF(D37:AH37,"x/2")/2 -> 0 | AJ37: =0 -> 0 | AK37: =AI37+AJ37 -> 0
AI38: ="" | AJ38: ="" | AK38: =""
A39: 8 | B39: Trần Văn Quỳnh | C39: TC | T39: 2 | Z39: 4 | AA39: 4 | AB39: 4 | AD39: 4 | AE39: 4 | AF39: 4 | AI39: =0 -> 0 | AJ39: =SUM(D39:AH39)/8 -> 3.25 | AK39: =AI39+AJ39 -> 3.25
C40: C1 | D40: x | E40: x | F40: x | G40: x | I40: x | J40: x | K40: x | L40: x | M40: x | N40: x | O40: x | P40: x | Q40: x | R40: x | S40: x | T40: x | U40: x | V40: x | W40: x | X40: x | Y40: x | Z40: x | AA40: x | AB40: x | AD40: x | AE40: x | AF40: x | AI40: =COUNTIF(D40:AH40,"x")+COUNTIF(D40:AH40,"x-0,25")+COUNTIF(D40:AH40,"x-0,50")+COUNTIF(D40:AH40,"x-0.75")+COUNTIF(D40:AH40,"x-1")+COUNTIF(D40:AH40,"x-1,25")+COUNTIF(D40:AH40,"x-1,5")+COUNTIF(D40:AH40,"x-1,55")+COUNTIF(D40:AH40,"x-2")+COUNTIF(D40:AH40,"x/2")/2 -> 27 | AJ40: =0 -> 0 | AK40: =AI40+AJ40 -> 27
...

Sheet T5
A1: Px GCCK | D1: BẢNG CHẤM CÔNG THÁNG - THÁNG 5/2026 | AI1: Tổng công ca | AJ1: Tổng công TC | AK1: ∑
D2: 46143
A3: STT | B3: Họ tên | D3: 46143 | E3: 46144 | F3: =+E3+1 -> 46145 | G3: =+F3+1 -> 46146 | H3: =+G3+1 -> 46147 | I3: =+H3+1 -> 46148 | J3: =+I3+1 -> 46149 | K3: =+J3+1 -> 46150 | L3: =+K3+1 -> 46151 | M3: =+L3+1 -> 46152 | ... AH3: =+AG3+1 -> 46173
A4: 1 | B4: Nguyễn Trung Đông | C4: TC | AI4: =0 -> 0 | AJ4: =SUM(D4:AH4)/8 -> 0 | AK4: =AI4+AJ4 -> 0
C5: C1 | N5: x | P5: x | Q5: x | R5: x | S5: x | AI5: =COUNTIF(D5:AH5,"x")+COUNTIF(D5:AH5,"x-0,25")+COUNTIF(D5:AH5,"x-0,50")+COUNTIF(D5:AH5,"x-0.75")+COUNTIF(D5:AH5,"x-1")+COUNTIF(D5:AH5,"x-1,25")+COUNTIF(D5:AH5,"x-1,5")+COUNTIF(D5:AH5,"x-1,55")+COUNTIF(D5:AH5,"x-2")+COUNTIF(D5:AH5,"x/2")/2 -> 5 | AJ5: =0 -> 0 | AK5: =AI5+AJ5 -> 5
C6: C2 | F6: x | G6: 0 | H6: x | I6: x | J6: x | K6: x | L6: 0 | O6: x | AB6: x | AC6: x | AD6: x | AE6: x | AF6: x | AG6: x | AH6: x | AI6: =COUNTIF(D6:AH6,"x")+COUNTIF(D6:AH6,"x-0,25")+COUNTIF(D6:AH6,"x-0,50")+COUNTIF(D6:AH6,"x-0.75")+COUNTIF(D6:AH6,"x-1")+COUNTIF(D6:AH6,"x-1,25")+COUNTIF(D6:AH6,"x-1,5")+COUNTIF(D6:AH6,"x-1,55")+COUNTIF(D6:AH6,"x-2")+COUNTIF(D6:AH6,"x/2")/2 -> 13 | AJ6: =0 -> 0 | AK6: =AI6+AJ6 -> 13
C7: C3 | E7: x | T7: x | U7: x | V7: x | W7: x | X7: x | Y7: x | Z7: x | AI7: =COUNTIF(D7:AH7,"x")+COUNTIF(D7:AH7,"x-0,25")+COUNTIF(D7:AH7,"x-0,50")+COUNTIF(D7:AH7,"x-0.75")+COUNTIF(D7:AH7,"x-1")+COUNTIF(D7:AH7,"x-1,25")+COUNTIF(D7:AH7,"x-1,5")+COUNTIF(D7:AH7,"x-1,55")+COUNTIF(D7:AH7,"x-2")+COUNTIF(D7:AH7,"x/2")/2 -> 8 | AJ7: =0 -> 0 | AK7: =AI7+AJ7 -> 8
AI8: =0 -> 0 | AJ8: =SUM(D8:AH8)/8 -> 0 | AK8: =AI8+AJ8 -> 0
A9: 2 | B9: Trần Văn Dũng | C9: TC | AI9: =0 -> 0 | AJ9: =SUM(D9:AH9)/8 -> 0 | AK9: =AI9+AJ9 -> 0
C10: C1 | E10: x | T10: x | U10: x | V10: x | W10: x | X10: x | Y10: x | Z10: x | AI10: =COUNTIF(D10:AH10,"x")+COUNTIF(D10:AH10,"x-0,25")+COUNTIF(D10:AH10,"x-0,50")+COUNTIF(D10:AH10,"x-0.75")+COUNTIF(D10:AH10,"x-1")+COUNTIF(D10:AH10,"x-1,25")+COUNTIF(D10:AH10,"x-1,5")+COUNTIF(D10:AH10,"x-1,55")+COUNTIF(D10:AH10,"x-2")+COUNTIF(D10:AH10,"x/2")/2 -> 8 | AJ10: =0 -> 0 | AK10: =AI10+AJ10 -> 8
C11: C2 | N11: x | O11: x | P11: x | Q11: x | R11: x | S11: x | AH11: x | AI11: =COUNTIF(D11:AH11,"x")+COUNTIF(D11:AH11,"x-0,25")+COUNTIF(D11:AH11,"x-0,50")+COUNTIF(D11:AH11,"x-0.75")+COUNTIF(D11:AH11,"x-1")+COUNTIF(D11:AH11,"x-1,25")+COUNTIF(D11:AH11,"x-1,5")+COUNTIF(D11:AH11,"x-1,55")+COUNTIF(D11:AH11,"x-2")+COUNTIF(D11:AH11,"x/2")/2 -> 7 | AJ11: =0 -> 0 | AK11: =AI11+AJ11 -> 7
C12: C3 | F12: x | G12: x | H12: 0 | I12: x | J12: x | K12: x | L12: x | AA12: x | AB12: x | AC12: x | AD12: x | AE12: x | AF12: x | AG12: x | AI12: =COUNTIF(D12:AH12,"x")+COUNTIF(D12:AH12,"x-0,25")+COUNTIF(D12:AH12,"x-0,50")+COUNTIF(D12:AH12,"x-0.75")+COUNTIF(D12:AH12,"x-1")+COUNTIF(D12:AH12,"x-1,25")+COUNTIF(D12:AH12,"x-1,5")+COUNTIF(D12:AH12,"x-1,55")+COUNTIF(D12:AH12,"x-2")+COUNTIF(D12:AH12,"x/2")/2 -> 13 | AJ12: =0 -> 0 | AK12: =AI12+AJ12 -> 13
AI13: =0 -> 0 | AJ13: =SUM(D13:AH13)/8 -> 0 | AK13: =AI13+AJ13 -> 0
A14: 3 | B14: Hoàng Ngọc Hà | C14: TC | AI14: =0 -> 0 | AJ14: =SUM(D14:AH14)/8 -> 0 | AK14: =AI14+AJ14 -> 0
C15: C1 | G15: x | H15: x | I15: x | J15: x | K15: x | L15: x-1,25 | N15: x | O15: x | P15: x | Q15: x/2 | R15: x | S15: x | U15: x | V15: X-1 | W15: x | X15: x | Y15: x | Z15: x/2 | AB15: x | AC15: x | AD15: x | AE15: x/2 | AF15: x | AG15: x | AH15: x | AI15: =COUNTIF(D15:AH15,"x")+COUNTIF(D15:AH15,"x-0,25")+COUNTIF(D15:AH15,"x-0,50")+COUNTIF(D15:AH15,"x-0.75")+COUNTIF(D15:AH15,"x-1")+COUNTIF(D15:AH15,"x-1,25")+COUNTIF(D15:AH15,"x-1,5")+COUNTIF(D15:AH15,"x-1,55")+COUNTIF(D15:AH15,"x-2")+COUNTIF(D15:AH15,"x/2")/2 -> 23.5 | AJ15: =0 -> 0 | AK15: =AI15+AJ15 -> 23.5
C16: C2 | M16: x | T16: x/2 | AA16: x-0.75 | AI16: =COUNTIF(D16:AH16,"x")+COUNTIF(D16:AH16,"x-0,25")+COUNTIF(D16:AH16,"x-0,50")+COUNTIF(D16:AH16,"x-0.75")+COUNTIF(D16:AH16,"x-1")+COUNTIF(D16:AH16,"x-1,25")+COUNTIF(D16:AH16,"x-1,5")+COUNTIF(D16:AH16,"x-1,55")+COUNTIF(D16:AH16,"x-2")+COUNTIF(D16:AH16,"x/2")/2 -> 2.5 | AJ16: =0 -> 0 | AK16: =AI16+AJ16 -> 2.5
C17: C3 | AI17: =COUNTIF(D17:AH17,"x")+COUNTIF(D17:AH17,"x-0,25")+COUNTIF(D17:AH17,"x-0,50")+COUNTIF(D17:AH17,"x-0.75")+COUNTIF(D17:AH17,"x-1")+COUNTIF(D17:AH17,"x-1,25")+COUNTIF(D17:AH17,"x-1,5")+COUNTIF(D17:AH17,"x-1,55")+COUNTIF(D17:AH17,"x-2")+COUNTIF(D17:AH17,"x/2")/2 -> 0 | AJ17: =0 -> 0 | AK17: =AI17+AJ17 -> 0
AI18: =0 -> 0 | AJ18: =SUM(D18:AH18)/8 -> 0 | AK18: =AI18+AJ18 -> 0
A19: 4 | B19: Phùng Đình Hùng | C19: TC | AI19: =0 -> 0 | AJ19: =SUM(D19:AH19)/8 -> 0 | AK19: =AI19+AJ19 -> 0
C20: C1 | M20: x | N20: x | O20: x | P20: x | S20: x | U20: x | V20: x | W20: x | X20: x | Y20: x | Z20: x | AI20: =COUNTIF(D20:AH20,"x")+COUNTIF(D20:AH20,"x-0,25")+COUNTIF(D20:AH20,"x-0,50")+COUNTIF(D20:AH20,"x-0.75")+COUNTIF(D20:AH20,"x-1")+COUNTIF(D20:AH20,"x-1,25")+COUNTIF(D20:AH20,"x-1,5")+COUNTIF(D20:AH20,"x-1,55")+COUNTIF(D20:AH20,"x-2")+COUNTIF(D20:AH20,"x/2")/2 -> 11 | AJ20: =0 -> 0 | AK20: =AI20+AJ20 -> 11
C21: C2 | E21: x | F21: x | G21: x | H21: x | I21: x | J21: x | K21: x | L21: x | Q21: x | R21: x | AB21: x | AC21: x | AD21: x | AE21: x | AF21: x | AG21: x | AI21: =COUNTIF(D21:AH21,"x")+COUNTIF(D21:AH21,"x-0,25")+COUNTIF(D21:AH21,"x-0,50")+COUNTIF(D21:AH21,"x-0.75")+COUNTIF(D21:AH21,"x-1")+COUNTIF(D21:AH21,"x-1,25")+COUNTIF(D21:AH21,"x-1,5")+COUNTIF(D21:AH21,"x-1,55")+COUNTIF(D21:AH21,"x-2")+COUNTIF(D21:AH21,"x/2")/2 -> 16 | AJ21: =0 -> 0 | AK21: =AI21+AJ21 -> 16
C22: C3 | AI22: =COUNTIF(D22:AH22,"x")+COUNTIF(D22:AH22,"x-0,25")+COUNTIF(D22:AH22,"x-0,50")+COUNTIF(D22:AH22,"x-0.75")+COUNTIF(D22:AH22,"x-1")+COUNTIF(D22:AH22,"x-1,25")+COUNTIF(D22:AH22,"x-1,5")+COUNTIF(D22:AH22,"x-1,55")+COUNTIF(D22:AH22,"x-2")+COUNTIF(D22:AH22,"x/2")/2 -> 0 | AJ22: =0 -> 0 | AK22: =AI22+AJ22 -> 0
AI23: =0 -> 0 | AJ23: =SUM(D23:AH23)/8 -> 0 | AK23: =AI23+AJ23 -> 0
A24: 5 | B24: Đặng Ngọc Long | C24: TC | AI24: =0 -> 0 | AJ24: =SUM(D24:AH24)/8 -> 0 | AK24: =AI24+AJ24 -> 0
C25: C1 | AI25: =COUNTIF(D25:AH25,"x")+COUNTIF(D25:AH25,"x-0,25")+COUNTIF(D25:AH25,"x-0,50")+COUNTIF(D25:AH25,"x-0.75")+COUNTIF(D25:AH25,"x-1")+COUNTIF(D25:AH25,"x-1,25")+COUNTIF(D25:AH25,"x-1,5")+COUNTIF(D25:AH25,"x-1,55")+COUNTIF(D25:AH25,"x-2")+COUNTIF(D25:AH25,"x/2")/2 -> 0 | AJ25: =0 -> 0 | AK25: =AI25+AJ25 -> 0
C26: C2 | E26: x | G26: x | H26: x | I26: x | J26: x | K26: x | L26: x | M26: x | N26: x | O26: x | P26: x | Q26: x | R26: x | S26: x | T26: x | U26: x | V26: x | W26: x | X26: x | Y26: x | Z26: x | AA26: x | AB26: x | AC26: x | AD26: x | AE26: x | AF26: x | AG26: x | AH26: x | AI26: =COUNTIF(D26:AH26,"x")+COUNTIF(D26:AH26,"x-0,25")+COUNTIF(D26:AH26,"x-0,50")+COUNTIF(D26:AH26,"x-0.75")+COUNTIF(D26:AH26,"x-1")+COUNTIF(D26:AH26,"x-1,25")+COUNTIF(D26:AH26,"x-1,5")+COUNTIF(D26:AH26,"x-1,55")+COUNTIF(D26:AH26,"x-2")+COUNTIF(D26:AH26,"x/2")/2 -> 29 | AJ26: =0 -> 0 | AK26: =AI26+AJ26 -> 29
C27: C3 | AI27: =COUNTIF(D27:AH27,"x")+COUNTIF(D27:AH27,"x-0,25")+COUNTIF(D27:AH27,"x-0,50")+COUNTIF(D27:AH27,"x-0.75")+COUNTIF(D27:AH27,"x-1")+COUNTIF(D27:AH27,"x-1,25")+COUNTIF(D27:AH27,"x-1,5")+COUNTIF(D27:AH27,"x-1,55")+COUNTIF(D27:AH27,"x-2")+COUNTIF(D27:AH27,"x/2")/2 -> 0 | AJ27: =0 -> 0 | AK27: =AI27+AJ27 -> 0
AI28: =0 -> 0 | AJ28: ="" | AK28: =""
A29: 6 | B29: Trần Văn Nhận | C29: TC | AI29: =0 -> 0 | AJ29: =SUM(D29:AH29)/8 -> 0 | AK29: =AI29+AJ29 -> 0
C30: C1 | F30: x | G30: x | H30: x | I30: x | J30: x | K30: x | L30: x | AA30: x | AB30: x | AC30: x | AD30: x | AE30: x | AF30: x | AG30: x | AI30: =COUNTIF(D30:AH30,"x")+COUNTIF(D30:AH30,"x-0,25")+COUNTIF(D30:AH30,"x-0,50")+COUNTIF(D30:AH30,"x-0.75")+COUNTIF(D30:AH30,"x-1")+COUNTIF(D30:AH30,"x-1,25")+COUNTIF(D30:AH30,"x-1,5")+COUNTIF(D30:AH30,"x-1,55")+COUNTIF(D30:AH30,"x-2")+COUNTIF(D30:AH30,"x/2")/2 -> 14 | AJ30: =0 -> 0 | AK30: =AI30+AJ30 -> 14
C31: C2 | E31: x | T31: x | U31: x | V31: x | W31: x | X31: x | Y31: x | Z31: x | AI31: =COUNTIF(D31:AH31,"x")+COUNTIF(D31:AH31,"x-0,25")+COUNTIF(D31:AH31,"x-0,50")+COUNTIF(D31:AH31,"x-0.75")+COUNTIF(D31:AH31,"x-1")+COUNTIF(D31:AH31,"x-1,25")+COUNTIF(D31:AH31,"x-1,5")+COUNTIF(D31:AH31,"x-1,55")+COUNTIF(D31:AH31,"x-2")+COUNTIF(D31:AH31,"x/2")/2 -> 8 | AJ31: =0 -> 0 | AK31: =AI31+AJ31 -> 8
C32: C3 | M32: x | N32: x | O32: x | P32: x | Q32: x | R32: x | S32: x | AI32: =COUNTIF(D32:AH32,"x")+COUNTIF(D32:AH32,"x-0,25")+COUNTIF(D32:AH32,"x-0,50")+COUNTIF(D32:AH32,"x-0.75")+COUNTIF(D32:AH32,"x-1")+COUNTIF(D32:AH32,"x-1,25")+COUNTIF(D32:AH32,"x-1,5")+COUNTIF(D32:AH32,"x-1,55")+COUNTIF(D32:AH32,"x-2")+COUNTIF(D32:AH32,"x/2")/2 -> 7 | AJ32: =0 -> 0 | AK32: =AI32+AJ32 -> 7
AI33: =0 -> 0 | AJ33: ="" | AK33: =""
A34: 7 | B34: Phùng Gia Phúc | C34: TC | AI34: =0 -> 0 | AJ34: =SUM(D34:AH34)/8 -> 0 | AK34: =AI34+AJ34 -> 0
C35: C1 | F35: x | G35: x | H35: x | I35: x | J35: x | K35: x | L35: x | AA35: x | AB35: x | AC35: x | AD35: x | AE35: x | AF35: x | AG35: x | AI35: =COUNTIF(D35:AH35,"x")+COUNTIF(D35:AH35,"x-0,25")+COUNTIF(D35:AH35,"x-0,50")+COUNTIF(D35:AH35,"x-0.75")+COUNTIF(D35:AH35,"x-1")+COUNTIF(D35:AH35,"x-1,25")+COUNTIF(D35:AH35,"x-1,5")+COUNTIF(D35:AH35,"x-1,55")+COUNTIF(D35:AH35,"x-2")+COUNTIF(D35:AH35,"x/2")/2 -> 14 | AJ35: =0 -> 0 | AK35: =AI35+AJ35 -> 14
C36: C2 | E36: x | AI36: =COUNTIF(D36:AH36,"x")+COUNTIF(D36:AH36,"x-0,25")+COUNTIF(D36:AH36,"x-0,50")+COUNTIF(D36:AH36,"x-0.75")+COUNTIF(D36:AH36,"x-1")+COUNTIF(D36:AH36,"x-1,25")+COUNTIF(D36:AH36,"x-1,5")+COUNTIF(D36:AH36,"x-1,55")+COUNTIF(D36:AH36,"x-2")+COUNTIF(D36:AH36,"x/2")/2 -> 1 | AJ36: =0 -> 0 | AK36: =AI36+AJ36 -> 1
C37: C3 | M37: x | N37: x | O37: x | P37: x | Q37: x | R37: x | S37: x | U37: x | V37: x | W37: x | X37: x | Y37: x | Z37: x | AH37: x | AI37: =COUNTIF(D37:AH37,"x")+COUNTIF(D37:AH37,"x-0,25")+COUNTIF(D37:AH37,"x-0,50")+COUNTIF(D37:AH37,"x-0.75")+COUNTIF(D37:AH37,"x-1")+COUNTIF(D37:AH37,"x-1,25")+COUNTIF(D37:AH37,"x-1,5")+COUNTIF(D37:AH37,"x-1,55")+COUNTIF(D37:AH37,"x-2")+COUNTIF(D37:AH37,"x/2")/2 -> 14 | AJ37: =0 -> 0 | AK37: =AI37+AJ37 -> 14
AI38: =0 -> 0 | AJ38: ="" | AK38: =""
A39: 8 | B39: Trần Văn Quỳnh | C39: TC | AG39: 1 | AI39: =0 -> 0 | AJ39: =SUM(D39:AH39)/8 -> 0.125 | AK39: =AI39+AJ39 -> 0.125
C40: C1 | F40: x | G40: x | H40: x | I40: x | J40: x | K40: x | L40: x | N40: x | O40: x | P40: x | Q40: x | R40: x | S40: x | AA40: x | AB40: x | AC40: x | AD40: x | AE40: x | AF40: x | AG40: x | AH40: x | AI40: =COUNTIF(D40:AH40,"x")+COUNTIF(D40:AH40,"x-0,25")+COUNTIF(D40:AH40,"x-0,50")+COUNTIF(D40:AH40,"x-0.75")+COUNTIF(D40:AH40,"x-1")+COUNTIF(D40:AH40,"x-1,25")+COUNTIF(D40:AH40,"x-1,5")+COUNTIF(D40:AH40,"x-1,55")+COUNTIF(D40:AH40,"x-2")+COUNTIF(D40:AH40,"x/2")/2 -> 21 | AJ40: =0 -> 0 | AK40: =AI40+AJ40 -> 21
...

Sheet T6
A1: Px GCCK | D1: BẢNG CHẤM CÔNG THÁNG - THÁNG 6/2026 | AI1: Tổng công ca | AJ1: Tổng công TC | AK1: ∑
D2: 46174
A3: STT | B3: Họ tên | D3: 46174 | E3: 46175 | F3: =+E3+1 -> 46176 | G3: =+F3+1 -> 46177 | H3: =+G3+1 -> 46178 | I3: =+H3+1 -> 46179 | J3: =+I3+1 -> 46180 | K3: =+J3+1 -> 46181 | L3: =+K3+1 -> 46182 | M3: =+L3+1 -> 46183 | ... AH3: =+AG3+1 -> 46204
A4: 1 | B4: Nguyễn Trung Đông | C4: TC | Y4: 4 | Z4: 4 | AA4: 3 | AB4: 4 | AC4: 4 | AD4: 3.25 | AF4: 2 | AI4: =0 -> 0 | AJ4: =SUM(D4:AH4)/8 -> 3.03125 | AK4: =AI4+AJ4 -> 3.03125
C5: C1 | D5: 0 | G5: x | H5: x | I5: x | X5: x | Y5: x | Z5: x | AA5: x | AB5: x | AC5: x | AD5: x | AI5: =COUNTIF(D5:AH5,"x")+COUNTIF(D5:AH5,"x-0,25")+COUNTIF(D5:AH5,"x-0,50")+COUNTIF(D5:AH5,"x-0.75")+COUNTIF(D5:AH5,"x-1")+COUNTIF(D5:AH5,"x-1,25")+COUNTIF(D5:AH5,"x-1,5")+COUNTIF(D5:AH5,"x-1,55")+COUNTIF(D5:AH5,"x-2")+COUNTIF(D5:AH5,"x/2")/2 -> 10 | AJ5: =0 -> 0 | AK5: =AI5+AJ5 -> 10
C6: C2 | E6: x | F6: x | S6: x | T6: x | U6: x | V6: x | W6: x | AI6: =COUNTIF(D6:AH6,"x")+COUNTIF(D6:AH6,"x-0,25")+COUNTIF(D6:AH6,"x-0,50")+COUNTIF(D6:AH6,"x-0.75")+COUNTIF(D6:AH6,"x-1")+COUNTIF(D6:AH6,"x-1,25")+COUNTIF(D6:AH6,"x-1,5")+COUNTIF(D6:AH6,"x-1,55")+COUNTIF(D6:AH6,"x-2")+COUNTIF(D6:AH6,"x/2")/2 -> 7 | AJ6: =0 -> 0 | AK6: =AI6+AJ6 -> 7
C7: C3 | J7: x | K7: x | L7: x | M7: x | N7: x | O7: x | P7: x/2 | AF7: x | AG7: x | AI7: =COUNTIF(D7:AH7,"x")+COUNTIF(D7:AH7,"x-0,25")+COUNTIF(D7:AH7,"x-0,50")+COUNTIF(D7:AH7,"x-0.75")+COUNTIF(D7:AH7,"x-1")+COUNTIF(D7:AH7,"x-1,25")+COUNTIF(D7:AH7,"x-1,5")+COUNTIF(D7:AH7,"x-1,55")+COUNTIF(D7:AH7,"x-2")+COUNTIF(D7:AH7,"x/2")/2 -> 8.5 | AJ7: =0 -> 0 | AK7: =AI7+AJ7 -> 8.5
AI8: ="" | AJ8: ="" | AK8: =""
A9: 2 | B9: Trần Văn Dũng | C9: TC | T9: 4 | U9: 4 | Y9: 4 | Z9: 4 | AA9: 3 | AB9: 4 | AC9: 4 | AD9: 4 | AF9: 2 | AG9: 2 | AI9: =0 -> 0 | AJ9: =SUM(D9:AH9)/8 -> 4.375 | AK9: =AI9+AJ9 -> 4.375
C10: C1 | J10: x | K10: x | L10: x | M10: x | N10: x | O10: x | P10: x | Y10: x | Z10: x | AA10: x | AB10: x | AC10: x | AD10: x | AE10: x | AF10: x | AG10: x | AI10: =COUNTIF(D10:AH10,"x")+COUNTIF(D10:AH10,"x-0,25")+COUNTIF(D10:AH10,"x-0,50")+COUNTIF(D10:AH10,"x-0.75")+COUNTIF(D10:AH10,"x-1")+COUNTIF(D10:AH10,"x-1,25")+COUNTIF(D10:AH10,"x-1,5")+COUNTIF(D10:AH10,"x-1,55")+COUNTIF(D10:AH10,"x-2")+COUNTIF(D10:AH10,"x/2")/2 -> 16 | AJ10: =0 -> 0 | AK10: =AI10+AJ10 -> 16
C11: C2 | D11: x | E11: x | F11: x | G11: x | H11: x | I11: x | AI11: =COUNTIF(D11:AH11,"x")+COUNTIF(D11:AH11,"x-0,25")+COUNTIF(D11:AH11,"x-0,50")+COUNTIF(D11:AH11,"x-0.75")+COUNTIF(D11:AH11,"x-1")+COUNTIF(D11:AH11,"x-1,25")+COUNTIF(D11:AH11,"x-1,5")+COUNTIF(D11:AH11,"x-1,55")+COUNTIF(D11:AH11,"x-2")+COUNTIF(D11:AH11,"x/2")/2 -> 6 | AJ11: =0 -> 0 | AK11: =AI11+AJ11 -> 6
C12: C3 | S12: x | T12: x | U12: x | V12: x | W12: x | AI12: =COUNTIF(D12:AH12,"x")+COUNTIF(D12:AH12,"x-0,25")+COUNTIF(D12:AH12,"x-0,50")+COUNTIF(D12:AH12,"x-0.75")+COUNTIF(D12:AH12,"x-1")+COUNTIF(D12:AH12,"x-1,25")+COUNTIF(D12:AH12,"x-1,5")+COUNTIF(D12:AH12,"x-1,55")+COUNTIF(D12:AH12,"x-2")+COUNTIF(D12:AH12,"x/2")/2 -> 5 | AJ12: =0 -> 0 | AK12: =AI12+AJ12 -> 5
AI13: ="" | AJ13: ="" | AK13: =""
A14: 3 | B14: Hoàng Ngọc Hà | C14: TC | U14: 2 | AB14: 0.75 | AC14: 1 | AI14: =0 -> 0 | AJ14: =SUM(D14:AH14)/8 -> 0.46875 | AK14: =AI14+AJ14 -> 0.46875
C15: C1 | D15: x | E15: x | F15: x | G15: x | H15: x | I15: x | K15: x | L15: x | M15: x | N15: x | O15: x | P15: x | S15: x | T15: x-2 | U15: x-1,55 | V15: x | W15: x | X15: x/2 | Y15: x-0,50 | Z15: x | AA15: x | AB15: x | AC15: x | AD15: x | AF15: x | AG15: x | AI15: =COUNTIF(D15:AH15,"x")+COUNTIF(D15:AH15,"x-0,25")+COUNTIF(D15:AH15,"x-0,50")+COUNTIF(D15:AH15,"x-0.75")+COUNTIF(D15:AH15,"x-1")+COUNTIF(D15:AH15,"x-1,25")+COUNTIF(D15:AH15,"x-1,5")+COUNTIF(D15:AH15,"x-1,55")+COUNTIF(D15:AH15,"x-2")+COUNTIF(D15:AH15,"x/2")/2 -> 25.5 | AJ15: =0 -> 0 | AK15: =AI15+AJ15 -> 25.5
C16: C2 | AI16: =COUNTIF(D16:AH16,"x")+COUNTIF(D16:AH16,"x-0,25")+COUNTIF(D16:AH16,"x-0,50")+COUNTIF(D16:AH16,"x-0.75")+COUNTIF(D16:AH16,"x-1")+COUNTIF(D16:AH16,"x-1,25")+COUNTIF(D16:AH16,"x-1,5")+COUNTIF(D16:AH16,"x-1,55")+COUNTIF(D16:AH16,"x-2")+COUNTIF(D16:AH16,"x/2")/2 -> 0 | AJ16: =0 -> 0 | AK16: =AI16+AJ16 -> 0
C17: C3 | AI17: =COUNTIF(D17:AH17,"x")+COUNTIF(D17:AH17,"x-0,25")+COUNTIF(D17:AH17,"x-0,50")+COUNTIF(D17:AH17,"x-0.75")+COUNTIF(D17:AH17,"x-1")+COUNTIF(D17:AH17,"x-1,25")+COUNTIF(D17:AH17,"x-1,5")+COUNTIF(D17:AH17,"x-1,55")+COUNTIF(D17:AH17,"x-2")+COUNTIF(D17:AH17,"x/2")/2 -> 0 | AJ17: =0 -> 0 | AK17: =AI17+AJ17 -> 0
AI18: ="" | AJ18: ="" | AK18: =""
A19: 4 | B19: Phùng Đình Hùng | C19: TC | Y19: 4 | Z19: 4 | AA19: 0 | AB19: 3 | AC19: 4 | AG19: 2 | AI19: =0 -> 0 | AJ19: =SUM(D19:AH19)/8 -> 2.125 | AK19: =AI19+AJ19 -> 2.125
C20: C1 | D20: x | E20: x | F20: x | G20: x | H20: x | I20: x | J20: x | K20: x | L20: x | M20: x | N20: x | O20: x | P20: x | X20: x | Y20: x | Z20: x | AA20: x | AB20: x | AC20: x | AD20: 0 | AE20: x | AF20: x | AG20: x | AI20: =COUNTIF(D20:AH20,"x")+COUNTIF(D20:AH20,"x-0,25")+COUNTIF(D20:AH20,"x-0,50")+COUNTIF(D20:AH20,"x-0.75")+COUNTIF(D20:AH20,"x-1")+COUNTIF(D20:AH20,"x-1,25")+COUNTIF(D20:AH20,"x-1,5")+COUNTIF(D20:AH20,"x-1,55")+COUNTIF(D20:AH20,"x-2")+COUNTIF(D20:AH20,"x/2")/2 -> 22 | AJ20: =0 -> 0 | AK20: =AI20+AJ20 -> 22
C21: C2 | S21: x | T21: x | U21: x | V21: x | W21: x | AI21: =COUNTIF(D21:AH21,"x")+COUNTIF(D21:AH21,"x-0,25")+COUNTIF(D21:AH21,"x-0,50")+COUNTIF(D21:AH21,"x-0.75")+COUNTIF(D21:AH21,"x-1")+COUNTIF(D21:AH21,"x-1,25")+COUNTIF(D21:AH21,"x-1,5")+COUNTIF(D21:AH21,"x-1,55")+COUNTIF(D21:AH21,"x-2")+COUNTIF(D21:AH21,"x/2")/2 -> 5 | AJ21: =0 -> 0 | AK21: =AI21+AJ21 -> 5
C22: C3 | AI22: =COUNTIF(D22:AH22,"x")+COUNTIF(D22:AH22,"x-0,25")+COUNTIF(D22:AH22,"x-0,50")+COUNTIF(D22:AH22,"x-0.75")+COUNTIF(D22:AH22,"x-1")+COUNTIF(D22:AH22,"x-1,25")+COUNTIF(D22:AH22,"x-1,5")+COUNTIF(D22:AH22,"x-1,55")+COUNTIF(D22:AH22,"x-2")+COUNTIF(D22:AH22,"x/2")/2 -> 0 | AJ22: =0 -> 0 | AK22: =AI22+AJ22 -> 0
AI23: ="" | AJ23: ="" | AK23: =""
A24: 5 | B24: Đặng Ngọc Long | C24: TC | Y24: 4 | Z24: 4 | AA24: 3 | AC24: 4 | AD24: 4 | AF24: 2 | AG24: 2 | AI24: =0 -> 0 | AJ24: =SUM(D24:AH24)/8 -> 2.875 | AK24: =AI24+AJ24 -> 2.875
C25: C1 | Y25: x | Z25: x | AA25: x | AB25: x | AC25: x | AD25: x | AE25: x | AI25: =COUNTIF(D25:AH25,"x")+COUNTIF(D25:AH25,"x-0,25")+COUNTIF(D25:AH25,"x-0,50")+COUNTIF(D25:AH25,"x-0.75")+COUNTIF(D25:AH25,"x-1")+COUNTIF(D25:AH25,"x-1,25")+COUNTIF(D25:AH25,"x-1,5")+COUNTIF(D25:AH25,"x-1,55")+COUNTIF(D25:AH25,"x-2")+COUNTIF(D25:AH25,"x/2")/2 -> 7 | AJ25: =0 -> 0 | AK25: =AI25+AJ25 -> 7
C26: C2 | D26: x | E26: x | F26: x | G26: x | H26: x | I26: 0 | K26: x | L26: x | M26: x | N26: x | O26: x | P26: x | S26: 0 | T26: 0 | U26: 0 | V26: 0 | W26: 0 | AF26: x | AG26: x | AI26: =COUNTIF(D26:AH26,"x")+COUNTIF(D26:AH26,"x-0,25")+COUNTIF(D26:AH26,"x-0,50")+COUNTIF(D26:AH26,"x-0.75")+COUNTIF(D26:AH26,"x-1")+COUNTIF(D26:AH26,"x-1,25")+COUNTIF(D26:AH26,"x-1,5")+COUNTIF(D26:AH26,"x-1,55")+COUNTIF(D26:AH26,"x-2")+COUNTIF(D26:AH26,"x/2")/2 -> 13 | AJ26: =0 -> 0 | AK26: =AI26+AJ26 -> 13
C27: C3 | AI27: =COUNTIF(D27:AH27,"x")+COUNTIF(D27:AH27,"x-0,25")+COUNTIF(D27:AH27,"x-0,50")+COUNTIF(D27:AH27,"x-0.75")+COUNTIF(D27:AH27,"x-1")+COUNTIF(D27:AH27,"x-1,25")+COUNTIF(D27:AH27,"x-1,5")+COUNTIF(D27:AH27,"x-1,55")+COUNTIF(D27:AH27,"x-2")+COUNTIF(D27:AH27,"x/2")/2 -> 0 | AJ27: =0 -> 0 | AK27: =AI27+AJ27 -> 0
