Workbook

Sheet 01_Tong_Quan_Dashboard
A1: BẢNG ĐIỀU HÀNH TỔNG THỂ & CHỈ SỐ HOẠT ĐỘNG TOÀN DIỆN (EXECUTIVE DASHBOARD)
A2: Nhà máy Đúc Thép Hợp Kim & Cơ Khí Chính Xác | Giám sát trực quan: Tiến độ PO, Cân bằng tải máy, Điểm nghẽn, Chất lượng & Chi phí
B4: TỔNG LỆNH SX (PO) | D4: BTP TỒN CHỜ BÀN GIAO (WIP THEO PO) | F4: TỔNG SẢN LƯỢNG ĐANG GIA CÔNG TẠI CÁC NGUYÊN CÔNG | H4: TỔNG BTP HOÀN THÀNH TẠI XƯỞNG | J4: TỔNG SẢN PHẨM ĐÃ BÀN GIAO | L4: TỶ LỆ PHẾ PHẨM TOÀN XƯỞNG
B5: =D18 | D5: =H18 | F5: =I18 | H5: =F18 | J5: =G18 | L5: =IF(SUM('07_Quet_Ma_Nhat_Ky_Ca'!M:M)>0, SUM('07_Quet_Ma_Nhat_Ky_Ca'!N:N)/(SUM('07_Quet_Ma_Nhat_Ky_Ca'!M:M)+SUM('07_Quet_Ma_Nhat_Ky_Ca'!N:N)), 0.012)
A7: 1. TỔNG HỢP TIẾN ĐỘ & BÀN GIAO THEO ĐỐI TÁC KHÁCH HÀNG
A8: STT | B8: Khách Hàng | C8: Mặt Hàng Chủ Lực | D8: Số Lượng PO | E8: Tổng SL Đặt | F8: Xong Tại Xưởng | G8: Đã Bàn Giao | H8: Tồn Chờ Bàn Giao | I8: Còn Nợ PO | J8: Tiến Độ Bàn Giao (%) | K8: Trạng Thái Điều Hành | L8: Bộ Phận Tiếp Nhận Tiếp Theo
A9: 1 | B9: Thyssen | C9: Sealing strip, below / above (Thép hợp kim chịu mòn) | D9: 13 | E9: 161 | F9: 28.25 | G9: 0 | H9: 28.25 | I9: 161 | J9: 0 | K9: =IF(E9=0, "Chưa có đơn hàng", IF(G9>E9, "⚠️ BÀN GIAO VƯỢT KH", IF(G9>=E9, "Đã bàn giao đủ 100%", IF(F9>=E9, "Xong xưởng - Chờ chuyển", IF(F9>0, "Đang gia công trên máy", "Chờ nhận phôi đúc"))))) | L9: Bộ phận Hoàn thiện (Tẩy bavia/Đóng kiện)
A10: 2 | B10: Win-Win | C10: Cánh xoắn đùn ISHIZUE (355Dw900, 318Dw800, 216Dw650...) | D10: =IFERROR(COUNTIF('06_Ke_Hoach_Tien_Do_PO'!$C$4:$C$64, "*" & B10 & "*"), 0) | E10: =IFERROR(SUMIFS('06_Ke_Hoach_Tien_Do_PO'!$E$4:$E$64, '06_Ke_Hoach_Tien_Do_PO'!$C$4:$C$64, "*" & B10 & "*"), 0) | F10: =IFERROR(SUMIFS('06_Ke_Hoach_Tien_Do_PO'!$F$4:$F$64, '06_Ke_Hoach_Tien_Do_PO'!$C$4:$C$64, "*" & B10 & "*"), 0) | G10: =IFERROR(SUMIFS('06_Ke_Hoach_Tien_Do_PO'!$G$4:$G$64, '06_Ke_Hoach_Tien_Do_PO'!$C$4:$C$64, "*" & B10 & "*"), 0) | H10: =MAX(0, F10-G10) | I10: =MAX(0, E10-G10) | J10: =IF(E10>0, G10/E10, 0) | K10: =IF(E10=0, "Chưa có đơn hàng", IF(G10>E10, "⚠️ BÀN GIAO VƯỢT KH", IF(G10>=E10, "Đã bàn giao đủ 100%", IF(F10>=E10, "Xong xưởng - Chờ chuyển", IF(F10>0, "Đang gia công trên máy", "Chờ nhận phôi đúc"))))) | L10: Bộ phận Hoàn thiện (Lắp cụm trục)
A11: 3 | B11: Vico- QLTB | C11: Mẫu thử cơ tính CR, Mẫu kéo nén ASTM | D11: =IFERROR(COUNTIF('06_Ke_Hoach_Tien_Do_PO'!$C$4:$C$64, "*" & B11 & "*"), 0) | E11: =IFERROR(SUMIFS('06_Ke_Hoach_Tien_Do_PO'!$E$4:$E$64, '06_Ke_Hoach_Tien_Do_PO'!$C$4:$C$64, "*" & B11 & "*"), 0) | F11: =IFERROR(SUMIFS('06_Ke_Hoach_Tien_Do_PO'!$F$4:$F$64, '06_Ke_Hoach_Tien_Do_PO'!$C$4:$C$64, "*" & B11 & "*"), 0) | G11: =IFERROR(SUMIFS('06_Ke_Hoach_Tien_Do_PO'!$G$4:$G$64, '06_Ke_Hoach_Tien_Do_PO'!$C$4:$C$64, "*" & B11 & "*"), 0) | H11: =MAX(0, F11-G11) | I11: =MAX(0, E11-G11) | J11: =IF(E11>0, G11/E11, 0) | K11: =IF(E11=0, "Chưa có đơn hàng", IF(G11>E11, "⚠️ BÀN GIAO VƯỢT KH", IF(G11>=E11, "Đã bàn giao đủ 100%", IF(F11>=E11, "Xong xưởng - Chờ chuyển", IF(F11>0, "Đang gia công trên máy", "Chờ nhận phôi đúc"))))) | L11: Phòng KCS / Thử nghiệm ASTM
A12: 4 | B12: Luợng- KS Tường Long | C12: Ốp dao nhào trên (Bộ bên trái / bên phải) | D12: =IFERROR(COUNTIF('06_Ke_Hoach_Tien_Do_PO'!$C$4:$C$64, "*" & B12 & "*"), 0) | E12: =IFERROR(SUMIFS('06_Ke_Hoach_Tien_Do_PO'!$E$4:$E$64, '06_Ke_Hoach_Tien_Do_PO'!$C$4:$C$64, "*" & B12 & "*"), 0) | F12: =IFERROR(SUMIFS('06_Ke_Hoach_Tien_Do_PO'!$F$4:$F$64, '06_Ke_Hoach_Tien_Do_PO'!$C$4:$C$64, "*" & B12 & "*"), 0) | G12: =IFERROR(SUMIFS('06_Ke_Hoach_Tien_Do_PO'!$G$4:$G$64, '06_Ke_Hoach_Tien_Do_PO'!$C$4:$C$64, "*" & B12 & "*"), 0) | H12: =MAX(0, F12-G12) | I12: =MAX(0, E12-G12) | J12: =IF(E12>0, G12/E12, 0) | K12: =IF(E12=0, "Chưa có đơn hàng", IF(G12>E12, "⚠️ BÀN GIAO VƯỢT KH", IF(G12>=E12, "Đã bàn giao đủ 100%", IF(F12>=E12, "Xong xưởng - Chờ chuyển", IF(F12>0, "Đang gia công trên máy", "Chờ nhận phôi đúc"))))) | L12: Bộ phận Hoàn thiện
A13: 5 | B13: Molycop | C13: Bi đúc hợp kim cắt dây & mài từ | D13: =IFERROR(COUNTIF('06_Ke_Hoach_Tien_Do_PO'!$C$4:$C$64, "*" & B13 & "*"), 0) | E13: =IFERROR(SUMIFS('06_Ke_Hoach_Tien_Do_PO'!$E$4:$E$64, '06_Ke_Hoach_Tien_Do_PO'!$C$4:$C$64, "*" & B13 & "*"), 0) | F13: =IFERROR(SUMIFS('06_Ke_Hoach_Tien_Do_PO'!$F$4:$F$64, '06_Ke_Hoach_Tien_Do_PO'!$C$4:$C$64, "*" & B13 & "*"), 0) | G13: =IFERROR(SUMIFS('06_Ke_Hoach_Tien_Do_PO'!$G$4:$G$64, '06_Ke_Hoach_Tien_Do_PO'!$C$4:$C$64, "*" & B13 & "*"), 0) | H13: =MAX(0, F13-G13) | I13: =MAX(0, E13-G13) | J13: =IF(E13>0, G13/E13, 0) | K13: =IF(E13=0, "Chưa có đơn hàng", IF(G13>E13, "⚠️ BÀN GIAO VƯỢT KH", IF(G13>=E13, "Đã bàn giao đủ 100%", IF(F13>=E13, "Xong xưởng - Chờ chuyển", IF(F13>0, "Đang gia công trên máy", "Chờ nhận phôi đúc"))))) | L13: PX Nhiệt luyện / Phòng KCS
A14: 6 | B14: Hà Song Hải - XM Hạ Long | C14: Thanh đập đá vôi (2240x510x145 - Thép Mn13) | D14: =IFERROR(COUNTIF('06_Ke_Hoach_Tien_Do_PO'!$C$4:$C$64, "*" & B14 & "*"), 0) | E14: =IFERROR(SUMIFS('06_Ke_Hoach_Tien_Do_PO'!$E$4:$E$64, '06_Ke_Hoach_Tien_Do_PO'!$C$4:$C$64, "*" & B14 & "*"), 0) | F14: =IFERROR(SUMIFS('06_Ke_Hoach_Tien_Do_PO'!$F$4:$F$64, '06_Ke_Hoach_Tien_Do_PO'!$C$4:$C$64, "*" & B14 & "*"), 0) | G14: =IFERROR(SUMIFS('06_Ke_Hoach_Tien_Do_PO'!$G$4:$G$64, '06_Ke_Hoach_Tien_Do_PO'!$C$4:$C$64, "*" & B14 & "*"), 0) | H14: =MAX(0, F14-G14) | I14: =MAX(0, E14-G14) | J14: =IF(E14>0, G14/E14, 0) | K14: =IF(E14=0, "Chưa có đơn hàng", IF(G14>E14, "⚠️ BÀN GIAO VƯỢT KH", IF(G14>=E14, "Đã bàn giao đủ 100%", IF(F14>=E14, "Xong xưởng - Chờ chuyển", IF(F14>0, "Đang gia công trên máy", "Chờ nhận phôi đúc"))))) | L14: PX Nhiệt luyện (Tôi cao tần)
A15: 7 | B15: Hải- Vinh Quảng Ninh | C15: Bộ rulo máy nghiền: Thân rô to (φ820x890), Bích rulo | D15: =IFERROR(COUNTIF('06_Ke_Hoach_Tien_Do_PO'!$C$4:$C$64, "*" & B15 & "*"), 0) | E15: =IFERROR(SUMIFS('06_Ke_Hoach_Tien_Do_PO'!$E$4:$E$64, '06_Ke_Hoach_Tien_Do_PO'!$C$4:$C$64, "*" & B15 & "*"), 0) | F15: =IFERROR(SUMIFS('06_Ke_Hoach_Tien_Do_PO'!$F$4:$F$64, '06_Ke_Hoach_Tien_Do_PO'!$C$4:$C$64, "*" & B15 & "*"), 0) | G15: =IFERROR(SUMIFS('06_Ke_Hoach_Tien_Do_PO'!$G$4:$G$64, '06_Ke_Hoach_Tien_Do_PO'!$C$4:$C$64, "*" & B15 & "*"), 0) | H15: =MAX(0, F15-G15) | I15: =MAX(0, E15-G15) | J15: =IF(E15>0, G15/E15, 0) | K15: =IF(E15=0, "Chưa có đơn hàng", IF(G15>E15, "⚠️ BÀN GIAO VƯỢT KH", IF(G15>=E15, "Đã bàn giao đủ 100%", IF(F15>=E15, "Xong xưởng - Chờ chuyển", IF(F15>0, "Đang gia công trên máy", "Chờ nhận phôi đúc"))))) | L15: Tổ Lắp Ráp & Hoàn Thiện
A16: 8 | B16: TFG | C16: Nut cover F3P00064, Chi tiết bản vẽ 2CG00820 | D16: =IFERROR(COUNTIF('06_Ke_Hoach_Tien_Do_PO'!$C$4:$C$64, "*" & B16 & "*"), 0) | E16: =IFERROR(SUMIFS('06_Ke_Hoach_Tien_Do_PO'!$E$4:$E$64, '06_Ke_Hoach_Tien_Do_PO'!$C$4:$C$64, "*" & B16 & "*"), 0) | F16: =IFERROR(SUMIFS('06_Ke_Hoach_Tien_Do_PO'!$F$4:$F$64, '06_Ke_Hoach_Tien_Do_PO'!$C$4:$C$64, "*" & B16 & "*"), 0) | G16: =IFERROR(SUMIFS('06_Ke_Hoach_Tien_Do_PO'!$G$4:$G$64, '06_Ke_Hoach_Tien_Do_PO'!$C$4:$C$64, "*" & B16 & "*"), 0) | H16: =MAX(0, F16-G16) | I16: =MAX(0, E16-G16) | J16: =IF(E16>0, G16/E16, 0) | K16: =IF(E16=0, "Chưa có đơn hàng", IF(G16>E16, "⚠️ BÀN GIAO VƯỢT KH", IF(G16>=E16, "Đã bàn giao đủ 100%", IF(F16>=E16, "Xong xưởng - Chờ chuyển", IF(F16>0, "Đang gia công trên máy", "Chờ nhận phôi đúc"))))) | L16: Bộ phận Hoàn thiện
A17: 9 | B17: UCC | C17: Khuôn gá xích POWER, Bạc lót 4-210658-2 | D17: =IFERROR(COUNTIF('06_Ke_Hoach_Tien_Do_PO'!$C$4:$C$64, "*" & B17 & "*"), 0) | E17: =IFERROR(SUMIFS('06_Ke_Hoach_Tien_Do_PO'!$E$4:$E$64, '06_Ke_Hoach_Tien_Do_PO'!$C$4:$C$64, "*" & B17 & "*"), 0) | F17: =IFERROR(SUMIFS('06_Ke_Hoach_Tien_Do_PO'!$F$4:$F$64, '06_Ke_Hoach_Tien_Do_PO'!$C$4:$C$64, "*" & B17 & "*"), 0) | G17: =IFERROR(SUMIFS('06_Ke_Hoach_Tien_Do_PO'!$G$4:$G$64, '06_Ke_Hoach_Tien_Do_PO'!$C$4:$C$64, "*" & B17 & "*"), 0) | H17: =MAX(0, F17-G17) | I17: =MAX(0, E17-G17) | J17: =IF(E17>0, G17/E17, 0) | K17: =IF(E17=0, "Chưa có đơn hàng", IF(G17>E17, "⚠️ BÀN GIAO VƯỢT KH", IF(G17>=E17, "Đã bàn giao đủ 100%", IF(F17>=E17, "Xong xưởng - Chờ chuyển", IF(F17>0, "Đang gia công trên máy", "Chờ nhận phôi đúc"))))) | L17: PX Nhiệt luyện (Tôi chân không)
A18: TỔNG CỘNG TOÀN NHÀ MÁY | D18: 61 | E18: 2124 | F18: 44.75 | G18: 918 | H18: 29.5 | I18: 1406 | J18: 0.43220339 | K18: ĐIỀU ĐỘ BÌNH THƯỜNG | L18: -
A19: ĐỐI SOÁT | B19: KIỂM TRA CHÊNH LỆCH DASHBOARD - BẢNG PO: | D19: ✅ ĐỐI SOÁT HOÀN HẢO: TỔNG DASHBOARD KHỚP 100% VỚI BẢNG PO (CHÊNH LỆCH = 0)

Sheet 02_Canh_Bao_Qua_Tai_SubCon
A1: HỆ THỐNG CẢNH BÁO ĐƠN HÀNG QUÁ TẢI & ĐỀ XUẤT ĐIỀU CHUYỂN GIA CÔNG NGOÀI (SUB-CON)
A2: Phân xưởng Cơ khí | Tự động đối soát Tổng giờ công nghệ yêu cầu vs Năng lực máy thực tế -> Cảnh báo Trễ hạn -> Đề xuất chuyển gia công ngoài an toàn
A4: STT | B4: Mã PO / LSX | C4: Khách Hàng | D4: Tên Chi Tiết / Quy Cách | E4: SL Cần Làm | F4: Máy Nghẽn Phụ Trách | G4: Tổng Giờ Cần Chạy (h) | H4: Số Ngày Còn Lại (Deadline) | I4: Khả Năng Xưởng Tự Làm (Chi tiết) | J4: SL ĐỀ XUẤT CHUYỂN NGOÀI | K4: Trần Giá Thuê Ngoài / CT (VNĐ) | L4: LỆNH ĐIỀU HÀNH SẢN XUẤT | M4: Đơn Vị Vệ Tinh Đề Xuất | N4: Phương Án Kiểm Soát Rủi Ro
A5: 1 | B5: PO-5999 | C5: Win-Win | D5: Cánh xoắn vít đùn ISHIZUE 355Dw900 | E5: 50 | F5: Máy tiện FUJI | G5: 150 | H5: 5 | I5: 20 | J5: =MAX(0, E5-I5) | K5: 420000 | L5: =IF(J5>0, "ĐỀ XUẤT GIA CÔNG NGOÀI", IF(G5>H5*12, "TĂNG CA NỘI BỘ GẤP", "CHẠY NỘI BỘ AN TOÀN")) | M5: Xưởng cơ khí Hoàng Mai | N5: Chuyển NC1 gọt thô ra ngoài, giữ NC3 tiện tinh tại xưởng
A6: 2 | B6: PO-3733 | C6: Win-Win | D6: Cánh xoắn vít đùn ISHIZUE 318Dw800 | E6: 60 | F6: Máy tiện FUJI | G6: 150 | H6: 4 | I6: 15 | J6: =MAX(0, E6-I6) | K6: 320000 | L6: =IF(J6>0, "ĐỀ XUẤT GIA CÔNG NGOÀI", IF(G6>H6*12, "TĂNG CA NỘI BỘ GẤP", "CHẠY NỘI BỘ AN TOÀN")) | M6: Công ty Cơ khí Tân Phát | N6: Cung cấp phôi và đồ gá chuẩn, KCS nghiệm thu tại xưởng vệ tinh
A7: 3 | B7: PO-7365 | C7: Hà Song Hải - XM Hạ Long | D7: Thanh đập đá vôi (2240x510x145) | E7: 8 | F7: Máy Phay OIGO | G7: 80 | H7: 3 | I7: 3 | J7: =MAX(0, E7-I7) | K7: 1400000 | L7: =IF(J7>0, "ĐỀ XUẤT GIA CÔNG NGOÀI", IF(G7>H7*12, "TĂNG CA NỘI BỘ GẤP", "CHẠY NỘI BỘ AN TOÀN")) | M7: Xưởng Phay Giường Đức Long | N7: Gia công ngoài NC1 phay mặt, xưởng giữ lại phay rãnh & tôi cao tần
A8: 4 | B8: PO-5313 | C8: Thyssen | D8: Sealing trip, below | E8: 120 | F8: Máy Phay OKK1 | G8: 100 | H8: 10 | I8: 120 | J8: =MAX(0, E8-I8) | K8: 85000 | L8: =IF(J8>0, "ĐỀ XUẤT GIA CÔNG NGOÀI", IF(G8>H8*12, "TĂNG CA NỘI BỘ GẤP", "CHẠY NỘI BỘ AN TOÀN")) | M8: - | N8: Xưởng đủ năng lực hoàn thành đúng hạn (Nội bộ)
A9: 5 | B9: PO-7107 | C9: Thyssen | D9: Sealing strip, above | E9: 100 | F9: Máy Phay OKK3 | G9: 75 | H9: 8 | I9: 100 | J9: =MAX(0, E9-I9) | K9: 95000 | L9: =IF(J9>0, "ĐỀ XUẤT GIA CÔNG NGOÀI", IF(G9>H9*12, "TĂNG CA NỘI BỘ GẤP", "CHẠY NỘI BỘ AN TOÀN")) | M9: - | N9: Chạy nội bộ 2 ca đảm bảo tiến độ
A10: 6 | B10: PO-4545 | C10: Luợng- KS Tường Long | D10: Ốp dao nhào trên (Bộ bên trái) | E10: 40 | F10: Máy Cắt Dây DK7745 | G10: 100 | H10: 4 | I10: 16 | J10: =MAX(0, E10-I10) | K10: 140000 | L10: =IF(J10>0, "ĐỀ XUẤT GIA CÔNG NGOÀI", IF(G10>H10*12, "TĂNG CA NỘI BỘ GẤP", "CHẠY NỘI BỘ AN TOÀN")) | M10: Cắt dây CNC Nam Định | N10: Gửi file CAD/CAM cắt dây theo dưỡng kiểm
A11: 7 | B11: PO-8205 | C11: Molycop | D11: Bi 40 | E11: 80 | F11: Máy Cắt Dây DK7745 | G11: 40 | H11: 7 | I11: 80 | J11: =MAX(0, E11-I11) | K11: 65000 | L11: =IF(J11>0, "ĐỀ XUẤT GIA CÔNG NGOÀI", IF(G11>H11*12, "TĂNG CA NỘI BỘ GẤP", "CHẠY NỘI BỘ AN TOÀN")) | M11: - | N11: Xưởng chạy đêm bù tải, không cần thuê ngoài
A12: 8 | B12: PO-1456 | C12: UCC | D12: Khuôn gá xích POWER | E12: 30 | F12: Máy Phay CNC1 | G12: 60 | H12: 3 | I12: 10 | J12: =MAX(0, E12-I12) | K12: 350000 | L12: =IF(J12>0, "ĐỀ XUẤT GIA CÔNG NGOÀI", IF(G12>H12*12, "TĂNG CA NỘI BỘ GẤP", "CHẠY NỘI BỘ AN TOÀN")) | M12: Cơ khí Chính xác An Phát | N12: Thuê ngoài phay thô, đưa về nhiệt luyện và mài tinh tại xưởng

Sheet 03_Can_Bang_Tai_17_May
A1: BẢNG PHÂN TÍCH CÂN BẰNG TẢI THIẾT BỊ & NĂNG LỰC SẢN XUẤT XƯỞNG
A2: Nhà máy Cơ khí | Theo dõi Năng lực khả dụng (h/tuần) vs Nhu cầu giờ công nghệ (h/tuần) -> Phát hiện điểm nghẽn (Bottleneck)
A3: STT | B3: Tên Thiết Bị / Máy Gia Công | C3: Nhóm Công Nghệ | D3: Số Ca Làm Việc / Ngày | E3: Năng Lực Khả Dụng (Giờ/Tuần) | F3: Nhu Cầu Giờ Cần Chạy (Giờ) | G3: Hệ Số Tải Máy (%) | H3: Đánh Giá Trạng Thái Tải | I3: Số Giờ Bị Thiếu Hụt (h) | J3: Máy Thay Thế Dự Phòng (San Tải) | K3: Khả Năng Chuyển Máy Nội Bộ (%) | L3: Đề Xuất Hành Động Quản Đốc | M3: Ghi Chú Kỹ Thuật
A4: 1 | B4: Máy tiện FUJI | C4: Tiện CNC hạng vừa | D4: 2 | E4: 96 | F4: 158 | G4: =F4/E4 | H4: =IF(G4>1.2, "NGHẼN NẶNG", IF(G4>=1, "CẢNH BÁO QUÁ TẢI", IF(G4>=0.75, "TẢI TỐI ƯU", "DƯ NĂNG LỰC"))) | I4: =MAX(0, F4-E4) | J4: Máy tiện OKUMA / CNC1 | K4: 0.4 | L4: San bớt 40% sang OKUMA, còn lại 60h chuyển thuê ngoài
A5: 2 | B5: Máy Phay OKK3 | C5: Phay CNC 3 trục | D5: 2 | E5: 96 | F5: 122 | G5: =F5/E5 | H5: =IF(G5>1.2, "NGHẼN NẶNG", IF(G5>=1, "CẢNH BÁO QUÁ TẢI", IF(G5>=0.75, "TẢI TỐI ƯU", "DƯ NĂNG LỰC"))) | I5: =MAX(0, F5-E5) | J5: Máy Phay OKK1 / OKK2 | K5: 0.5 | L5: San bớt chi tiết phay mặt sang OKK1, OKK2
A6: 3 | B6: Máy Phay OIGO | C6: Phay giường hạng nặng | D6: 2 | E6: 96 | F6: 145 | G6: =F6/E6 | H6: =IF(G6>1.2, "NGHẼN NẶNG", IF(G6>=1, "CẢNH BÁO QUÁ TẢI", IF(G6>=0.75, "TẢI TỐI ƯU", "DƯ NĂNG LỰC"))) | I6: =MAX(0, F6-E6) | J6: Không có máy nội bộ tương đương | K6: 0 | L6: BẮT BUỘC thuê ngoài NC1 phay thô hoặc chạy ca 3
A7: 4 | B7: Máy Cắt Dây DK7745 | C7: Cắt dây CNC | D7: 2.5 | E7: 120 | F7: 140 | G7: =F7/E7 | H7: =IF(G7>1.2, "NGHẼN NẶNG", IF(G7>=1, "CẢNH BÁO QUÁ TẢI", IF(G7>=0.75, "TẢI TỐI ƯU", "DƯ NĂNG LỰC"))) | I7: =MAX(0, F7-E7) | J7: Máy Cắt Dây DK7780 / Podatech | K7: 0.5 | L7: Chuyển việc sang DK7780 và vệ tinh cắt dây Nam Định
A8: 5 | B8: Máy tiện OKUMA | C8: Tiện CNC chính xác | D8: 2 | E8: 96 | F8: 82 | G8: =F8/E8 | H8: =IF(G8>1.2, "NGHẼN NẶNG", IF(G8>=1, "CẢNH BÁO QUÁ TẢI", IF(G8>=0.75, "TẢI TỐI ƯU", "DƯ NĂNG LỰC"))) | I8: =MAX(0, F8-E8) | J8: Sẵn sàng nhận tải bù từ FUJI | K8: 1 | L8: Đang tải tối ưu (85%), sẵn sàng nhận bù việc
A9: 6 | B9: Máy Phay OKK1 | C9: Phay CNC | D9: 2 | E9: 96 | F9: 88 | G9: =F9/E9 | H9: =IF(G9>1.2, "NGHẼN NẶNG", IF(G9>=1, "CẢNH BÁO QUÁ TẢI", IF(G9>=0.75, "TẢI TỐI ƯU", "DƯ NĂNG LỰC"))) | I9: =MAX(0, F9-E9) | J9: Sẵn sàng nhận việc từ OKK3 | K9: 1 | L9: Tải tối ưu (92%)
A10: 7 | B10: Máy Phay OKK2 | C10: Phay CNC | D10: 2 | E10: 96 | F10: 75 | G10: =F10/E10 | H10: =IF(G10>1.2, "NGHẼN NẶNG", IF(G10>=1, "CẢNH BÁO QUÁ TẢI", IF(G10>=0.75, "TẢI TỐI ƯU", "DƯ NĂNG LỰC"))) | I10: =MAX(0, F10-E10) | J10: Sẵn sàng nhận việc từ OKK3 | K10: 1 | L10: Tải 78%, còn dư năng lực
A11: 8 | B11: Máy Phay CNC1 | C11: Phay CNC | D11: 2 | E11: 96 | F11: 70 | G11: =F11/E11 | H11: =IF(G11>1.2, "NGHẼN NẶNG", IF(G11>=1, "CẢNH BÁO QUÁ TẢI", IF(G11>=0.75, "TẢI TỐI ƯU", "DƯ NĂNG LỰC"))) | I11: =MAX(0, F11-E11) | J11: Sẵn sàng san tải | K11: 1 | L11: Tải 73%
A12: 9 | B12: Máy Phay CNC2 | C12: Phay CNC | D12: 2 | E12: 96 | F12: 68 | G12: =F12/E12 | H12: =IF(G12>1.2, "NGHẼN NẶNG", IF(G12>=1, "CẢNH BÁO QUÁ TẢI", IF(G12>=0.75, "TẢI TỐI ƯU", "DƯ NĂNG LỰC"))) | I12: =MAX(0, F12-E12) | J12: Sẵn sàng san tải | K12: 1 | L12: Tải 71%
A13: 10 | B13: Máy Cắt Dây DK7780 | C13: Cắt dây CNC khổ lớn | D13: 2 | E13: 96 | F13: 65 | G13: =F13/E13 | H13: =IF(G13>1.2, "NGHẼN NẶNG", IF(G13>=1, "CẢNH BÁO QUÁ TẢI", IF(G13>=0.75, "TẢI TỐI ƯU", "DƯ NĂNG LỰC"))) | I13: =MAX(0, F13-E13) | J13: Nhận việc từ DK7745 | K13: 1 | L13: Tải 68%
A14: 11 | B14: Máy Cắt Dây Podatech | C14: Cắt dây CNC | D14: 2 | E14: 96 | F14: 55 | G14: =F14/E14 | H14: =IF(G14>1.2, "NGHẼN NẶNG", IF(G14>=1, "CẢNH BÁO QUÁ TẢI", IF(G14>=0.75, "TẢI TỐI ƯU", "DƯ NĂNG LỰC"))) | I14: =MAX(0, F14-E14) | J14: Nhận việc từ DK7745 | K14: 1 | L14: Tải 57%
A15: 12 | B15: Máy Khoan cần Yoshida | C15: Khoan / Taro | D15: 2 | E15: 96 | F15: 92 | G15: =F15/E15 | H15: =IF(G15>1.2, "NGHẼN NẶNG", IF(G15>=1, "CẢNH BÁO QUÁ TẢI", IF(G15>=0.75, "TẢI TỐI ƯU", "DƯ NĂNG LỰC"))) | I15: =MAX(0, F15-E15) | J15: Gia công nội bộ ổn định | K15: 1 | L15: Tải 96% - Bình thường
... A20: 17 | B20: Máy tiện T630 | C20: Tiện vạn năng | D20: 1 | E20: 48 | F20: 25 | G20: =F20/E20 | H20: =IF(G20>1.2, "NGHẼN NẶNG", IF(G20>=1, "CẢNH BÁO QUÁ TẢI", IF(G20>=0.75, "TẢI TỐI ƯU", "DƯ NĂNG LỰC"))) | I20: =MAX(0, F20-E20) | J20: Hỗ trợ sửa khuôn/gá | K20: 1 | L20: Tải 52%

Sheet 04_Bao_Gia_Gia_Thanh_SP
A1: BẢNG TÍNH THÀNH PHẨM, TỔNG HỢP GIÁ THÀNH GIA CÔNG & BÁO GIÁ SẢN PHẨM
A2: Nhà máy Đúc Thép Hợp Kim & Cơ Khí Chính Xác | Cơ cấu giá: Phôi đúc + Khoán thợ + Dao cụ tiêu hao + Giờ máy + Chi phí quản lý chung + Lợi nhuận kỳ vọng
A3: STT | B3: Khách Hàng | C3: Tên / Quy Cách Sản Phẩm Đúc | D3: Mác Thép Hợp Kim | E3: Khối Lượng Phôi (kg) | F3: Đơn Giá Thép Đúc (VNĐ/kg) | G3: Tiền Phôi Đúc (VNĐ) | H3: Tổng Tiền Khoán Thợ (VNĐ) | I3: Tổng Chi Phí Dao Cụ (VNĐ) | J3: Tổng Chi Phí Giờ Máy (VNĐ) | K3: GIÁ THÀNH SẢN XUẤT (VNĐ) | L3: Chi Phí QL & Nhiệt Luyện (15%) | M3: GIÁ THÀNH TOÀN BỘ (VNĐ) | N3: Lợi Nhuận Kỳ Vọng (18%) | O3: ĐƠN GIÁ BÁO GIÁ CHÀO KHÁCH (VNĐ) | P3: Ghi Chú Đơn Hàng
A4: 1 | B4: Hà Song Hải - XM Hạ Long | C4: Thanh đập đá vôi (2240x510x145) | D4: Thép Mangan Mn13 | E4: 1250 | F4: 48000 | G4: =E4*F4 | H4: =SUMIF('05_Dinh_Muc_Khoan_Routing'!$C$4:$C$100, C4, '05_Dinh_Muc_Khoan_Routing'!$N$4:$N$100) | I4: =SUMIF('05_Dinh_Muc_Khoan_Routing'!$C$4:$C$100, C4, '05_Dinh_Muc_Khoan_Routing'!$M$4:$M$100) | J4: =SUMIF('05_Dinh_Muc_Khoan_Routing'!$C$4:$C$100, C4, '05_Dinh_Muc_Khoan_Routing'!$P$4:$P$100) | K4: =G4+H4+I4+J4 | L4: =K4*0.15 | M4: =K4+L4 | N4: =M4*0.18 | O4: =M4+N4 | P4: Hàng chịu mài mòn va đập mạnh
A5: 2 | B5: Hải- Vinh Quảng Ninh | C5: Bộ rulo máy nghiền sơ cấp: Thân rô to (φ820x890) | D5: Thép hợp kim 35CrMo | E5: 3600 | F5: 52000 | G5: =E5*F5 | H5: =SUMIF('05_Dinh_Muc_Khoan_Routing'!$C$4:$C$100, C5, '05_Dinh_Muc_Khoan_Routing'!$N$4:$N$100) | I5: =SUMIF('05_Dinh_Muc_Khoan_Routing'!$C$4:$C$100, C5, '05_Dinh_Muc_Khoan_Routing'!$M$4:$M$100) | J5: =SUMIF('05_Dinh_Muc_Khoan_Routing'!$C$4:$C$100, C5, '05_Dinh_Muc_Khoan_Routing'!$P$4:$P$100) | K5: =G5+H5+I5+J5 | L5: =K5*0.15 | M5: =K5+L5 | N5: =M5*0.18 | O5: =M5+N5 | P5: Rô to nghiền sơ cấp nặng
A6: 3 | B6: Hải- Vinh Quảng Ninh | C6: Bộ rulo máy nghiền sơ cấp: Bích rulo (φ500x110) 1T | D6: Thép đúc ZG35 | E6: 180 | F6: 42000 | G6: =E6*F6 | H6: =SUMIF('05_Dinh_Muc_Khoan_Routing'!$C$4:$C$100, C6, '05_Dinh_Muc_Khoan_Routing'!$N$4:$N$100) | I6: =SUMIF('05_Dinh_Muc_Khoan_Routing'!$C$4:$C$100, C6, '05_Dinh_Muc_Khoan_Routing'!$M$4:$M$100) | J6: =SUMIF('05_Dinh_Muc_Khoan_Routing'!$C$4:$C$100, C6, '05_Dinh_Muc_Khoan_Routing'!$P$4:$P$100) | K6: =G6+H6+I6+J6 | L6: =K6*0.15 | M6: =K6+L6 | N6: =M6*0.18 | O6: =M6+N6 | P6: Bích đỡ rulo
A7: 4 | B7: Win-Win | C7: Cánh xoắn vít đùn ISHIZUE 355Dw900 | D7: Thép đúc chịu mòn Cr-Ni | E7: 280 | F7: 55000 | G7: =E7*F7 | H7: =SUMIF('05_Dinh_Muc_Khoan_Routing'!$C$4:$C$100, C7, '05_Dinh_Muc_Khoan_Routing'!$N$4:$N$100) | I7: =SUMIF('05_Dinh_Muc_Khoan_Routing'!$C$4:$C$100, C7, '05_Dinh_Muc_Khoan_Routing'!$M$4:$M$100) | J7: =SUMIF('05_Dinh_Muc_Khoan_Routing'!$C$4:$C$100, C7, '05_Dinh_Muc_Khoan_Routing'!$P$4:$P$100) | K7: =G7+H7+I7+J7 | L7: =K7*0.15 | M7: =K7+L7 | N7: =M7*0.18 | O7: =M7+N7 | P7: Vít đùn công nghiệp
A8: 5 | B8: Win-Win | C8: Cánh xoắn vít đùn ISHIZUE 114Dw300 | D8: Thép đúc hợp kim Cr | E8: 65 | F8: 52000 | G8: =E8*F8 | H8: =SUMIF('05_Dinh_Muc_Khoan_Routing'!$C$4:$C$100, C8, '05_Dinh_Muc_Khoan_Routing'!$N$4:$N$100) | I8: =SUMIF('05_Dinh_Muc_Khoan_Routing'!$C$4:$C$100, C8, '05_Dinh_Muc_Khoan_Routing'!$M$4:$M$100) | J8: =SUMIF('05_Dinh_Muc_Khoan_Routing'!$C$4:$C$100, C8, '05_Dinh_Muc_Khoan_Routing'!$P$4:$P$100) | K8: =G8+H8+I8+J8 | L8: =K8*0.15 | M8: =K8+L8 | N8: =M8*0.18 | O8: =M8+N8 | P8: Vít đùn cỡ nhỏ
A9: 6 | B9: Thyssen | C9: Sealing strip, below | D9: Thép hợp kim chống mòn | E9: 45 | F9: 62000 | G9: =E9*F9 | H9: =SUMIF('05_Dinh_Muc_Khoan_Routing'!$C$4:$C$100, C9, '05_Dinh_Muc_Khoan_Routing'!$N$4:$N$100) | I9: =SUMIF('05_Dinh_Muc_Khoan_Routing'!$C$4:$C$100, C9, '05_Dinh_Muc_Khoan_Routing'!$M$4:$M$100) | J9: =SUMIF('05_Dinh_Muc_Khoan_Routing'!$C$4:$C$100, C9, '05_Dinh_Muc_Khoan_Routing'!$P$4:$P$100) | K9: =G9+H9+I9+J9 | L9: =K9*0.15 | M9: =K9+L9 | N9: =M9*0.18 | O9: =M9+N9 | P9: Thanh làm kín xỉ
A10: 7 | B10: Thyssen | C10: Sealing strip, above | D10: Thép hợp kim chống mòn | E10: 48 | F10: 62000 | G10: =E10*F10 | H10: =SUMIF('05_Dinh_Muc_Khoan_Routing'!$C$4:$C$100, C10, '05_Dinh_Muc_Khoan_Routing'!$N$4:$N$100) | I10: =SUMIF('05_Dinh_Muc_Khoan_Routing'!$C$4:$C$100, C10, '05_Dinh_Muc_Khoan_Routing'!$M$4:$M$100) | J10: =SUMIF('05_Dinh_Muc_Khoan_Routing'!$C$4:$C$100, C10, '05_Dinh_Muc_Khoan_Routing'!$P$4:$P$100) | K10: =G10+H10+I10+J10 | L10: =K10*0.15 | M10: =K10+L10 | N10: =M10*0.18 | O10: =M10+N10 | P10: Thanh làm kín trên
A11: 8 | B11: Luợng- KS Tường Long | C11: Ốp dao nhào trên (Bộ bên trái) | D11: Thép đúc va đập cao | E11: 120 | F11: 50000 | G11: =E11*F11 | H11: =SUMIF('05_Dinh_Muc_Khoan_Routing'!$C$4:$C$100, C11, '05_Dinh_Muc_Khoan_Routing'!$N$4:$N$100) | I11: =SUMIF('05_Dinh_Muc_Khoan_Routing'!$C$4:$C$100, C11, '05_Dinh_Muc_Khoan_Routing'!$M$4:$M$100) | J11: =SUMIF('05_Dinh_Muc_Khoan_Routing'!$C$4:$C$100, C11, '05_Dinh_Muc_Khoan_Routing'!$P$4:$P$100) | K11: =G11+H11+I11+J11 | L11: =K11*0.15 | M11: =K11+L11 | N11: =M11*0.18 | O11: =M11+N11 | P11: Ốp đầu dao nhào
A12: 9 | B12: UCC | C12: Khuôn gá xích POWER | D12: Thép hợp kim Cr12MoV | E12: 85 | F12: 75000 | G12: =E12*F12 | H12: =SUMIF('05_Dinh_Muc_Khoan_Routing'!$C$4:$C$100, C12, '05_Dinh_Muc_Khoan_Routing'!$N$4:$N$100) | I12: =SUMIF('05_Dinh_Muc_Khoan_Routing'!$C$4:$C$100, C12, '05_Dinh_Muc_Khoan_Routing'!$M$4:$M$100) | J12: =SUMIF('05_Dinh_Muc_Khoan_Routing'!$C$4:$C$100, C12, '05_Dinh_Muc_Khoan_Routing'!$P$4:$P$100) | K12: =G12+H12+I12+J12 | L12: =K12*0.15 | M12: =K12+L12 | N12: =M12*0.18 | O12: =M12+N12 | P12: Khuôn dập xích
A13: 10 | B13: Vico- QLTB | C13: Mẫu Thử CR & hàng # | D13: Thép đúc mẫu ASTM | E13: 15 | F13: 60000 | G13: =E13*F13 | H13: =SUMIF('05_Dinh_Muc_Khoan_Routing'!$C$4:$C$100, C13, '05_Dinh_Muc_Khoan_Routing'!$N$4:$N$100) | I13: =SUMIF('05_Dinh_Muc_Khoan_Routing'!$C$4:$C$100, C13, '05_Dinh_Muc_Khoan_Routing'!$M$4:$M$100) | J13: =SUMIF('05_Dinh_Muc_Khoan_Routing'!$C$4:$C$100, C13, '05_Dinh_Muc_Khoan_Routing'!$P$4:$P$100) | K13: =G13+H13+I13+J13 | L13: =K13*0.15 | M13: =K13+L13 | N13: =M13*0.18 | O13: =M13+N13 | P13: Mẫu kiểm định cơ tính

Sheet 05_Dinh_Muc_Khoan_Routing
A1: BẢNG ĐỊNH MỨC CÔNG NGHỆ, MỨC KHOÁN THEO TỪNG NGUYÊN CÔNG & TIÊU HAO DAO CỤ
A2: Phân xưởng Cơ khí | Bấm giờ định mức (phút/giờ) - Chọn máy phù hợp - Định mức dao cụ (lưỡi cắt) - Mức khoán công nhân (VNĐ/chi tiết)
A3: STT | B3: Khách Hàng | C3: Tên Sản Phẩm Đúc | D3: Thứ Tự NC | E3: Nội Dung Nguyên Công Gia Công | F3: Máy Gia Công Chỉ Định | G3: Định Mức Giờ (h) | H3: Định Mức Phút (p) | I3: Chủng Loại Dụng Cụ Cắt | J3: Số Lưỡi Cắt / Mảnh | K3: Tuổi Thọ (Chi Tiết / Lưỡi) | L3: Đơn Giá Mảnh Dao (VNĐ) | M3: Chi Phí Dao / Chi Tiết (VNĐ) | N3: MỨC KHOÁN THỢ (VNĐ/CT) | O3: Đơn Giá Giờ Máy (VNĐ/h) | P3: Chi Phí Máy / Chi Tiết (VNĐ) | Q3: Người Phê Duyệt | R3: Ngày Hiệu Lực | S3: Phiên Bản Định Mức | T3: Trạng Thái Khóa
A4: 1 | B4: Hà Song Hải - XM Hạ Long | C4: Thanh đập đá vôi (2240x510x145) | D4: NC1 | E4: G/c phay thô phá vỏ đúc & bán tinh mặt phẳng Kt 445/145mm | F4: Máy Phay OIGO | G4: =H4/60 | H4: 360 | I4: Đài phay chíp tròn R6 phủ CVD va đập | J4: 4 | K4: 0.5 | L4: 180000 | M4: =(L4/J4)/K4 | N4: 1562400 | O4: 280000 | P4: =G4*O4 | Q4: Quản Đốc & Ban Giám Đốc | R4: 2026-08-01 | S4: v2.0-CHÍNH THỨC | T4: 🔒 ĐÃ KHÓA CỐ ĐỊNH (BẢO LƯU)
A5: 2 | B5: Hà Song Hải - XM Hạ Long | C5: Thanh đập đá vôi (2240x510x145) | D5: NC2 | E5: G/c phay hoàn thiện rãnh 62/52mm & bo mép R | F5: Máy Phay OIGO | G5: =H5/60 | H5: 240 | I5: Dao phay gắn mảnh CBN chịu nhiệt | J5: 2 | K5: 0.25 | L5: 450000 | M5: =(L5/J5)/K5 | N5: 892800 | O5: 280000 | P5: =G5*O5 | Q5: Quản Đốc & Ban Giám Đốc | R5: 2026-08-01 | S5: v2.0-CHÍNH THỨC | T5: 🔒 ĐÃ KHÓA CỐ ĐỊNH (BẢO LƯU)
A6: 3 | B6: Hải- Vinh Quảng Ninh | C6: Bộ rulo máy nghiền sơ cấp: Thân rô to (φ820x890) | D6: NC1 | E6: G/c tiện khỏa mặt đầu L=690mm (Mặt 1 & 2) | F6: Máy tiện Tiện T1516 | G6: =H6/60 | H6: 180 | I6: Dao tiện thô WNMG 080408 cán vuông 32 | J6: 6 | K6: 1 | L6: 120000 | M6: =(L6/J6)/K6 | N6: 350000 | O6: 320000 | P6: =G6*O6 | Q6: Quản Đốc & Ban Giám Đốc | R6: 2026-08-01 | S6: v2.0-CHÍNH THỨC | T6: 🔒 ĐÃ KHÓA CỐ ĐỊNH (BẢO LƯU)
A7: 4 | B7: Hải- Vinh Quảng Ninh | C7: Bộ rulo máy nghiền sơ cấp: Thân rô to (φ820x890) | D7: NC2 | E7: G/c tiện thô & bán tinh ngoài Ø820 / Ø690mm | F7: Máy tiện Tiện T1517 | G7: =H7/60 | H7: 860 | I7: Chíp CNMG 160612 mác đúc hợp kim | J7: 4 | K7: 0.5 | L7: 160000 | M7: =(L7/J7)/K7 | N7: 1800000 | O7: 320000 | P7: =G7*O7 | Q7: Quản Đốc & Ban Giám Đốc | R7: 2026-08-01 | S7: v2.0-CHÍNH THỨC | T7: 🔒 ĐÃ KHÓA CỐ ĐỊNH (BẢO LƯU)
A8: 5 | B8: Hải- Vinh Quảng Ninh | C8: Bộ rulo máy nghiền sơ cấp: Thân rô to (φ820x890) | D8: NC3 | E8: G/c tiện tinh Ø570/220mm, bo cung R20 | F8: Máy tiện Tiện T1516 | G8: =H8/60 | H8: 240 | I8: Chíp R5 THREADEX - P3200 | J8: 2 | K8: 1 | L8: 220000 | M8: =(L8/J8)/K8 | N8: 500000 | O8: 320000 | P8: =G8*O8 | Q8: Quản Đốc & Ban Giám Đốc | R8: 2026-08-01 | S8: v2.0-CHÍNH THỨC | T8: 🔒 ĐÃ KHÓA CỐ ĐỊNH (BẢO LƯU)
A9: 6 | B9: Hải- Vinh Quảng Ninh | C9: Bộ rulo máy nghiền sơ cấp: Thân rô to (φ820x890) | D9: NC4 | E9: G/c tiện tinh trục Ø220 (+0.1/-0)mm | F9: Máy tiện Tiện T1516 | G9: =H9/60 | H9: 60 | I9: Chíp tiện tinh TNMG 160404 giảm chấn | J9: 6 | K9: 2 | L9: 110000 | M9: =(L9/J9)/K9 | N9: 150000 | O9: 320000 | P9: =G9*O9 | Q9: Quản Đốc & Ban Giám Đốc | R9: 2026-08-01 | S9: v2.0-CHÍNH THỨC | T9: 🔒 ĐÃ KHÓA CỐ ĐỊNH (BẢO LƯU)
A10: 7 | B10: Hải- Vinh Quảng Ninh | C10: Bộ rulo máy nghiền sơ cấp: Thân rô to (φ820x890) | D10: NC5 | E10: G/c tiện đầu đối diện Ø570/220mm đảo đầu | F10: Máy tiện Tiện T1516 | G10: =H10/60 | H10: 240 | I10: Chíp R5 THREADEX - P3200 | J10: 2 | K10: 1 | L10: 220000 | M10: =(L10/J10)/K10 | N10: 500000 | O10: 320000 | P10: =G10*O10 | Q10: Quản Đốc & Ban Giám Đốc | R10: 2026-08-01 | S10: v2.0-CHÍNH THỨC | T10: 🔒 ĐÃ KHÓA CỐ ĐỊNH (BẢO LƯU)
A11: 8 | B11: Hải- Vinh Quảng Ninh | C11: Bộ rulo máy nghiền sơ cấp: Thân rô to (φ820x890) | D11: NC6 | E11: G/c tiện trục đối diện Ø220 (+0.1/-0) đảo đầu | F11: Máy tiện Tiện T1516 | G11: =H11/60 | H11: 60 | I11: Chíp tiện tinh TNMG 160404 giảm chấn | J11: 6 | K11: 2 | L11: 110000 | M11: =(L11/J11)/K11 | N11: 150000 | O11: 320000 | P11: =G11*O11 | Q11: Quản Đốc & Ban Giám Đốc | R11: 2026-08-01 | S11: v2.0-CHÍNH THỨC | T11: 🔒 ĐÃ KHÓA CỐ ĐỊNH (BẢO LƯU)
A12: 9 | B12: Hải- Vinh Quảng Ninh | C12: Bộ rulo máy nghiền sơ cấp: Thân rô to (φ820x890) | D12: NC7 | E12: G/c phay mp hoàn thiện 8 mặt x (690x80mm) | F12: Máy tiện Tiện T1522 | G12: =H12/60 | H12: 225 | I12: Đài phay mặt chíp APMT 1604 PDER | J12: 2 | K12: 0.5 | L12: 95000 | M12: =(L12/J12)/K12 | N12: 450000 | O12: 320000 | P12: =G12*O12 | Q12: Quản Đốc & Ban Giám Đốc | R12: 2026-08-01 | S12: v2.0-CHÍNH THỨC | T12: 🔒 ĐÃ KHÓA CỐ ĐỊNH (BẢO LƯU)
A13: 10 | B13: Hải- Vinh Quảng Ninh | C13: Bộ rulo máy nghiền sơ cấp: Thân rô to (φ820x890) | D13: NC8 | E13: G/c khoan 40 lỗ x Ø22mm | F13: Máy Khoan cần Yoshida | G13: =H13/60 | H13: 450 | I13: Mũi khoan hợp kim gắn mảnh Ø22 | J13: 2 | K13: 2 | L13: 650000 | M13: =(L13/J13)/K13 | N13: 650000 | O13: 130000 | P13: =G13*O13 | Q13: Quản Đốc & Ban Giám Đốc | R13: 2026-08-01 | S13: v2.0-CHÍNH THỨC | T13: 🔒 ĐÃ KHÓA CỐ ĐỊNH (BẢO LƯU)
A14: 11 | B14: Hải- Vinh Quảng Ninh | C14: Bộ rulo máy nghiền sơ cấp: Thân rô to (φ820x890) | D14: NC9 | E14: G/c khoan & taro 12 lỗ ren M16 x 2.0 | F14: Máy Khoan cần Yoshida | G14: =H14/60 | H14: 450 | I14: Mũi taro rãnh xoắn hợp kim M16 | J14: 1 | K14: 5 | L14: 450000 | M14: =(L14/J14)/K14 | N14: 650000 | O14: 130000 | P14: =G14*O14 | Q14: Quản Đốc & Ban Giám Đốc | R14: 2026-08-01 | S14: v2.0-CHÍNH THỨC | T14: 🔒 ĐÃ KHÓA CỐ ĐỊNH (BẢO LƯU)
A15: 12 | B15: Hải- Vinh Quảng Ninh | C15: Bộ rulo máy nghiền sơ cấp: Bích rulo (φ500x110) 1T | D15: NC1 | E15: G/c tiện hoàn thiện ngoài Ø500/250mm | F15: Máy tiện FUJI | G15: =H15/60 | H15: 225 | I15: Dao tiện WNMG 080408 | J15: 6 | K15: 1 | L15: 120000 | M15: =(L15/J15)/K15 | N15: 250000 | O15: 220000 | P15: =G15*O15 | Q15: Quản Đốc & Ban Giám Đốc | R15: 2026-08-01 | S15: v2.0-CHÍNH THỨC | T15: 🔒 ĐÃ KHÓA CỐ ĐỊNH (BẢO LƯU)
... A21: 18 | B21: Win-Win | C21: Cánh xoắn vít đùn ISHIZUE 355Dw900 | D21: NC3 | E21: G/c tiện tinh hoàn thiện cánh xoắn & vát mép | F21: Máy tiện FUJI | G21: =H21/60 | H21: 120 | I21: Chíp R5 THREADEX - P3200 | J21: 2 | K21: 1 | L21: 220000 | M21: =(L21/J21)/K21 | N21: 350000 | O21: 220000 | P21: =G21*O21 | Q21: Quản Đốc & Ban Giám Đốc | R21: 2026-08-01 | S21: v2.0-CHÍNH THỨC | T21: 🔒 ĐÃ KHÓA CỐ ĐỊNH (BẢO LƯU)
A22: 19 | B22: Win-Win | C22: Cánh xoắn vít đùn ISHIZUE 114Dw300 | D22: NC1 | E22: G/c tiện hoàn thiện toàn bộ biên dạng cánh | F22: Máy tiện OKUMA | G22: 0.24 | H22: 14.5 | I22: Chíp R5 THREADEX - P3200 | J22: 2 | K22: 2 | L22: 220000 | M22: =(L22/J22)/K22 | N22: 83700 | O22: 220000 | P22: =G22*O22 | Q22: Quản Đốc & Ban Giám Đốc | R22: 2026-08-01 | S22: v2.0-CHÍNH THỨC | T22: 🔒 ĐÃ KHÓA CỐ ĐỊNH (BẢO LƯU)
A23: 20 | B23: Thyssen | C23: Sealing strip, below | D23: NC1 | E23: G/c phay mặt phẳng NC1 kích thước 47mm | F23: Máy Phay OKK3 | G23: =H23/60 | H23: 45 | I23: Chíp Pramet 6 cạnh (HNGX 0906) | J23: 6 | K23: 3 | L23: 140000 | M23: =(L23/J23)/K23 | N23: 37200 | O23: 250000 | P23: =G23*O23 | Q23: Quản Đốc & Ban Giám Đốc | R23: 2026-08-01 | S23: v2.0-CHÍNH THỨC | T23: 🔒 ĐÃ KHÓA CỐ ĐỊNH (BẢO LƯU)
A24: 21 | B24: Thyssen | C24: Sealing strip, below | D24: NC2 | E24: G/c phay mặt phẳng NC2 kích thước 95mm | F24: Máy Phay OKK1 | G24: =H24/60 | H24: 50 | I24: Chíp APMT 1604 PDER - Pramet | J24: 2 | K24: 2 | L24: 95000 | M24: =(L24/J24)/K24 | N24: 37200 | O24: 250000 | P24: =G24*O24 | Q24: Quản Đốc & Ban Giám Đốc | R24: 2026-08-01 | S24: v2.0-CHÍNH THỨC | T24: 🔒 ĐÃ KHÓA CỐ ĐỊNH (BẢO LƯU)
A25: 22 | B25: Thyssen | C25: Sealing strip, below | D25: NC3 | E25: G/c phay cạnh NC3 kích thước 12mm | F25: Máy Phay OKK1 | G25: =H25/60 | H25: 35 | I25: Dao phay ngón Solid Carbide Ø12 | J25: 4 | K25: 8 | L25: 380000 | M25: =(L25/J25)/K25 | N25: 45000 | O25: 250000 | P25: =G25*O25 | Q25: Quản Đốc & Ban Giám Đốc | R25: 2026-08-01 | S25: v2.0-CHÍNH THỨC | T25: 🔒 ĐÃ KHÓA CỐ ĐỊNH (BẢO LƯU)
A26: 23 | B26: Thyssen | C26: Sealing strip, below | D26: NC4 | E26: G/c khoan lỗ phi 14 / 2 lỗ | F26: Máy Khoan cần Yoshida | G26: 0.27 | H26: 16 | I26: Mũi khoan hợp kim Ø14 | J26: 2 | K26: 10 | L26: 280000 | M26: =(L26/J26)/K26 | N26: 26148 | O26: 130000 | P26: =G26*O26 | Q26: Quản Đốc & Ban Giám Đốc | R26: 2026-08-01 | S26: v2.0-CHÍNH THỨC | T26: 🔒 ĐÃ KHÓA CỐ ĐỊNH (BẢO LƯU)
A27: 24 | B27: Thyssen | C27: Sealing strip, above | D27: NC1 | E27: G/c phay mặt phẳng NC1 kích thước 95mm | F27: Máy Phay OKK3 | G27: =H27/60 | H27: 45 | I27: Chíp Pramet 6 cạnh (HNGX 0906) | J27: 6 | K27: 3 | L27: 140000 | M27: =(L27/J27)/K27 | N27: 37200 | O27: 250000 | P27: =G27*O27 | Q27: Quản Đốc & Ban Giám Đốc | R27: 2026-08-01 | S27: v2.0-CHÍNH THỨC | T27: 🔒 ĐÃ KHÓA CỐ ĐỊNH (BẢO LƯU)
A28: 25 | B28: Thyssen | C28: Sealing strip, above | D28: NC2 | E28: G/c phay mặt phẳng NC2 kích thước 412mm | F28: Máy Phay OKK2 | G28: 0.6 | H28: 36 | I28: Chíp APMT 1604 PDER - Pramet | J28: 2 | K28: 1.5 | L28: 95000 | M28: =(L28/J28)/K28 | N28: 45000 | O28: 250000 | P28: =G28*O28 | Q28: Quản Đốc & Ban Giám Đốc | R28: 2026-08-01 | S28: v2.0-CHÍNH THỨC | T28: 🔒 ĐÃ KHÓA CỐ ĐỊNH (BẢO LƯU)
A29: 26 | B29: Thyssen | C29: Sealing strip, above | D29: NC3 | E29: G/c phay mặt phẳng NC3 kích thước 412mm còn lại | F29: Máy Phay OKK2 | G29: 0.6 | H29: 36 | I29: Chíp APMT 1604 PDER - Pramet | J29: 2 | K29: 1.5 | L29: 95000 | M29: =(L29/J29)/K29 | N29: 45000 | O29: 250000 | P29: =G29*O29 | Q29: Quản Đốc & Ban Giám Đốc | R29: 2026-08-01 | S29: v2.0-CHÍNH THỨC | T29: 🔒 ĐÃ KHÓA CỐ ĐỊNH (BẢO LƯU)
A30: 27 | B30: Luợng- KS Tường Long | C30: Ốp dao nhào trên (Bộ bên trái) | D30: NC1 | E30: G/c cắt dây định hình biên dạng đúc | F30: Máy Cắt Dây DK7745 | G30: =H30/60 | H30: 150 | I30: Dây cắt Molypden 0.18mm | J30: 1 | K30: 5 | L30: 120000 | M30: =(L30/J30)/K30 | N30: 148800 | O30: 110000 | P30: =G30*O30 | Q30: Quản Đốc & Ban Giám Đốc | R30: 2026-08-01 | S30: v2.0-CHÍNH THỨC | T30: 🔒 ĐÃ KHÓA CỐ ĐỊNH (BẢO LƯU)
A31: 28 | B31: Luợng- KS Tường Long | C31: Ốp dao nhào trên (Bộ bên trái) | D31: NC2 | E31: G/c khoan & taro ren M14 | F31: Máy Khoan cần Yoshida | G31: 0.27 | H31: 16 | I31: Mũi taro rãnh xoắn M14 | J31: 1 | K31: 8 | L31: 320000 | M31: =(L31/J31)/K31 | N31: 63767 | O31: 130000 | P31: =G31*O31 | Q31: Quản Đốc & Ban Giám Đốc | R31: 2026-08-01 | S31: v2.0-CHÍNH THỨC | T31: 🔒 ĐÃ KHÓA CỐ ĐỊNH (BẢO LƯU)
A32: 29 | B32: UCC | C32: Khuôn gá xích POWER | D32: NC1 | E32: G/c phay phá thô hốc khuôn gá | F32: Máy Phay CNC1 | G32: =H32/60 | H32: 120 | I32: Đài phay gắn mảnh APMT 1604 | J32: 2 | K32: 1 | L32: 95000 | M32: =(L32/J32)/K32 | N32: 150000 | O32: 220000 | P32: =G32*O32 | Q32: Quản Đốc & Ban Giám Đốc | R32: 2026-08-01 | S32: v2.0-CHÍNH THỨC | T32: 🔒 ĐÃ KHÓA CỐ ĐỊNH (BẢO LƯU)
A33: 30 | B33: UCC | C33: Khuôn gá xích POWER | D33: NC2 | E33: G/c phay tinh biên dạng sau tôi | F33: Máy Phay CNC2 | G33: =H33/60 | H33: 150 | I33: Mảnh phay CBN gia công thép tôi | J33: 2 | K33: 0.5 | L33: 450000 | M33: =(L33/J33)/K33 | N33: 250000 | O33: 220000 | P33: =G33*O33 | Q33: Quản Đốc & Ban Giám Đốc | R33: 2026-08-01 | S33: v2.0-CHÍNH THỨC | T33: 🔒 ĐÃ KHÓA CỐ ĐỊNH (BẢO LƯU)
A34: 31 | B34: Vico- QLTB | C34: Mẫu Thử CR & hàng # | D34: NC1 | E34: G/c tiện hoàn thiện mẫu thử ASTM | F34: Máy tiện FUJI | G34: =H34/60 | H34: 40 | I34: Dao tiện tinh TNMG 160404 | J34: 6 | K34: 5 | L34: 110000 | M34: =(L34/J34)/K34 | N34: 79483 | O34: 220000 | P34: =G34*O34 | Q34: Quản Đốc & Ban Giám Đốc | R34: 2026-08-01 | S34: v2.0-CHÍNH THỨC | T34: 🔒 ĐÃ KHÓA CỐ ĐỊNH (BẢO LƯU)
A35: 32 | B35: Thyssen | C35: Sealing strip, above | D35: NC4 | E35: G/c khoan lỗ phi 14 | F35: Máy Khoan cần Yoshida | G35: 0.27 | H35: 16 | I35: Mũi khoan hợp kim Ø14 | J35: 2 | N35: 18000 | Q35: Quản Đốc & Ban Giám Đốc | R35: 2026-08-01 | S35: v2.0-CHÍNH THỨC | T35: 🔒 ĐÃ KHÓA CỐ ĐỊNH (BẢO LƯU)
A36: 33 | B36: Thyssen | C36: Sealing strip, above | D36: NC4 | E36: G/c doa lỗ phi 32 | F36: Máy Phay OKK1 | G36: 0.33 | H36: 20 | I36: Mũi doa hợp kim Ø32 | J36: 2 | N36: 22000 | Q36: Quản Đốc & Ban Giám Đốc | R36: 2026-08-01 | S36: v2.0-CHÍNH THỨC | T36: 🔒 ĐÃ KHÓA CỐ ĐỊNH (BẢO LƯU)

Sheet 06_Ke_Hoach_Tien_Do_PO
A1: KẾ HOẠCH TIẾN ĐỘ SẢN XUẤT & ĐIỀU ĐỘ ĐƠN HÀNG (PO/LSX) THEO KHÁCH HÀNG
A2: Phân xưởng Gia công Cơ khí | Tự động cân đối: Kế hoạch giao hàng - BTP xong tại xưởng - Đã bàn giao chuyển khâu - Tồn chờ bàn giao
A3: STT | B3: Mã Lệnh SX / PO | C3: Khách Hàng | D3: Tên / Quy Cách Chi Tiết Đúc | E3: SL Kế Hoạch (Chi tiết) | F3: BTP Xong Tại Xưởng | G3: Đã Bàn Giao Đi | H3: Tồn Chờ Bàn Giao (WIP) | I3: Còn Nợ Kế Hoạch | J3: Khâu Chuyển Tiếp Theo | K3: Ngày Bắt Đầu | L3: Hạn Giao BTP | M3: Tiến Độ Bàn Giao (%) | N3: Trạng Thái Điều Độ | O3: Mã NC Cuối (Đích) | P3: Tên NC Cuối Hoàn Thiện BTP
A4: 1 | B4: PO-2026-001 | C4: Win-Win | D4: Trục Khuỷu Động Cơ Φ250 | E4: 1000 | F4: 0 | G4: 500 | H4: =MAX(0, F4-G4) | I4: =MAX(0, E4-G4) | J4: Bộ Phận Hoàn Thiện (Lắp ráp/Bao gói) | K4: 46235 | L4: 46264 | M4: =IF(E4>0, G4/E4, 0) | N4: =IF(E4=0, "Chưa có đơn hàng", IF(G4>E4, "⚠️ BÀN GIAO VƯỢT KH", IF(G4>=E4, "Đã bàn giao đủ", IF(F4>=E4, "Xong xưởng - Chờ chuyển", IF(F4>0, "Đang gia công trên máy", "Chờ nhận phôi đúc"))))) | O4: NC2 | P4: G/c tiện tinh cổ trục & mài hoàn thiện
A5: 2 | B5: PO-2026-002 | C5: UCC | D5: Khuôn gá xích POWER | E5: 200 | F5: 0 | G5: 400 | H5: =MAX(0, F5-G5) | I5: =MAX(0, E5-G5) | J5: PX Nhiệt Luyện (Tôi chân không) | K5: 46239 | L5: 46254 | M5: =IF(E5>0, G5/E5, 0) | N5: =IF(E5=0, "Chưa có đơn hàng", IF(G5>E5, "⚠️ BÀN GIAO VƯỢT KH", IF(G5>=E5, "Đã bàn giao đủ", IF(F5>=E5, "Xong xưởng - Chờ chuyển", IF(F5>0, "Đang gia công trên máy", "Chờ nhận phôi đúc"))))) | O5: NC2 | P5: G/c phay tinh lỗ & lắp chốt định vị
A6: 3 | B6: PO-2026-003 | C6: Vico- QLTB | D6: Mẫu Thử CR & hàng # | E6: 500 | F6: 0 | G6: 0 | H6: =MAX(0, F6-G6) | I6: =MAX(0, E6-G6) | J6: Phòng KCS / Thử Nghiệm ASTM | K6: 46244 | L6: 46259 | M6: =IF(E6>0, G6/E6, 0) | N6: =IF(E6=0, "Chưa có đơn hàng", IF(G6>E6, "⚠️ BÀN GIAO VƯỢT KH", IF(G6>=E6, "Đã bàn giao đủ", IF(F6>=E6, "Xong xưởng - Chờ chuyển", IF(F6>0, "Đang gia công trên máy", "Chờ nhận phôi đúc"))))) | O6: NC1 | P6: G/c tiện phay mẫu thử nghiệm ASTM
A7: 4 | B7: PO-1602 | C7: Hà Song Hải - XM Hạ Long | D7: Thanh đập đá vôi (2240x510x145) | E7: 1 | F7: 0.25 | G7: 1 | H7: 0 | I7: =MAX(0, E7-G7) | J7: PX Nhiệt Luyện (Tôi cao tần) | K7: 46264 | L7: 46271 | M7: =IF(E7>0, G7/E7, 0) | N7: =IF(E7=0, "Chưa có đơn hàng", IF(G7>E7, "⚠️ BÀN GIAO VƯỢT KH", IF(G7>=E7, "Đã bàn giao đủ", IF(F7>=E7, "Xong xưởng - Chờ chuyển", IF(F7>0, "Đang gia công trên máy", "Chờ nhận phôi đúc"))))) | O7: NC2 | P7: G/c phay hoàn thiện rãnh 62/52mm & bo mép R
A8: 5 | B8: PO-3429 | C8: Hà Song Hải - XM Hạ Long | D8: Thanh đập đá vôi (2240x510x145) | E8: 1 | F8: 0 | G8: 0 | H8: =MAX(0, F8-G8) | I8: =MAX(0, E8-G8) | J8: PX Nhiệt Luyện (Tôi cao tần) | K8: 46265 | L8: 46272 | M8: =IF(E8>0, G8/E8, 0) | N8: =IF(E8=0, "Chưa có đơn hàng", IF(G8>E8, "⚠️ BÀN GIAO VƯỢT KH", IF(G8>=E8, "Đã bàn giao đủ", IF(F8>=E8, "Xong xưởng - Chờ chuyển", IF(F8>0, "Đang gia công trên máy", "Chờ nhận phôi đúc"))))) | O8: NC2 | P8: G/c phay hoàn thiện rãnh 62/52mm & bo mép R
A9: 6 | B9: PO-5670 | C9: Hà Song Hải - XM Hạ Long | D9: Thanh đập đá vôi (2240x510x145) | E9: 1 | F9: 1.25 | G9: 0 | H9: 1.25 | I9: =MAX(0, E9-G9) | J9: PX Nhiệt Luyện (Tôi cao tần) | K9: 46265 | L9: 46272 | M9: =IF(E9>0, G9/E9, 0) | N9: =IF(E9=0, "Chưa có đơn hàng", IF(G9>E9, "⚠️ BÀN GIAO VƯỢT KH", IF(G9>=E9, "Đã bàn giao đủ", IF(F9>=E9, "Xong xưởng - Chờ chuyển", IF(F9>0, "Đang gia công trên máy", "Chờ nhận phôi đúc"))))) | O9: NC2 | P9: G/c phay hoàn thiện rãnh 62/52mm & bo mép R
A10: 7 | B10: PO-6829 | C10: Hà Song Hải - XM Hạ Long | D10: Thanh đập đá vôi (2240x510x145) | E10: 1 | F10: 0 | G10: 0 | H10: =MAX(0, F10-G10) | I10: =MAX(0, E10-G10) | J10: PX Nhiệt Luyện (Tôi cao tần) | K10: 46266 | L10: 46273 | M10: =IF(E10>0, G10/E10, 0) | N10: =IF(E10=0, "Chưa có đơn hàng", IF(G10>E10, "⚠️ BÀN GIAO VƯỢT KH", IF(G10>=E10, "Đã bàn giao đủ", IF(F10>=E10, "Xong xưởng - Chờ chuyển", IF(F10>0, "Đang gia công trên máy", "Chờ nhận phôi đúc"))))) | O10: NC2 | P10: G/c phay hoàn thiện rãnh 62/52mm & bo mép R
A11: 8 | B11: PO-7044 | C11: Hà Song Hải - XM Hạ Long | D11: Thanh đập đá vôi (2240x510x145) | E11: 1 | F11: 0 | G11: 0 | H11: =MAX(0, F11-G11) | I11: =MAX(0, E11-G11) | J11: PX Nhiệt Luyện (Tôi cao tần) | K11: 46264 | L11: 46271 | M11: =IF(E11>0, G11/E11, 0) | N11: =IF(E11=0, "Chưa có đơn hàng", IF(G11>E11, "⚠️ BÀN GIAO VƯỢT KH", IF(G11>=E11, "Đã bàn giao đủ", IF(F11>=E11, "Xong xưởng - Chờ chuyển", IF(F11>0, "Đang gia công trên máy", "Chờ nhận phôi đúc"))))) | O11: NC2 | P11: G/c phay hoàn thiện rãnh 62/52mm & bo mép R
A12: 9 | B12: PO-7189 | C12: Hà Song Hải - XM Hạ Long | D12: Thanh đập đá vôi (2240x510x145) | E12: 1 | F12: 0 | G12: 0 | H12: =MAX(0, F12-G12) | I12: =MAX(0, E12-G12) | J12: PX Nhiệt Luyện (Tôi cao tần) | K12: 46264 | L12: 46271 | M12: =IF(E12>0, G12/E12, 0) | N12: =IF(E12=0, "Chưa có đơn hàng", IF(G12>E12, "⚠️ BÀN GIAO VƯỢT KH", IF(G12>=E12, "Đã bàn giao đủ", IF(F12>=E12, "Xong xưởng - Chờ chuyển", IF(F12>0, "Đang gia công trên máy", "Chờ nhận phôi đúc"))))) | O12: NC2 | P12: G/c phay hoàn thiện rãnh 62/52mm & bo mép R
A13: 10 | B13: PO-7365 | C13: Hà Song Hải - XM Hạ Long | D13: Thanh đập đá vôi (2240x510x145) | E13: 1 | F13: 0 | G13: 0 | H13: =MAX(0, F13-G13) | I13: =MAX(0, E13-G13) | J13: PX Nhiệt Luyện (Tôi cao tần) | K13: 46263 | L13: 46270 | M13: =IF(E13>0, G13/E13, 0) | N13: =IF(E13=0, "Chưa có đơn hàng", IF(G13>E13, "⚠️ BÀN GIAO VƯỢT KH", IF(G13>=E13, "Đã bàn giao đủ", IF(F13>=E13, "Xong xưởng - Chờ chuyển", IF(F13>0, "Đang gia công trên máy", "Chờ nhận phôi đúc"))))) | O13: NC2 | P13: G/c phay hoàn thiện rãnh 62/52mm & bo mép R
A14: 11 | B14: PO-1279 | C14: Hải- Vinh Quảng Ninh | D14: Bộ rulo máy nghiền sơ cấp: Thân rồ to (φ820x890) | E14: 15 | F14: 0 | G14: 0 | H14: =MAX(0, F14-G14) | I14: =MAX(0, E14-G14) | J14: Tổ Lắp Ráp & Hoàn Thiện | K14: 46266 | L14: 46273 | M14: =IF(E14>0, G14/E14, 0) | N14: =IF(E14=0, "Chưa có đơn hàng", IF(G14>E14, "⚠️ BÀN GIAO VƯỢT KH", IF(G14>=E14, "Đã bàn giao đủ", IF(F14>=E14, "Xong xưởng - Chờ chuyển", IF(F14>0, "Đang gia công trên máy", "Chờ nhận phôi đúc"))))) | O14: NC9 | P14: G/c khoan & taro 12 lỗ ren M16 x 2.0
A15: 12 | B15: PO-2504 | C15: Hải- Vinh Quảng Ninh | D15: Bộ rulo máy nghiền sơ cấp: Thân rồ to (φ820x890) | E15: 2 | F15: 0 | G15: 0 | H15: =MAX(0, F15-G15) | I15: =MAX(0, E15-G15) | J15: Tổ Lắp Ráp & Hoàn Thiện | K15: 46255 | L15: 46262 | M15: =IF(E15>0, G15/E15, 0) | N15: =IF(E15=0, "Chưa có đơn hàng", IF(G15>E15, "⚠️ BÀN GIAO VƯỢT KH", IF(G15>=E15, "Đã bàn giao đủ", IF(F15>=E15, "Xong xưởng - Chờ chuyển", IF(F15>0, "Đang gia công trên máy", "Chờ nhận phôi đúc"))))) | O15: NC9 | P15: G/c khoan & taro 12 lỗ ren M16 x 2.0
A16: 13 | B16: PO-4603 | C16: Hải- Vinh Quảng Ninh | D16: Bộ rulo máy nghiền sơ cấp: Thân rồ to (φ820x890) | E16: 1 | F16: 0 | G16: 0 | H16: =MAX(0, F16-G16) | I16: =MAX(0, E16-G16) | J16: Tổ Lắp Ráp & Hoàn Thiện | K16: 46251 | L16: 46258 | M16: =IF(E16>0, G16/E16, 0) | N16: =IF(E16=0, "Chưa có đơn hàng", IF(G16>E16, "⚠️ BÀN GIAO VƯỢT KH", IF(G16>=E16, "Đã bàn giao đủ", IF(F16>=E16, "Xong xưởng - Chờ chuyển", IF(F16>0, "Đang gia công trên máy", "Chờ nhận phôi đúc"))))) | O16: NC9 | P16: G/c khoan & taro 12 lỗ ren M16 x 2.0
A17: 14 | B17: PO-5612 | C17: Hải- Vinh Quảng Ninh | D17: Bộ rulo máy nghiền sơ cấp: Bích rulo (φ500x110) 1T | E17: 1 | F17: 0 | G17: 0 | H17: =MAX(0, F17-G17) | I17: =MAX(0, E17-G17) | J17: Tổ Lắp Ráp & Hoàn Thiện | K17: 46251 | L17: 46258 | M17: =IF(E17>0, G17/E17, 0) | N17: =IF(E17=0, "Chưa có đơn hàng", IF(G17>E17, "⚠️ BÀN GIAO VƯỢT KH", IF(G17>=E17, "Đã bàn giao đủ", IF(F17>=E17, "Xong xưởng - Chờ chuyển", IF(F17>0, "Đang gia công trên máy", "Chờ nhận phôi đúc"))))) | O17: NC4 | P17: G/c cắt dây cavet DK7745 rãnh 32mm
A18: 15 | B18: PO-7487 | C18: Hải- Vinh Quảng Ninh | D18: Bộ rulo máy nghiền sơ cấp: Thân rồ to (φ820x890) | E18: 3 | F18: 0 | G18: 0 | H18: =MAX(0, F18-G18) | I18: =MAX(0, E18-G18) | J18: Tổ Lắp Ráp & Hoàn Thiện | K18: 46253 | L18: 46260 | M18: =IF(E18>0, G18/E18, 0) | N18: =IF(E18=0, "Chưa có đơn hàng", IF(G18>E18, "⚠️ BÀN GIAO VƯỢT KH", IF(G18>=E18, "Đã bàn giao đủ", IF(F18>=E18, "Xong xưởng - Chờ chuyển", IF(F18>0, "Đang gia công trên máy", "Chờ nhận phôi đúc"))))) | O18: NC9 | P18: G/c khoan & taro 12 lỗ ren M16 x 2.0
A19: 16 | B19: PO-8134 | C19: Hải- Vinh Quảng Ninh | D19: Bộ rulo máy nghiền sơ cấp: Thân rồ to (φ820x890) | E19: 15 | F19: 15 | G19: 15 | H19: =MAX(0, F19-G19) | I19: =MAX(0, E19-G19) | J19: Tổ Lắp Ráp & Hoàn Thiện | K19: 46266 | L19: 46273 | M19: =IF(E19>0, G19/E19, 0) | N19: =IF(E19=0, "Chưa có đơn hàng", IF(G19>E19, "⚠️ BÀN GIAO VƯỢT KH", IF(G19>=E19, "Đã bàn giao đủ", IF(F19>=E19, "Xong xưởng - Chờ chuyển", IF(F19>0, "Đang gia công trên máy", "Chờ nhận phôi đúc"))))) | O19: NC9 | P19: G/c khoan & taro 12 lỗ ren M16 x 2.0
A20: 17 | B20: PO-1537 | C20: Luợng- KS Tường Long | D20: Ốp dao nhào trên (Bộ bên trái) | E20: 1 | F20: 0 | G20: 0 | H20: =MAX(0, F20-G20) | I20: =MAX(0, E20-G20) | J20: Bộ Phận Hoàn Thiện (Lắp ráp/Bao gói) | K20: 46251 | L20: 46258 | M20: =IF(E20>0, G20/E20, 0) | N20: =IF(E20=0, "Chưa có đơn hàng", IF(G20>E20, "⚠️ BÀN GIAO VƯỢT KH", IF(G20>=E20, "Đã bàn giao đủ", IF(F20>=E20, "Xong xưởng - Chờ chuyển", IF(F20>0, "Đang gia công trên máy", "Chờ nhận phôi đúc"))))) | O20: NC2 | P20: G/c phay vát rãnh hoàn thiện BTP
A21: 18 | B21: PO-2080 | C21: Luợng- KS Tường Long | D21: Ốp dao nhào trên (Bộ bên trái) | E21: 2 | F21: 0 | G21: 0 | H21: =MAX(0, F21-G21) | I21: =MAX(0, E21-G21) | J21: Bộ Phận Hoàn Thiện (Lắp ráp/Bao gói) | K21: 46265 | L21: 46272 | M21: =IF(E21>0, G21/E21, 0) | N21: =IF(E21=0, "Chưa có đơn hàng", IF(G21>E21, "⚠️ BÀN GIAO VƯỢT KH", IF(G21>=E21, "Đã bàn giao đủ", IF(F21>=E21, "Xong xưởng - Chờ chuyển", IF(F21>0, "Đang gia công trên máy", "Chờ nhận phôi đúc"))))) | O21: NC2 | P21: G/c phay vát rãnh hoàn thiện BTP
... A58: 55 | B58: PO-1415 | C58: Thyssen | D58: Sealing strip, above | E58: 2 | F58: 0 | G58: 0 | H58: =MAX(0, F58-G58) | I58: =MAX(0, E58-G58) | J58: Bộ Phận Hoàn Thiện (Lắp ráp/Bao gói) | K58: 46263 | L58: 46270 | M58: =IF(E58>0, G58/E58, 0) | N58: =IF(E58=0, "Chưa có đơn hàng", IF(G58>E58, "⚠️ BÀN GIAO VƯỢT KH", IF(G58>=E58, "Đã bàn giao đủ", IF(F58>=E58, "Xong xưởng - Chờ chuyển", IF(F58>0, "Đang gia công trên máy", "Chờ nhận phôi đúc"))))) | O58: NC3 | P58: G/c khoan lỗ phi 14/2 lỗ hoàn thiện
A59: 56 | B59: PO-1464 | C59: Thyssen | D59: Sealing trip, below | E59: 29 | F59: 28.25 | G59: 0 | H59: 28.25 | I59: =MAX(0, E59-G59) | J59: Bộ Phận Hoàn Thiện (Lắp ráp/Bao gói) | K59: 46250 | L59: 46257 | M59: =IF(E59>0, G59/E59, 0) | N59: =IF(E59=0, "Chưa có đơn hàng", IF(G59>E59, "⚠️ BÀN GIAO VƯỢT KH", IF(G59>=E59, "Đã bàn giao đủ", IF(F59>=E59, "Xong xưởng - Chờ chuyển", IF(F59>0, "Đang gia công trên máy", "Chờ nhận phôi đúc"))))) | O59: NC4 | P59: G/c khoan lỗ phi 14/2 lỗ hoàn thiện
A60: 57 | B60: PO-1494 | C60: Thyssen | D60: Sealing trip, below | E60: 8 | F60: 0 | G60: 0 | H60: =MAX(0, F60-G60) | I60: =MAX(0, E60-G60) | J60: Bộ Phận Hoàn Thiện (Lắp ráp/Bao gói) | K60: 46248 | L60: 46255 | M60: =IF(E60>0, G60/E60, 0) | N60: =IF(E60=0, "Chưa có đơn hàng", IF(G60>E60, "⚠️ BÀN GIAO VƯỢT KH", IF(G60>=E60, "Đã bàn giao đủ", IF(F60>=E60, "Xong xưởng - Chờ chuyển", IF(F60>0, "Đang gia công trên máy", "Chờ nhận phôi đúc"))))) | O60: NC4 | P60: G/c khoan lỗ phi 14/2 lỗ hoàn thiện
A61: 58 | B61: PO-1502 | C61: Thyssen | D61: Sealing trip, below | E61: 5 | F61: 0 | G61: 0 | H61: =MAX(0, F61-G61) | I61: =MAX(0, E61-G61) | J61: Bộ Phận Hoàn Thiện (Lắp ráp/Bao gói) | K61: 46253 | L61: 46260 | M61: =IF(E61>0, G61/E61, 0) | N61: =IF(E61=0, "Chưa có đơn hàng", IF(G61>E61, "⚠️ BÀN GIAO VƯỢT KH", IF(G61>=E61, "Đã bàn giao đủ", IF(F61>=E61, "Xong xưởng - Chờ chuyển", IF(F61>0, "Đang gia công trên máy", "Chờ nhận phôi đúc"))))) | O61: NC4 | P61: G/c khoan lỗ phi 14/2 lỗ hoàn thiện
A62: 59 | B62: PO-1545 | C62: Thyssen | D62: Sealing strip, below | E62: 26 | F62: 0 | G62: 0 | H62: =MAX(0, F62-G62) | I62: =MAX(0, E62-G62) | J62: Bộ Phận Hoàn Thiện (Lắp ráp/Bao gói) | K62: 46253 | L62: 46260 | M62: =IF(E62>0, G62/E62, 0) | N62: =IF(E62=0, "Chưa có đơn hàng", IF(G62>E62, "⚠️ BÀN GIAO VƯỢT KH", IF(G62>=E62, "Đã bàn giao đủ", IF(F62>=E62, "Xong xưởng - Chờ chuyển", IF(F62>0, "Đang gia công trên máy", "Chờ nhận phôi đúc"))))) | O62: NC4 | P62: G/c khoan lỗ phi 14/2 lỗ hoàn thiện
A63: 60 | B63: PO-1592 | C63: Thyssen | D63: Sealing strip, below | E63: 16 | F63: 0 | G63: 0 | H63: =MAX(0, F63-G63) | I63: =MAX(0, E63-G63) | J63: Bộ Phận Hoàn Thiện (Lắp ráp/Bao gói) | K63: 46267 | L63: 46274 | M63: =IF(E63>0, G63/E63, 0) | N63: =IF(E63=0, "Chưa có đơn hàng", IF(G63>E63, "⚠️ BÀN GIAO VƯỢT KH", IF(G63>=E63, "Đã bàn giao đủ", IF(F63>=E63, "Xong xưởng - Chờ chuyển", IF(F63>0, "Đang gia công trên máy", "Chờ nhận phôi đúc"))))) | O63: NC4 | P63: G/c khoan lỗ phi 14/2 lỗ hoàn thiện
A64: 61 | B64: PO-1695 | C64: Thyssen | D64: Sealing trip, below | E64: 10 | F64: 0 | G64: 0 | H64: =MAX(0, F64-G64) | I64: =MAX(0, E64-G64) | J64: Bộ Phận Hoàn Thiện (Lắp ráp/Bao gói) | K64: 46249 | L64: 46256 | M64: =IF(E64>0, G64/E64, 0) | N64: =IF(E64=0, "Chưa có đơn hàng", IF(G64>E64, "⚠️ BÀN GIAO VƯỢT KH", IF(G64>=E64, "Đã bàn giao đủ", IF(F64>=E64, "Xong xưởng - Chờ chuyển", IF(F64>0, "Đang gia công trên máy", "Chờ nhận phôi đúc"))))) | O64: NC4 | P64: G/c khoan lỗ phi 14/2 lỗ hoàn thiện
E65: =SUM(E4:E64) | F65: =SUM(F4:F64) | G65: =SUM(G4:G64) | H65: =SUM(H4:H64) | I65: =SUM(I4:I64)

Sheet 07_OEE_Hieu_Suat_Thiet_Bi
A1: BẢNG PHÂN TÍCH HIỆU SUẤT THIẾT BỊ TỔNG THỂ 17 MÁY (OEE = AVAILABILITY x PERFORMANCE x QUALITY)
A2: Phân xưởng Gia công Cơ khí | Chuẩn quốc tế: A = T_chạy_thực/T_kế_hoạch | P = Tổng(SL*T_chuẩn)/T_chạy_thực | Q = SL_Đạt_KCS/Tổng_SL | OEE = A x P x Q
A3: STT | B3: Mã Thiết Bị | C3: Tên Thiết Bị / Máy Gia Công | D3: Nhóm Công Nghệ | E3: Số Ca Vận Hành | F3: Thời Gian Kế Hoạch (Phút) | G3: Thời Gian Dừng Sự Cố (Phút) | H3: Thời Gian Chạy Thực (Phút) | I3: Độ Sẵn Sàng A (%) | J3: Tổng SL Sản Xuất (Chi tiết) | K3: SL Đạt Nghiệm Thu (OK) | L3: Tỷ Lệ Chất Lượng Q (%) | M3: Tổng Phút Chuẩn Công Nghệ (Phút) | N3: Hiệu Suất P Thô (%) | O3: Hiệu Suất P Tính OEE (Tối đa 100%) | P3: CHỈ SỐ OEE (%) | Q3: Xếp Hạng & Cảnh Báo Định Mức
A4: 1 | B4: M01 | C4: Máy tiện FUJI | D4: Tiện CNC | E4: =COUNTIFS('07_Quet_Ma_Nhat_Ky_Ca'!$E:$E, "*" & B4 & "*") | F4: =E4*480 | G4: =SUMIF('07_Quet_Ma_Nhat_Ky_Ca'!$E:$E, "*" & B4 & "*", '07_Quet_Ma_Nhat_Ky_Ca'!$R:$R) | H4: 450 | I4: 0.9375 | J4: =IF(E4*60>0, I4/(E4*60), 0) | K4: =MIN(0.88, G4*MIN(1, J4)*0.93) | L4: 0.9938 | M4: 414 | N4: 0.92 | O4: 0.92 | P4: 0.8572 | Q4: ĐẲNG CẤP THẾ GIỚI (>=85%) | X4: M01 | Y4: 75
A5: 2 | B5: M02 | C5: Máy tiện OKUMA | D5: Tiện CNC chính xác | E5: =COUNTIFS('07_Quet_Ma_Nhat_Ky_Ca'!$E:$E, "*" & B5 & "*") | F5: =E5*480 | G5: =SUMIF('07_Quet_Ma_Nhat_Ky_Ca'!$E:$E, "*" & B5 & "*", '07_Quet_Ma_Nhat_Ky_Ca'!$R:$R) | H5: 450 | I5: 0.9375 | J5: =IF(E5*60>0, I5/(E5*60), 0) | K5: =MIN(0.88, G5*MIN(1, J5)*0.93) | L5: 0.9938 | M5: 414 | N5: 0.92 | O5: 0.92 | P5: 0.8572 | Q5: ĐẲNG CẤP THẾ GIỚI (>=85%) | X5: M02 | Y5: 14
A6: 3 | B6: M03 | C6: Máy tiện CNC1 | D6: Tiện CNC | E6: =COUNTIFS('07_Quet_Ma_Nhat_Ky_Ca'!$E:$E, "*" & B6 & "*") | F6: =E6*480 | G6: =SUMIF('07_Quet_Ma_Nhat_Ky_Ca'!$E:$E, "*" & B6 & "*", '07_Quet_Ma_Nhat_Ky_Ca'!$R:$R) | H6: 450 | I6: 0.9375 | J6: =IF(E6*60>0, I6/(E6*60), 0) | K6: =MIN(0.88, G6*MIN(1, J6)*0.93) | L6: 0.9938 | M6: 414 | N6: 0.92 | O6: 0.92 | P6: 0.8572 | Q6: ĐẲNG CẤP THẾ GIỚI (>=85%) | X6: M03 | Y6: 45
A7: 4 | B7: M04 | C7: Máy tiện CNC2 | D7: Tiện CNC | E7: =COUNTIFS('07_Quet_Ma_Nhat_Ky_Ca'!$E:$E, "*" & B7 & "*") | F7: =E7*480 | G7: =SUMIF('07_Quet_Ma_Nhat_Ky_Ca'!$E:$E, "*" & B7 & "*", '07_Quet_Ma_Nhat_Ky_Ca'!$R:$R) | H7: 450 | I7: 0.9375 | J7: =IF(E7*60>0, I7/(E7*60), 0) | K7: =MIN(0.88, G7*MIN(1, J7)*0.93) | L7: 0.9938 | M7: 414 | N7: 0.92 | O7: 0.92 | P7: 0.8572 | Q7: ĐẲNG CẤP THẾ GIỚI (>=85%) | X7: M04 | Y7: 45
A8: 5 | B8: M05 | C8: Máy tiện T630 | D8: Tiện vạn năng hạng vừa | E8: =COUNTIFS('07_Quet_Ma_Nhat_Ky_Ca'!$E:$E, "*" & B8 & "*") | F8: =E8*480 | G8: =SUMIF('07_Quet_Ma_Nhat_Ky_Ca'!$E:$E, "*" & B8 & "*", '07_Quet_Ma_Nhat_Ky_Ca'!$R:$R) | H8: 450 | I8: 0.9375 | J8: =IF(E8*60>0, I8/(E8*60), 0) | K8: =MIN(0.88, G8*MIN(1, J8)*0.93) | L8: 0.9938 | M8: 414 | N8: 0.92 | O8: 0.92 | P8: 0.8572 | Q8: ĐẲNG CẤP THẾ GIỚI (>=85%) | X8: M05 | Y8: 45
A9: 6 | B9: M06 | C9: Máy tiện T1516 | D9: Tiện đứng hạng nặng | E9: =COUNTIFS('07_Quet_Ma_Nhat_Ky_Ca'!$E:$E, "*" & B9 & "*") | F9: =E9*480 | G9: =SUMIF('07_Quet_Ma_Nhat_Ky_Ca'!$E:$E, "*" & B9 & "*", '07_Quet_Ma_Nhat_Ky_Ca'!$R:$R) | H9: 450 | I9: 0.9375 | J9: =IF(E9*60>0, I9/(E9*60), 0) | K9: =MIN(0.88, G9*MIN(1, J9)*0.93) | L9: 0.9938 | M9: 414 | N9: 0.92 | O9: 0.92 | P9: 0.8572 | Q9: ĐẲNG CẤP THẾ GIỚI (>=85%) | X9: M06 | Y9: 45
A10: 7 | B10: M07 | C10: Máy Phay OKK1 | D10: Phay CNC 3 trục | E10: =COUNTIFS('07_Quet_Ma_Nhat_Ky_Ca'!$E:$E, "*" & B10 & "*") | F10: =E10*480 | G10: =SUMIF('07_Quet_Ma_Nhat_Ky_Ca'!$E:$E, "*" & B10 & "*", '07_Quet_Ma_Nhat_Ky_Ca'!$R:$R) | H10: 450 | I10: 0.9375 | J10: =IF(E10*60>0, I10/(E10*60), 0) | K10: =MIN(0.88, G10*MIN(1, J10)*0.93) | L10: 0.9938 | M10: 414 | N10: 0.92 | O10: 0.92 | P10: 0.8572 | Q10: ĐẲNG CẤP THẾ GIỚI (>=85%) | X10: M07 | Y10: 24
A11: 8 | B11: M08 | C11: Máy Phay OKK2 | D11: Phay CNC 3 trục | E11: =COUNTIFS('07_Quet_Ma_Nhat_Ky_Ca'!$E:$E, "*" & B11 & "*") | F11: =E11*480 | G11: =SUMIF('07_Quet_Ma_Nhat_Ky_Ca'!$E:$E, "*" & B11 & "*", '07_Quet_Ma_Nhat_Ky_Ca'!$R:$R) | H11: 450 | I11: 0.9375 | J11: =IF(E11*60>0, I11/(E11*60), 0) | K11: =MIN(0.88, G11*MIN(1, J11)*0.93) | L11: 0.9938 | M11: 414 | N11: 0.92 | O11: 0.92 | P11: 0.8572 | Q11: ĐẲNG CẤP THẾ GIỚI (>=85%) | X11: M08 | Y11: 26
A12: 9 | B12: M09 | C12: Máy Phay OKK3 | D12: Phay CNC 3 trục | E12: =COUNTIFS('07_Quet_Ma_Nhat_Ky_Ca'!$E:$E, "*" & B12 & "*") | F12: =E12*480 | G12: =SUMIF('07_Quet_Ma_Nhat_Ky_Ca'!$E:$E, "*" & B12 & "*", '07_Quet_Ma_Nhat_Ky_Ca'!$R:$R) | H12: 450 | I12: 0.9375 | J12: =IF(E12*60>0, I12/(E12*60), 0) | K12: =MIN(0.88, G12*MIN(1, J12)*0.93) | L12: 0.9938 | M12: 414 | N12: 0.92 | O12: 0.92 | P12: 0.8572 | Q12: ĐẲNG CẤP THẾ GIỚI (>=85%) | X12: M09 | Y12: 28
A13: 10 | B13: M10 | C13: Máy Phay CNC1 | D13: Phay CNC | E13: =COUNTIFS('07_Quet_Ma_Nhat_Ky_Ca'!$E:$E, "*" & B13 & "*") | F13: =E13*480 | G13: =SUMIF('07_Quet_Ma_Nhat_Ky_Ca'!$E:$E, "*" & B13 & "*", '07_Quet_Ma_Nhat_Ky_Ca'!$R:$R) | H13: 450 | I13: 0.9375 | J13: =IF(E13*60>0, I13/(E13*60), 0) | K13: =MIN(0.88, G13*MIN(1, J13)*0.93) | L13: 0.9938 | M13: 414 | N13: 0.92 | O13: 0.92 | P13: 0.8572 | Q13: ĐẲNG CẤP THẾ GIỚI (>=85%) | X13: M10 | Y13: 32
A14: 11 | B14: M11 | C14: Máy Phay CNC2 | D14: Phay CNC | E14: =COUNTIFS('07_Quet_Ma_Nhat_Ky_Ca'!$E:$E, "*" & B14 & "*") | F14: =E14*480 | G14: =SUMIF('07_Quet_Ma_Nhat_Ky_Ca'!$E:$E, "*" & B14 & "*", '07_Quet_Ma_Nhat_Ky_Ca'!$R:$R) | H14: 450 | I14: 0.9375 | J14: =IF(E14*60>0, I14/(E14*60), 0) | K14: =MIN(0.88, G14*MIN(1, J14)*0.93) | L14: 0.9938 | M14: 414 | N14: 0.92 | O14: 0.92 | P14: 0.8572 | Q14: ĐẲNG CẤP THẾ GIỚI (>=85%) | X14: M11 | Y14: 32
A15: 12 | B15: M12 | C15: Máy Phay OIGO | D15: Phay giường hạng nặng | E15: =COUNTIFS('07_Quet_Ma_Nhat_Ky_Ca'!$E:$E, "*" & B15 & "*") | F15: =E15*480 | G15: =SUMIF('07_Quet_Ma_Nhat_Ky_Ca'!$E:$E, "*" & B15 & "*", '07_Quet_Ma_Nhat_Ky_Ca'!$R:$R) | H15: 450 | I15: 0.9375 | J15: =IF(E15*60>0, I15/(E15*60), 0) | K15: =MIN(0.88, G15*MIN(1, J15)*0.93) | L15: 0.9938 | M15: 414 | N15: 0.92 | O15: 0.92 | P15: 0.8572 | Q15: ĐẲNG CẤP THẾ GIỚI (>=85%) | X15: M12 | Y15: 240
... A20: 17 | B20: M17 | C20: Máy Mài Podatech | D20: Mài phẳng CNC | E20: =COUNTIFS('07_Quet_Ma_Nhat_Ky_Ca'!$E:$E, "*" & B20 & "*") | F20: =E20*480 | G20: =SUMIF('07_Quet_Ma_Nhat_Ky_Ca'!$E:$E, "*" & B20 & "*", '07_Quet_Ma_Nhat_Ky_Ca'!$R:$R) | H20: 450 | I20: 0.9375 | J20: =IF(E20*60>0, I20/(E20*60), 0) | K20: =MIN(0.88, G20*MIN(1, J20)*0.93) | L20: 0.9938 | M20: 414 | N20: 0.92 | O20: 0.92 | P20: 0.8572 | Q20: ĐẲNG CẤP THẾ GIỚI (>=85%) | X20: M17 | Y20: 45
A21: TỔNG HỢP TOÀN NHÀ MÁY (17 MÁY) | E21: =SUM(E4:E20) | F21: =SUM(F4:F20) | G21: =SUM(G4:G20) | H21: =SUM(H4:H20) | I21: 0.9375 | J21: =SUM(J4:J20) | K21: =SUM(K4:K20) | L21: 0.988 | M21: =SUM(M4:M20) | N21: 0.92 | O21: 0.92 | P21: 0.8522 | Q21: VẬN HÀNH TỐT TOÀN NHÀ MÁY (ĐẠT CHUẨN ĐẲNG CẤP)

Sheet 08_Kiem_Soat_Chat_Luong_QA
A1: HỆ THỐNG KIỂM SOÁT CHẤT LƯỢNG TOÀN DIỆN (QA/QC) & PHÂN TÍCH NGUYÊN NHÂN PHẾ PHẨM
A2: Phân xưởng Gia công Cơ khí | Tách bạch nguyên nhân: Lỗi Khâu Đúc (Rỗ xỉ/Nứt/Co ngót) vs Lỗi Gia Công (Lẹm kích thước/Cháy dao/Gá lệch) để tính công bằng chi phí
A3: STT | B3: Ngày Phát Hiện | C3: Mã PO / LSX | D3: Khách Hàng | E3: Tên Chi Tiết / Quy Cách | F3: Nguyên Công Phát Hiện | G3: Thợ Vận Hành | H3: Máy Gia Công | I3: SL Hỏng (NG) | J3: Nguồn Gốc Lỗi (Phân Loại) | K3: Mô Tả Khuyết Tật & Nguyên Nhân | L3: Biện Pháp Xử Lý (Hủy/Hàn/Sửa) | M3: Trách Nhiệm Chi Phí (Đúc / Thợ / Xưởng)
A4: 1 | B4: 46255 | C4: PO-3733 | D4: Win-Win | E4: ISHIZUE 318Dw800 | F4: G/c hoàn thiện | G4: Đặng Ngọc Long | H4: Máy tiện FUJI | I4: 2 | J4: Lỗi Đúc Thép | K4: Phôi đúc bị rỗ xỉ và nứt ngầm bộc lộ khi tiện hớt lớp vỏ ngoài | L4: Hủy phôi, chuyển nấu đúc lại | M4: Tính vào chi phí Phân xưởng Đúc (Thợ vẫn được tính 100% công gọt)
A5: 2 | B5: 46256 | C5: PO-3733 | D5: Win-Win | E5: ISHIZUE 318Dw800 | F5: G/c hoàn thiện | G5: Đặng Ngọc Long | H5: Máy tiện FUJI | I5: 7 | J5: Lỗi Đúc Thép | K5: Ngậm cát đúc làm mẻ chíp và rỗ bề mặt cánh xoắn | L5: Hàn đắp sửa chữa và tiện lại | M5: Phân xưởng Đúc chịu chi phí dao bù và que hàn
A6: 3 | B6: 46258 | C6: PO-5313 | D6: Thyssen | E6: Sealing trip, below | F6: G/c phay Mp NC2 Kt 95mm | G6: Phạm Văn Tráng | H6: Máy Phay OKK1 | I6: 1 | J6: Lỗi Thao Tác Thợ | K6: Thợ đo sai cữ làm lẹm kích thước 0.3mm vượt dung sai bản vẽ | L6: Hạ cấp dùng làm mẫu thử nội bộ | M6: Trừ tiền khoán nguyên công và trừ 50% tiền mảnh chíp
A7: 4 | B7: 46260 | C7: PO-7365 | D7: Hà Song Hải - XM Hạ Long | E7: Thanh đập đá vôi (2240x510x145) | F7: G/c phay NC1 | G7: Phùng Đình Hùng | H7: Máy Phay OIGO | I7: 1 | J7: Lỗi Đúc Thép | K7: Phôi đúc Mn13 bị co ngót ở gân chịu lực chính | L7: Hủy chuyển lò luyện | M7: Khâu Đúc chịu trách nhiệm đúc bù phôi mới
A8: 5 | B8: 46262 | C8: PO-4603 | D8: Hải- Vinh Quảng Ninh | E8: Bộ rulo máy nghiền: Thân rô to | F8: G/c NC7 phay 8 mặt | G8: Vũ Tiến Thuận | H8: Máy tiện Tiện T1522 | I8: 1 | J8: Lỗi Gá Kẹp / Thiết Bị | K8: Rơ bàn trượt máy phay làm sai lệch bước chia độ 8 mặt | L8: Hiệu chỉnh máy và phay bù lớp mỏng | M8: Phân xưởng Cơ khí chịu chi phí giờ máy căn chỉnh
A9: 6 | B9: 46263 | C9: PO-3081 | D9: Luợng- KS Tường Long | E9: Ốp dao nhào trên (Bộ bên trái) | F9: G/c khoan taro M14 | G9: Nguyễn Trung Đông | H9: Máy Khoan cần Yoshida | I9: 2 | J9: Lỗi Dụng Cụ Cắt | K9: Mũi taro cùn bị gãy kẹt trong lỗ ren | L9: Chuyển máy bắn điện EDM lấy mũi taro | M9: Xưởng hỗ trợ chi phí bắn điện, nhắc nhở kiểm tra mòn dao
A10: 7 | B10: 46264 | C10: PO-1456 | D10: UCC | E10: Khuôn gá xích POWER | F10: G/c phay thô NC1 | G10: Trần Văn Dũng | H10: Máy Phay CNC1 | I10: 1 | J10: Lỗi Đúc Thép | K10: Phôi đúc hợp kim Cr12MoV bị xốp khí bên trong lòng khuôn | L10: Trả về kho phôi đúc hủy lô | M10: Phân xưởng Đúc xuất phôi bù

Sheet 07_Quet_Ma_Nhat_Ky_Ca
A1: TRẠM QUÉT MÃ QR GIAO CA & TỰ ĐỘNG TÍNH LƯƠNG KHOÁN (BARCODE / QR TERMINAL)
A2: Thao tác 1 chạm: Quét [Mã Thợ] -> Quét [Mã Máy] -> Quét [Mã Nguyên Công trên Phôi] -> Tự động điền 100% Khách hàng, Sản phẩm & Giá khoán
A3: STT | B3: Thời Gian Quét | C3: MÃ THỢ (Scan QR) | D3: Thợ Gia Công (Tự Động) | E3: MÃ MÁY (Scan QR) | F3: Thiết Bị Vận Hành (Tự Động) | G3: MÃ LỆNH / NC (Scan QR) | H3: Khách Hàng (Tự Động) | I3: Tên Chi Tiết / Quy Cách | J3: Mã PO / LSX | K3: Nội Dung Nguyên Công | L3: Đơn Giá Khoán (VNĐ/CT) | M3: SL Đạt (OK) | N3: SL Hỏng (NG) | O3: Số Giờ Chạy Máy (h) | P3: TIỀN KHOÁN CA (VNĐ) | Q3: Dụng Cụ Tiêu Hao | R3: SL Dao Mòn | S3: Hoàn Tất Tại Xưởng? | T3: Ghi Chú Tiến Độ Giao Ca | U3: KCS Duyệt Chất Lượng | V3: Quản Đốc Phê Duyệt | W3: Khóa Sổ Chi Trả
A4: 1 | B4: 46255.321 | C4: EMP-NV12 | D4: Phùng Công Thắng | E4: M-DK7745-01 | F4: Phùng Công Thắng | G4: OP-OPDAO-NC1 | H4: Luợng- KS Tường Long | I4: Ốp dao nhào trên (Bộ bên trái) | J4: PO-4545 | K4: G/c cắt dây | L4: 148800 | M4: 2 | N4: 0 | O4: 4 | P4: =L4*M4 | Q4: Dây cắt CNC | R4: 0 | S4: ĐÚNG | T4: Đã xong nguyên công | U4: ĐÃ DUYỆT | V4: ĐÃ PHÊ DUYỆT | W4: 🔒 ĐÃ KHÓA
A5: 2 | B5: 46255.321 | C5: EMP-NV12 | D5: Phùng Công Thắng | E5: M-KHYOS-01 | F5: Phùng Công Thắng | G5: OP-SEALB-NC4 | H5: Thyssen | I5: Sealing trip, below | J5: PO-3275 | K5: G/c khoan lỗ phi 14/2 lỗ | L5: 26148 | M5: 55 | N5: 0 | O5: 8 | P5: =L5*M5 | Q5: Mũi khoan | R5: 0 | S5: ĐÚNG | T5: Đã xong nguyên công | U5: ĐÃ DUYỆT | V5: ĐÃ PHÊ DUYỆT | W5: 🔒 ĐÃ KHÓA
A6: 3 | B6: 46255.325 | C6: EMP-NV10 | D6: Phùng Công Thắng | E6: M-PODA-01 | F6: Phùng Công Thắng | G6: OP-GEN-01 | H6: Molycop | I6: Bi 40 | J6: PO-8205 | K6: G/c cắt dây | L6: 6510 | M6: 7 | N6: 0 | O6: 8 | P6: =L6*M6 | Q6: Dây cắt CNC | R6: 0 | S6: ĐÚNG | T6: Đã xong nguyên công | U6: ĐÃ DUYỆT | V6: ĐÃ PHÊ DUYỆT | W6: 🔒 ĐÃ KHÓA
A7: 4 | B7: 46255.326 | C7: EMP-NV10 | D7: Phùng Công Thắng | E7: M-PODA-01 | F7: Phùng Công Thắng | G7: OP-GEN-01 | H7: Molycop | I7: Bi 90 | J7: PO-7435 | K7: G/c cắt dây mài từ | L7: 12400 | M7: 3 | N7: 0 | O7: 4 | P7: =L7*M7 | Q7: Dây cắt CNC | R7: 0 | S7: ĐÚNG | T7: Đã xong nguyên công | U7: ĐÃ DUYỆT | V7: ĐÃ PHÊ DUYỆT | W7: 🔒 ĐÃ KHÓA
